Workbook

Sheet Tổng quan
A1: Hệ thống phối quang FTTH – Chung cư Phố Đông (Tháp A + B)
A2: Kiến trúc: ONU căn hộ ─1FO─ Splitter 1:16 (tủ) ─ cáp trục 24FO (8FO/tủ) ─ ODF PM ─ Splitter 1:4 ─ PON ⇒ 1:64 / PON
B4: Tổng căn hộ | D4: Hoạt động | F4: Đã đấu nối | H4: Sự cố
B5: =COUNTA('Thuê bao'!$A$2:$A$677) | D5: =COUNTIF('Thuê bao'!$N$2:$N$677,"Hoạt động") | F5: =COUNTIF('Thuê bao'!$N$2:$N$677,"Đã đấu nối") | H5: =COUNTIF('Thuê bao'!$N$2:$N$677,"Sự cố")
B7: Số tủ | D7: Splitter 1:16 | F7: Cổng 1:4 dùng / 64 | H7: Margin quang (dB)
B8: =COUNTA('Tủ phối quang'!A5:A21) | D8: ='Tủ phối quang'!F22 | F8: =COUNTIF('ODF-PM & PON'!$D$5:$D$68,"Đã dùng") | H8: ='Quỹ công suất'!E27
B11: PON | C11: Splitter 1:4 | D11: Nhánh dùng | E11: Căn hộ | F11: Hoạt động | G11: Tải / 64 hộ | H11: Cảnh báo | J11: Tháp | K11: Căn hộ | L11: Hoạt động
B12: PON-01 | C12: S4-01 | D12: =COUNTIFS('ODF-PM & PON'!$A$5:$A$68,B12,'ODF-PM & PON'!$D$5:$D$68,"Đã dùng") | E12: =COUNTIF('Thuê bao'!$M$2:$M$677,B12) | F12: =COUNTIFS('Thuê bao'!$M$2:$M$677,B12,'Thuê bao'!$N$2:$N$677,"Hoạt động") | G12: =E12/'Quỹ công suất'!$C$6 | H12: =IF(E12=0,"Trống",IF(G12>0.9,"Gần đầy","OK")) | J12: Tháp A | K12: =COUNTIF('Thuê bao'!$B$2:$B$677,"A") | L12: =COUNTIFS('Thuê bao'!$B$2:$B$677,"A",'Thuê bao'!$N$2:$N$677,"Hoạt động")
B13: PON-02 | C13: S4-02 | D13: =COUNTIFS('ODF-PM & PON'!$A$5:$A$68,B13,'ODF-PM & PON'!$D$5:$D$68,"Đã dùng") | E13: =COUNTIF('Thuê bao'!$M$2:$M$677,B13) | F13: =COUNTIFS('Thuê bao'!$M$2:$M$677,B13,'Thuê bao'!$N$2:$N$677,"Hoạt động") | G13: =E13/'Quỹ công suất'!$C$6 | H13: =IF(E13=0,"Trống",IF(G13>0.9,"Gần đầy","OK")) | J13: Tháp B | K13: =COUNTIF('Thuê bao'!$B$2:$B$677,"B") | L13: =COUNTIFS('Thuê bao'!$B$2:$B$677,"B",'Thuê bao'!$N$2:$N$677,"Hoạt động")
B14: PON-03 | C14: S4-03 | D14: =COUNTIFS('ODF-PM & PON'!$A$5:$A$68,B14,'ODF-PM & PON'!$D$5:$D$68,"Đã dùng") | E14: =COUNTIF('Thuê bao'!$M$2:$M$677,B14) | F14: =COUNTIFS('Thuê bao'!$M$2:$M$677,B14,'Thuê bao'!$N$2:$N$677,"Hoạt động") | G14: =E14/'Quỹ công suất'!$C$6 | H14: =IF(E14=0,"Trống",IF(G14>0.9,"Gần đầy","OK"))
B15: PON-04 | C15: S4-04 | D15: =COUNTIFS('ODF-PM & PON'!$A$5:$A$68,B15,'ODF-PM & PON'!$D$5:$D$68,"Đã dùng") | E15: =COUNTIF('Thuê bao'!$M$2:$M$677,B15) | F15: =COUNTIFS('Thuê bao'!$M$2:$M$677,B15,'Thuê bao'!$N$2:$N$677,"Hoạt động") | G15: =E15/'Quỹ công suất'!$C$6 | H15: =IF(E15=0,"Trống",IF(G15>0.9,"Gần đầy","OK"))
B16: PON-05 | C16: S4-05 | D16: =COUNTIFS('ODF-PM & PON'!$A$5:$A$68,B16,'ODF-PM & PON'!$D$5:$D$68,"Đã dùng") | E16: =COUNTIF('Thuê bao'!$M$2:$M$677,B16) | F16: =COUNTIFS('Thuê bao'!$M$2:$M$677,B16,'Thuê bao'!$N$2:$N$677,"Hoạt động") | G16: =E16/'Quỹ công suất'!$C$6 | H16: =IF(E16=0,"Trống",IF(G16>0.9,"Gần đầy","OK")) | J16: Cách dùng nhanh
B17: PON-06 | C17: S4-06 | D17: =COUNTIFS('ODF-PM & PON'!$A$5:$A$68,B17,'ODF-PM & PON'!$D$5:$D$68,"Đã dùng") | E17: =COUNTIF('Thuê bao'!$M$2:$M$677,B17) | F17: =COUNTIFS('Thuê bao'!$M$2:$M$677,B17,'Thuê bao'!$N$2:$N$677,"Hoạt động") | G17: =E17/'Quỹ công suất'!$C$6 | H17: =IF(E17=0,"Trống",IF(G17>0.9,"Gần đầy","OK")) | J17: 1. Tra đường quang 1 căn hộ → sheet "Tra cứu".
B18: PON-07 | C18: S4-07 | D18: =COUNTIFS('ODF-PM & PON'!$A$5:$A$68,B18,'ODF-PM & PON'!$D$5:$D$68,"Đã dùng") | E18: =COUNTIF('Thuê bao'!$M$2:$M$677,B18) | F18: =COUNTIFS('Thuê bao'!$M$2:$M$677,B18,'Thuê bao'!$N$2:$N$677,"Hoạt động") | G18: =E18/'Quỹ công suất'!$C$6 | H18: =IF(E18=0,"Trống",IF(G18>0.9,"Gần đầy","OK")) | J18: 2. Khách mới: tìm căn hộ ở "Thuê bao", đổi Trạng thái,
B19: PON-08 | C19: S4-08 | D19: =COUNTIFS('ODF-PM & PON'!$A$5:$A$68,B19,'ODF-PM & PON'!$D$5:$D$68,"Đã dùng") | E19: =COUNTIF('Thuê bao'!$M$2:$M$677,B19) | F19: =COUNTIFS('Thuê bao'!$M$2:$M$677,B19,'Thuê bao'!$N$2:$N$677,"Hoạt động") | G19: =E19/'Quỹ công suất'!$C$6 | H19: =IF(E19=0,"Trống",IF(G19>0.9,"Gần đầy","OK")) | J19: ghi serial ONU. Dashboard tự cập nhật.
B20: PON-09 | C20: S4-09 | D20: =COUNTIFS('ODF-PM & PON'!$A$5:$A$68,B20,'ODF-PM & PON'!$D$5:$D$68,"Đã dùng") | E20: =COUNTIF('Thuê bao'!$M$2:$M$677,B20) | F20: =COUNTIFS('Thuê bao'!$M$2:$M$677,B20,'Thuê bao'!$N$2:$N$677,"Hoạt động") | G20: =E20/'Quỹ công suất'!$C$6 | H20: =IF(E20=0,"Trống",IF(G20>0.9,"Gần đầy","OK")) | J20: 3. Mất tín hiệu hàng loạt → xem "Vận hành" (cây xử lý sự cố).
B21: PON-10 | C21: S4-10 | D21: =COUNTIFS('ODF-PM & PON'!$A$5:$A$68,B21,'ODF-PM & PON'!$D$5:$D$68,"Đã dùng") | E21: =COUNTIF('Thuê bao'!$M$2:$M$677,B21) | F21: =COUNTIFS('Thuê bao'!$M$2:$M$677,B21,'Thuê bao'!$N$2:$N$677,"Hoạt động") | G21: =E21/'Quỹ công suất'!$C$6 | H21: =IF(E21=0,"Trống",IF(G21>0.9,"Gần đầy","OK")) | J21: 4. Đấu nối ODF → "ODF 48FO"; sự cố → "Sự cố & khắc phục".
B22: PON-11 | C22: S4-11 | D22: =COUNTIFS('ODF-PM & PON'!$A$5:$A$68,B22,'ODF-PM & PON'!$D$5:$D$68,"Đã dùng") | E22: =COUNTIF('Thuê bao'!$M$2:$M$677,B22) | F22: =COUNTIFS('Thuê bao'!$M$2:$M$677,B22,'Thuê bao'!$N$2:$N$677,"Hoạt động") | G22: =E22/'Quỹ công suất'!$C$6 | H22: =IF(E22=0,"Trống",IF(G22>0.9,"Gần đầy","OK"))
B23: PON-12 | C23: S4-12 | D23: =COUNTIFS('ODF-PM & PON'!$A$5:$A$68,B23,'ODF-PM & PON'!$D$5:$D$68,"Đã dùng") | E23: =COUNTIF('Thuê bao'!$M$2:$M$677,B23) | F23: =COUNTIFS('Thuê bao'!$M$2:$M$677,B23,'Thuê bao'!$N$2:$N$677,"Hoạt động") | G23: =E23/'Quỹ công suất'!$C$6 | H23: =IF(E23=0,"Trống",IF(G23>0.9,"Gần đầy","OK"))
B24: PON-13 | C24: S4-13 | D24: =COUNTIFS('ODF-PM & PON'!$A$5:$A$68,B24,'ODF-PM & PON'!$D$5:$D$68,"Đã dùng") | E24: =COUNTIF('Thuê bao'!$M$2:$M$677,B24) | F24: =COUNTIFS('Thuê bao'!$M$2:$M$677,B24,'Thuê bao'!$N$2:$N$677,"Hoạt động") | G24: =E24/'Quỹ công suất'!$C$6 | H24: =IF(E24=0,"Trống",IF(G24>0.9,"Gần đầy","OK"))
B25: PON-14 | C25: S4-14 | D25: =COUNTIFS('ODF-PM & PON'!$A$5:$A$68,B25,'ODF-PM & PON'!$D$5:$D$68,"Đã dùng") | E25: =COUNTIF('Thuê bao'!$M$2:$M$677,B25) | F25: =COUNTIFS('Thuê bao'!$M$2:$M$677,B25,'Thuê bao'!$N$2:$N$677,"Hoạt động") | G25: =E25/'Quỹ công suất'!$C$6 | H25: =IF(E25=0,"Trống",IF(G25>0.9,"Gần đầy","OK"))
B26: PON-15 | C26: S4-15 | D26: =COUNTIFS('ODF-PM & PON'!$A$5:$A$68,B26,'ODF-PM & PON'!$D$5:$D$68,"Đã dùng") | E26: =COUNTIF('Thuê bao'!$M$2:$M$677,B26) | F26: =COUNTIFS('Thuê bao'!$M$2:$M$677,B26,'Thuê bao'!$N$2:$N$677,"Hoạt động") | G26: =E26/'Quỹ công suất'!$C$6 | H26: =IF(E26=0,"Trống",IF(G26>0.9,"Gần đầy","OK"))
B27: PON-16 | C27: S4-16 | D27: =COUNTIFS('ODF-PM & PON'!$A$5:$A$68,B27,'ODF-PM & PON'!$D$5:$D$68,"Đã dùng") | E27: =COUNTIF('Thuê bao'!$M$2:$M$677,B27) | F27: =COUNTIFS('Thuê bao'!$M$2:$M$677,B27,'Thuê bao'!$N$2:$N$677,"Hoạt động") | G27: =E27/'Quỹ công suất'!$C$6 | H27: =IF(E27=0,"Trống",IF(G27>0.9,"Gần đầy","OK"))
B28: Tổng | D28: =SUM(D12:D27) | E28: =SUM(E12:E27) | F28: =SUM(F12:F27)

Sheet Sơ đồ trục
A1: Sơ đồ trục thông tầng – Tháp A & Tháp B (số hoá từ sổ tay)
A2: Ô đậm = tủ đặt tại tầng đó (ghi "gom nT/số hộ": gom n tầng); các hàng "│ TU-xx" là tầng thuộc cụm tủ đó. ⚠ = tủ đặt khác tầng gom (xem sheet "Đối chiếu bản vẽ"). Cột Trục 1-3 = cáp trục 24FO TR-x1 (thấp) … TR-x3 (cao).
B4: THÁP A | L4: THÁP B
B5: Tầng | C5: Trục 1 | D5: Trục 2 | E5: Trục 3 | F5: Tủ | G5: Số hộ | H5: PON | I5: Splitter | L5: Tầng | M5: Trục 1 | N5: Trục 2 | O5: Trục 3 | P5: Tủ | Q5: Số hộ | R5: PON | S5: Splitter
B6: 23F | E6: ● | F6: TU-A23 (1×1:16) | G6: 14 | H6: PON-08 | I6: gom 1T/14 | L6: 23F | O6: ● | P6: TU-B23 (2×1:16) | Q6: 14 | R6: PON-16 | S6: gom 2T/28
B7: 22F | F7: │ TU-A21 | G7: 14 | L7: 22F | P7: │ TU-B23 | Q7: 14
B8: 21F | E8: ● | F8: TU-A21 (3×1:16) | G8: 14 | H8: PON-08 | I8: gom 3T/42 | L8: 21F | P8: │ TU-B20 | Q8: 14
B9: 20F | F9: │ TU-A21 | G9: 14 | L9: 20F | O9: ● | P9: TU-B20 (3×1:16) | Q9: 14 | R9: PON-15,16 | S9: gom 3T/42
B10: 19F | F10: │ TU-A18 | G10: 14 | L10: 19F | P10: │ TU-B20 | Q10: 14
B11: 18F | E11: ● | F11: TU-A18 (3×1:16) | G11: 14 | H11: PON-07 | I11: gom 3T/42 | L11: 18F | P11: │ TU-B17 | Q11: 14
B12: 17F | F12: │ TU-A18 | G12: 14 | L12: 17F | O12: ● | P12: TU-B17 (3×1:16) | Q12: 14 | R12: PON-14,15 | S12: gom 3T/42
B13: 16F | F13: │ TU-A15 | G13: 14 | L13: 16F | P13: │ TU-B17 | Q13: 14
B14: 15F | D14: ● | F14: TU-A15 (3×1:16) | G14: 14 | H14: PON-06 | I14: gom 3T/42 | L14: 15F | P14: │ TU-B14 | Q14: 14
B15: 14F | F15: │ TU-A15 | G15: 14 | L15: 14F | N15: ● | P15: TU-B14 (3×1:16) | Q15: 14 | R15: PON-13,14 | S15: gom 3T/42
B16: 12AF | F16: │ TU-A12 | G16: 14 | L16: 12AF | P16: │ TU-B14 | Q16: 14
B17: 12F | D17: ● | F17: TU-A12 (3×1:16) | G17: 15 | H17: PON-05 | I17: gom 3T/44 | L17: 12F | P17: │ TU-B11 | Q17: 14
B18: 11F | F18: │ TU-A12 | G18: 15 | L18: 11F | N18: ● | P18: TU-B11 (3×1:16) | Q18: 14 | R18: PON-12,13 | S18: gom 3T/42
B19: 10F | F19: │ TU-A9 | G19: 15 | L19: 10F | P19: │ TU-B11 | Q19: 14
B20: 9F | D20: ● | F20: TU-A9 (3×1:16) | G20: 15 | H20: PON-04 | I20: gom 3T/45 | L20: 9F | P20: │ TU-B8 | Q20: 14
B21: 8F | F21: │ TU-A9 | G21: 15 | L21: 8F | N21: ● | P21: TU-B8 (3×1:16) | Q21: 14 | R21: PON-11,12 | S21: gom 3T/42
B22: 7F | C22: ● | F22: TU-A7 (3×1:16) | G22: 15 | H22: PON-03 | I22: gom 3T/45 | L22: 7F | P22: │ TU-B8 | Q22: 14
B23: 6F | F23: │ TU-A7 | G23: 15 | L23: 6F | P23: │ TU-B5 | Q23: 14
B24: 5F | C24: ● | F24: TU-A5 (3×1:16) ⚠ | G24: 15 | H24: PON-02 | I24: gom 2T/35 | L24: 5F | M24: ● | P24: TU-B5 (3×1:16) | Q24: 14 | R24: PON-10,11 | S24: gom 3T/42
B25: 4F | F25: │ TU-A5 | G25: 15 | L25: 4F | P25: │ TU-B5 | Q25: 14
B26: 3F | F26: │ TU-A5 | G26: 20 | L26: 3F | P26: │ TU-B2 | Q26: 17
B27: 2F | C27: ● | F27: TU-A2 (3×1:16) | G27: 27 | H27: PON-01 | I27: gom 2T/39 | L27: 2F | M27: ● | P27: TU-B2 (5×1:16) | Q27: 22 | R27: PON-09,10 | S27: gom 3T/48
B28: 1F | F28: │ TU-A2 | G28: 12 | L28: 1F | P28: │ TU-B2 | Q28: 9
B29: ▼ PHÒNG MÁY (hầm B1): ODF 48FO + 16 splitter 1:4 + OLT 16 PON | L29: ▼ PHÒNG MÁY (hầm B1): ODF 48FO + 16 splitter 1:4 + OLT 16 PON
C30: A1 | D30: A2 | E30: A3 | M30: B1 | N30: B2 | O30: B3
B32: Chú giải: ● = tủ trên trục; 3 màu xanh/cam/lục = 3 cáp trục 24FO của mỗi tháp (TR-x1 = cụm tầng thấp; mỗi cáp chia 8FO/tủ). Tầng 13 không có (12A thay thế).

Sheet Tủ phối quang
A1: Danh mục tủ phối quang (17 tủ)
A2: Số hộ / sử dụng / hoạt động tự cập nhật từ sheet "Thuê bao".
A4: Mã tủ | B4: Tháp | C4: Tầng đặt | D4: Các tầng phục vụ | E4: Số căn hộ | F4: Splitter 1:16 lắp | G4: Vị trí trống | H4: Số cổng khả dụng | I4: % sử dụng cổng | J4: Hoạt động | K4: Cáp trục | L4: Dải sợi (8FO) | M4: Vai trò | N4: PON cấp nguồn | O4: Số tầng gom | P4: Đối chiếu bản vẽ gốc
A5: TU-A23 | B5: A | C5: 23 | D5: 23 | E5: =COUNTIF('Thuê bao'!$E$2:$E$677,A5) | F5: 1 | G5: 3 | H5: =F5*16 | I5: =E5/H5 | J5: =COUNTIFS('Thuê bao'!$E$2:$E$677,A5,'Thuê bao'!$N$2:$N$677,"Hoạt động") | K5: TR-A3 | L5: 17-24 | M5: Tủ nhánh (cáp 8FO xuống hub) | N5: PON-08 | O5: 1 | P5: Khớp (ODF24FO-09 @ tầng 23)
A6: TU-A21 | B6: A | C6: 21 | D6: 22, 21, 20 | E6: =COUNTIF('Thuê bao'!$E$2:$E$677,A6) | F6: 3 | G6: 1 | H6: =F6*16 | I6: =E6/H6 | J6: =COUNTIFS('Thuê bao'!$E$2:$E$677,A6,'Thuê bao'!$N$2:$N$677,"Hoạt động") | K6: TR-A3 | L6: 9-16 | M6: Tủ nhánh (cáp 8FO xuống hub) | N6: PON-08 | O6: 3 | P6: Khớp (ODF96FO-08 @ tầng 21)
A7: TU-A18 | B7: A | C7: 18 | D7: 19, 18, 17 | E7: =COUNTIF('Thuê bao'!$E$2:$E$677,A7) | F7: 3 | G7: 1 | H7: =F7*16 | I7: =E7/H7 | J7: =COUNTIFS('Thuê bao'!$E$2:$E$677,A7,'Thuê bao'!$N$2:$N$677,"Hoạt động") | K7: TR-A3 | L7: 1-8 | M7: HUB (cáp trục 24FO về PM) | N7: PON-07 | O7: 3 | P7: Khớp (ODF96FO-07 @ tầng 18)
A8: TU-A15 | B8: A | C8: 15 | D8: 16, 15, 14 | E8: =COUNTIF('Thuê bao'!$E$2:$E$677,A8) | F8: 3 | G8: 1 | H8: =F8*16 | I8: =E8/H8 | J8: =COUNTIFS('Thuê bao'!$E$2:$E$677,A8,'Thuê bao'!$N$2:$N$677,"Hoạt động") | K8: TR-A2 | L8: 17-24 | M8: Tủ nhánh (cáp 8FO xuống hub) | N8: PON-06 | O8: 3 | P8: Khớp (ODF96FO-06 @ tầng 15)
A9: TU-A12 | B9: A | C9: 12 | D9: 12A, 12, 11 | E9: =COUNTIF('Thuê bao'!$E$2:$E$677,A9) | F9: 3 | G9: 1 | H9: =F9*16 | I9: =E9/H9 | J9: =COUNTIFS('Thuê bao'!$E$2:$E$677,A9,'Thuê bao'!$N$2:$N$677,"Hoạt động") | K9: TR-A2 | L9: 9-16 | M9: Tủ nhánh (cáp 8FO xuống hub) | N9: PON-05 | O9: 3 | P9: Khớp (ODF96FO-05 @ tầng 12)
A10: TU-A9 | B10: A | C10: 9 | D10: 10, 9, 8 | E10: =COUNTIF('Thuê bao'!$E$2:$E$677,A10) | F10: 3 | G10: 1 | H10: =F10*16 | I10: =E10/H10 | J10: =COUNTIFS('Thuê bao'!$E$2:$E$677,A10,'Thuê bao'!$N$2:$N$677,"Hoạt động") | K10: TR-A2 | L10: 1-8 | M10: HUB (cáp trục 24FO về PM) | N10: PON-04 | O10: 3 | P10: Khớp (ODF96FO-04 @ tầng 9)
A11: TU-A7 | B11: A | C11: 7 | D11: 7, 6, 5 | E11: =COUNTIF('Thuê bao'!$E$2:$E$677,A11) | F11: 3 | G11: 1 | H11: =F11*16 | I11: =E11/H11 | J11: =COUNTIFS('Thuê bao'!$E$2:$E$677,A11,'Thuê bao'!$N$2:$N$677,"Hoạt động") | K11: TR-A1 | L11: 17-24 | M11: Tủ nhánh (cáp 8FO xuống hub) | N11: PON-03 | O11: 3 | P11: LỆCH tầng đặt: sổ tay 7F, bản vẽ 6F (ODF96FO-03)
A12: TU-A5 | B12: A | C12: 5 | D12: 4, 3 | E12: =COUNTIF('Thuê bao'!$E$2:$E$677,A12) | F12: 3 | G12: 1 | H12: =F12*16 | I12: =E12/H12 | J12: =COUNTIFS('Thuê bao'!$E$2:$E$677,A12,'Thuê bao'!$N$2:$N$677,"Hoạt động") | K12: TR-A1 | L12: 9-16 | M12: Tủ nhánh (cáp 8FO xuống hub) | N12: PON-02 | O12: 2 | P12: LỆCH tầng đặt: sổ tay 5F, bản vẽ 4F (ODF96FO-02)
A13: TU-A2 | B13: A | C13: 2 | D13: 2, 1 | E13: =COUNTIF('Thuê bao'!$E$2:$E$677,A13) | F13: 3 | G13: 1 | H13: =F13*16 | I13: =E13/H13 | J13: =COUNTIFS('Thuê bao'!$E$2:$E$677,A13,'Thuê bao'!$N$2:$N$677,"Hoạt động") | K13: TR-A1 | L13: 1-8 | M13: HUB (cáp trục 24FO về PM) | N13: PON-01 | O13: 2 | P13: Khớp (ODF96FO-01 @ tầng 2)
A14: TU-B23 | B14: B | C14: 23 | D14: 23, 22 | E14: =COUNTIF('Thuê bao'!$E$2:$E$677,A14) | F14: 2 | G14: 2 | H14: =F14*16 | I14: =E14/H14 | J14: =COUNTIFS('Thuê bao'!$E$2:$E$677,A14,'Thuê bao'!$N$2:$N$677,"Hoạt động") | K14: TR-B3 | L14: 17-24 | M14: Tủ nhánh (cáp 8FO xuống hub) | N14: PON-16 | O14: 2 | P14: Khớp (ODF96FO-17 @ tầng 23)
A15: TU-B20 | B15: B | C15: 20 | D15: 21, 20, 19 | E15: =COUNTIF('Thuê bao'!$E$2:$E$677,A15) | F15: 3 | G15: 1 | H15: =F15*16 | I15: =E15/H15 | J15: =COUNTIFS('Thuê bao'!$E$2:$E$677,A15,'Thuê bao'!$N$2:$N$677,"Hoạt động") | K15: TR-B3 | L15: 9-16 | M15: Tủ nhánh (cáp 8FO xuống hub) | N15: PON-15, PON-16 | O15: 3 | P15: Khớp (ODF96FO-16 @ tầng 20)
A16: TU-B17 | B16: B | C16: 17 | D16: 18, 17, 16 | E16: =COUNTIF('Thuê bao'!$E$2:$E$677,A16) | F16: 3 | G16: 1 | H16: =F16*16 | I16: =E16/H16 | J16: =COUNTIFS('Thuê bao'!$E$2:$E$677,A16,'Thuê bao'!$N$2:$N$677,"Hoạt động") | K16: TR-B3 | L16: 1-8 | M16: HUB (cáp trục 24FO về PM) | N16: PON-14, PON-15 | O16: 3 | P16: Khớp (ODF96FO-15 @ tầng 17)
... A21: TU-B2 | B21: B | C21: 2 | D21: 3, 2, 1 | E21: =COUNTIF('Thuê bao'!$E$2:$E$677,A21) | F21: 5 | G21: 0 | H21: =F21*16 | I21: =E21/H21 | J21: =COUNTIFS('Thuê bao'!$E$2:$E$677,A21,'Thuê bao'!$N$2:$N$677,"Hoạt động") | K21: TR-B1 | L21: 1-8 | M21: HUB (cáp trục 24FO về PM) | N21: PON-09, PON-10 | O21: 3 | P21: Khớp (ODF96FO-10 @ tầng 2)
A22: Tổng | E22: =SUM(E5:E21) | F22: =SUM(F5:F21) | G22: =SUM(G5:G21) | H22: =SUM(H5:H21) | I22: =E22/H22 | J22: =SUM(J5:J21)

Sheet Đối chiếu bản vẽ
A1: Đối chiếu: sổ tay thi công ↔ bản vẽ gốc (sơ đồ nguyên lý PDF)
A2: Sổ tay cho biết tầng đặt tủ + nhóm cáp trục; bản vẽ gốc cho biết mỗi ODF/tủ gom những tầng nào (ODF phục vụ dòng box của tầng đặt + 1 dòng trên + 1 dòng dưới).
A4: Tháp | B4: Tủ (sổ tay) | C4: Tầng đặt (sổ tay) | D4: ODF bản vẽ gốc | E4: Tầng đặt (bản vẽ gốc) | F4: Các tầng gom (bản vẽ gốc) | G4: Số tầng gom | H4: Số căn hộ | I4: Splitter 1:16 | J4: Cáp trục | K4: Kết quả đối chiếu
A5: A | B5: TU-A23 | C5: 23F | D5: ODF24FO-09 | E5: 23F | F5: 23 | G5: 1 | H5: =COUNTIF('Thuê bao'!$E$2:$E$677,B5) | I5: 1 | J5: TR-A3 | K5: Khớp (ODF24FO-09 @ tầng 23)
A6: A | B6: TU-A21 | C6: 21F | D6: ODF96FO-08 | E6: 21F | F6: 22, 21, 20 | G6: 3 | H6: =COUNTIF('Thuê bao'!$E$2:$E$677,B6) | I6: 3 | J6: TR-A3 | K6: Khớp (ODF96FO-08 @ tầng 21)
A7: A | B7: TU-A18 | C7: 18F | D7: ODF96FO-07 | E7: 18F | F7: 19, 18, 17 | G7: 3 | H7: =COUNTIF('Thuê bao'!$E$2:$E$677,B7) | I7: 3 | J7: TR-A3 | K7: Khớp (ODF96FO-07 @ tầng 18)
A8: A | B8: TU-A15 | C8: 15F | D8: ODF96FO-06 | E8: 15F | F8: 16, 15, 14 | G8: 3 | H8: =COUNTIF('Thuê bao'!$E$2:$E$677,B8) | I8: 3 | J8: TR-A2 | K8: Khớp (ODF96FO-06 @ tầng 15)
A9: A | B9: TU-A12 | C9: 12F | D9: ODF96FO-05 | E9: 12F | F9: 12A, 12, 11 | G9: 3 | H9: =COUNTIF('Thuê bao'!$E$2:$E$677,B9) | I9: 3 | J9: TR-A2 | K9: Khớp (ODF96FO-05 @ tầng 12)
A10: A | B10: TU-A9 | C10: 9F | D10: ODF96FO-04 | E10: 9F | F10: 10, 9, 8 | G10: 3 | H10: =COUNTIF('Thuê bao'!$E$2:$E$677,B10) | I10: 3 | J10: TR-A2 | K10: Khớp (ODF96FO-04 @ tầng 9)
A11: A | B11: TU-A7 | C11: 7F | D11: ODF96FO-03 | E11: 6F | F11: 7, 6, 5 | G11: 3 | H11: =COUNTIF('Thuê bao'!$E$2:$E$677,B11) | I11: 3 | J11: TR-A1 | K11: LỆCH tầng đặt: sổ tay 7F, bản vẽ 6F (ODF96FO-03)
A12: A | B12: TU-A5 | C12: 5F | D12: ODF96FO-02 | E12: 4F | F12: 4, 3 | G12: 2 | H12: =COUNTIF('Thuê bao'!$E$2:$E$677,B12) | I12: 3 | J12: TR-A1 | K12: LỆCH tầng đặt: sổ tay 5F, bản vẽ 4F (ODF96FO-02)
A13: A | B13: TU-A2 | C13: 2F | D13: ODF96FO-01 | E13: 2F | F13: 2, 1 | G13: 2 | H13: =COUNTIF('Thuê bao'!$E$2:$E$677,B13) | I13: 3 | J13: TR-A1 | K13: Khớp (ODF96FO-01 @ tầng 2)
A14: B | B14: TU-B23 | C14: 23F | D14: ODF96FO-17 | E14: 23F | F14: 23, 22 | G14: 2 | H14: =COUNTIF('Thuê bao'!$E$2:$E$677,B14) | I14: 2 | J14: TR-B3 | K14: Khớp (ODF96FO-17 @ tầng 23)
A15: B | B15: TU-B20 | C15: 20F | D15: ODF96FO-16 | E15: 20F | F15: 21, 20, 19 | G15: 3 | H15: =COUNTIF('Thuê bao'!$E$2:$E$677,B15) | I15: 3 | J15: TR-B3 | K15: Khớp (ODF96FO-16 @ tầng 20)
A16: B | B16: TU-B17 | C16: 17F | D16: ODF96FO-15 | E16: 17F | F16: 18, 17, 16 | G16: 3 | H16: =COUNTIF('Thuê bao'!$E$2:$E$677,B16) | I16: 3 | J16: TR-B3 | K16: Khớp (ODF96FO-15 @ tầng 17)
... A21: B | B21: TU-B2 | C21: 2F | D21: ODF96FO-10 | E21: 2F | F21: 3, 2, 1 | G21: 3 | H21: =COUNTIF('Thuê bao'!$E$2:$E$677,B21) | I21: 5 | J21: TR-B1 | K21: Khớp (ODF96FO-10 @ tầng 2)
A23: KẾT QUẢ ĐỐI CHIẾU
A24: • Tháp B: 8/8 tủ khớp hoàn toàn (tầng đặt và cụm gom): 23 (23-22) · 20 (21-19) · 17 (18-16) · 14 (15-12A) · 11 (12-10) · 8 (9-7) · 5 (6-4) · 2 (3-1).
A25: • Tháp A: 7/9 tủ khớp. LỆCH 2 tủ: sổ tay ghi tủ 7F và 5F, bản vẽ gốc đặt ODF ở 6F (gom 7-6-5) và 4F (gom 4-3). Cần kiểm tra thực địa tủ nằm ở tầng nào.
A26: • Mô hình dùng tên tủ theo sổ tay (TU-A7, TU-A5) nhưng cụm gom theo bản vẽ gốc: TU-A7 gom 7-6-5, TU-A5 gom 4-3, TU-A2 gom 2-1 (tầng 2 gom 2 tầng, 39 hộ).
A27: • Sổ tay chưa thể hiện nhóm gom tầng → lấy từ bản vẽ gốc. Riêng tủ A23: bản vẽ gốc dùng ODF24FO-09 (chỉ 24FO) và chỉ phục vụ tầng 23 (14 hộ) nên lắp 1 splitter.
A28: • Nhóm 3 tủ/cáp trục: chỉ có trong sổ tay (bản vẽ gốc không vẽ). Đánh số mới: TR-A1 = A7-A5-A2 (thấp), TR-A2 = A15-A12-A9, TR-A3 = A23-A21-A18; TR-B1 = B5-B2, TR-B2 = B14-B11-B8, TR-B3 = B23-B20-B17.
A29: • Cả hai bản đều không có tầng 13 (dùng 12A). Số tầng: 23 tầng mỗi tháp, bản vẽ gốc: hàng box nằm trên đường nét đứt ghi tên tầng.
A30: • Quy tắc splitter: MỖI SPLITTER CHỈ PHỤC VỤ 1 TẦNG (cáp 1FO từ tủ tới căn hộ đã đặt cố định theo tầng, không dùng lệch tầng). Tầng ≤16 hộ = 1 splitter; tầng >16 hộ chia đều cho nhiều splitter. Riêng TU-B2 (tầng 3/2/1 = 17/22/9 hộ) cần 5 splitter (tủ 5 vị trí).

Sheet Sợi trục
A1: Bảng sợi cáp trục (6 cáp × 24FO)
A2: Cáp 24FO = 4 ống đệm (xanh dương, cam, xanh lá, nâu) × 6 màu sợi (xanh dương, cam, xanh lá, nâu, xám, trắng). Mỗi hàng coupler trên khay ODF = 1 ống đệm.
A4: Cáp trục | B4: Sợi | C4: Ống đệm | D4: Màu sợi | E4: Cáp nhánh 8FO # (từ dưới) | F4: Tủ | G4: Splitter 1:16 | H4: ODF / khay | I4: Coupler (hàng-cột) | J4: Splitter PM / cổng | K4: PON | L4: Trạng thái
A5: TR-A1 | B5: 1 | C5: Ống 1 Xanh dương | D5: Xanh dương | E5: 1 | F5: TU-A2 | G5: TU-A2/S1 | H5: ODF-02 Trái | I5: H1-C1 | J5: S4-01 / A-1 | K5: PON-01 | L5: Đang dùng
A6: TR-A1 | B6: 2 | C6: Ống 1 Xanh dương | D6: Cam | E6: 1 | F6: TU-A2 | G6: TU-A2/S2 | H6: ODF-02 Trái | I6: H1-C2 | J6: S4-01 / A-2 | K6: PON-01 | L6: Đang dùng
A7: TR-A1 | B7: 3 | C7: Ống 1 Xanh dương | D7: Xanh lá | E7: 1 | F7: TU-A2 | G7: TU-A2/S3 | H7: ODF-02 Trái | I7: H1-C3 | J7: S4-01 / A-3 | K7: PON-01 | L7: Đang dùng
A8: TR-A1 | B8: 4 | C8: Ống 1 Xanh dương | D8: Nâu | E8: 1 | F8: TU-A2 | G8: — | H8: ODF-02 Trái | I8: H1-C4 | J8: — | K8: — | L8: Dự phòng
A9: TR-A1 | B9: 5 | C9: Ống 1 Xanh dương | D9: Xám | E9: 1 | F9: TU-A2 | G9: — | H9: ODF-02 Trái | I9: H1-C5 | J9: — | K9: — | L9: Dự phòng
A10: TR-A1 | B10: 6 | C10: Ống 1 Xanh dương | D10: Trắng | E10: 1 | F10: TU-A2 | G10: — | H10: ODF-02 Trái | I10: H1-C6 | J10: — | K10: — | L10: Dự phòng
A11: TR-A1 | B11: 7 | C11: Ống 2 Cam | D11: Xanh dương | E11: 1 | F11: TU-A2 | G11: — | H11: ODF-02 Trái | I11: H2-C1 | J11: — | K11: — | L11: Dự phòng
A12: TR-A1 | B12: 8 | C12: Ống 2 Cam | D12: Cam | E12: 1 | F12: TU-A2 | G12: — | H12: ODF-02 Trái | I12: H2-C2 | J12: — | K12: — | L12: Dự phòng
A13: TR-A1 | B13: 9 | C13: Ống 2 Cam | D13: Xanh lá | E13: 2 | F13: TU-A5 | G13: TU-A5/S1 | H13: ODF-02 Trái | I13: H2-C3 | J13: S4-02 / A-5 | K13: PON-02 | L13: Đang dùng
A14: TR-A1 | B14: 10 | C14: Ống 2 Cam | D14: Nâu | E14: 2 | F14: TU-A5 | G14: TU-A5/S2 | H14: ODF-02 Trái | I14: H2-C4 | J14: S4-02 / A-6 | K14: PON-02 | L14: Đang dùng
A15: TR-A1 | B15: 11 | C15: Ống 2 Cam | D15: Xám | E15: 2 | F15: TU-A5 | G15: TU-A5/S3 | H15: ODF-02 Trái | I15: H2-C5 | J15: S4-02 / A-7 | K15: PON-02 | L15: Đang dùng
A16: TR-A1 | B16: 12 | C16: Ống 2 Cam | D16: Trắng | E16: 2 | F16: TU-A5 | G16: — | H16: ODF-02 Trái | I16: H2-C6 | J16: — | K16: — | L16: Dự phòng
... A148: TR-B3 | B148: 24 | C148: Ống 4 Nâu | D148: Trắng | E148: 3 | F148: TU-B23 | G148: — | H148: ODF-17/18 Phải | I148: H4-C6 | J148: — | K148: — | L148: Dự phòng

Sheet ODF-PM & PON
A1: Bảng đấu nối tại Phòng máy: OLT PON → ODF-96 (vào) → Splitter 1:4 → ODF-96 (ra) → ODF 48FO → Cáp trục
A2: ODF-96FO chia 2 nửa 4×12: TRÁI = tháp A (PON 1-8), PHẢI = tháp B (PON 9-16); mỗi nửa đếm từ 1, từ dưới lên, trái qua phải. Splitter thứ k của nửa: vào cổng 36+k (37-44), ra cổng 4k-3…4k. Mỗi PON dùng 3 cổng (cổng 4 dự phòng, được phép dùng khi tháp cần). Dây nhảy: OLT→cổng vào; cổng ra→ODF-48.
A4: PON | B4: Splitter PM 1:4 | C4: ODF-96 cổng ra (nửa-số) | D4: Trạng thái cổng | E4: ODF-48 đích | F4: Khay | G4: Coupler ODF-48 | H4: Cáp trục/sợi | I4: Ống / màu | J4: Tủ đích | K4: Splitter 1:16 đích | L4: Số căn hộ | M4: Hoạt động | N4: ODF-96 cổng vào (OLT) | O4: Vị trí cổng ra (hàng-cột) | P4: Vị trí cổng vào (hàng-cột)
A5: PON-01 | B5: S4-01 | C5: A-1 | D5: Đã dùng | E5: ODF-02 | F5: Trái | G5: H1-C1 | H5: TR-A1/01 | I5: Ống 1 Xanh dương / Xanh dương | J5: TU-A2 | K5: TU-A2/S1 | L5: =COUNTIF('Thuê bao'!$F$2:$F$677,K5) | M5: =COUNTIFS('Thuê bao'!$F$2:$F$677,K5,'Thuê bao'!$N$2:$N$677,"Hoạt động") | N5: A-37 | O5: H1-C1 | P5: H4-C1
A6: PON-01 | B6: S4-01 | C6: A-2 | D6: Đã dùng | E6: ODF-02 | F6: Trái | G6: H1-C2 | H6: TR-A1/02 | I6: Ống 1 Xanh dương / Cam | J6: TU-A2 | K6: TU-A2/S2 | L6: =COUNTIF('Thuê bao'!$F$2:$F$677,K6) | M6: =COUNTIFS('Thuê bao'!$F$2:$F$677,K6,'Thuê bao'!$N$2:$N$677,"Hoạt động") | N6: A-37 | O6: H1-C2 | P6: H4-C1
A7: PON-01 | B7: S4-01 | C7: A-3 | D7: Đã dùng | E7: ODF-02 | F7: Trái | G7: H1-C3 | H7: TR-A1/03 | I7: Ống 1 Xanh dương / Xanh lá | J7: TU-A2 | K7: TU-A2/S3 | L7: =COUNTIF('Thuê bao'!$F$2:$F$677,K7) | M7: =COUNTIFS('Thuê bao'!$F$2:$F$677,K7,'Thuê bao'!$N$2:$N$677,"Hoạt động") | N7: A-37 | O7: H1-C3 | P7: H4-C1
A8: PON-01 | B8: S4-01 | C8: A-4 | D8: Dự phòng | E8: — | F8: — | G8: — | H8: — | I8: — | J8: — | K8: — | L8: 0 | M8: 0 | N8: A-37 | O8: H1-C4 | P8: H4-C1
A9: PON-02 | B9: S4-02 | C9: A-5 | D9: Đã dùng | E9: ODF-02 | F9: Trái | G9: H2-C3 | H9: TR-A1/09 | I9: Ống 2 Cam / Xanh lá | J9: TU-A5 | K9: TU-A5/S1 | L9: =COUNTIF('Thuê bao'!$F$2:$F$677,K9) | M9: =COUNTIFS('Thuê bao'!$F$2:$F$677,K9,'Thuê bao'!$N$2:$N$677,"Hoạt động") | N9: A-38 | O9: H1-C5 | P9: H4-C2
A10: PON-02 | B10: S4-02 | C10: A-6 | D10: Đã dùng | E10: ODF-02 | F10: Trái | G10: H2-C4 | H10: TR-A1/10 | I10: Ống 2 Cam / Nâu | J10: TU-A5 | K10: TU-A5/S2 | L10: =COUNTIF('Thuê bao'!$F$2:$F$677,K10) | M10: =COUNTIFS('Thuê bao'!$F$2:$F$677,K10,'Thuê bao'!$N$2:$N$677,"Hoạt động") | N10: A-38 | O10: H1-C6 | P10: H4-C2
A11: PON-02 | B11: S4-02 | C11: A-7 | D11: Đã dùng | E11: ODF-02 | F11: Trái | G11: H2-C5 | H11: TR-A1/11 | I11: Ống 2 Cam / Xám | J11: TU-A5 | K11: TU-A5/S3 | L11: =COUNTIF('Thuê bao'!$F$2:$F$677,K11) | M11: =COUNTIFS('Thuê bao'!$F$2:$F$677,K11,'Thuê bao'!$N$2:$N$677,"Hoạt động") | N11: A-38 | O11: H1-C7 | P11: H4-C2
A12: PON-02 | B12: S4-02 | C12: A-8 | D12: Dự phòng | E12: — | F12: — | G12: — | H12: — | I12: — | J12: — | K12: — | L12: 0 | M12: 0 | N12: A-38 | O12: H1-C8 | P12: H4-C2
A13: PON-03 | B13: S4-03 | C13: A-9 | D13: Đã dùng | E13: ODF-02 | F13: Trái | G13: H3-C5 | H13: TR-A1/17 | I13: Ống 3 Xanh lá / Xám | J13: TU-A7 | K13: TU-A7/S1 | L13: =COUNTIF('Thuê bao'!$F$2:$F$677,K13) | M13: =COUNTIFS('Thuê bao'!$F$2:$F$677,K13,'Thuê bao'!$N$2:$N$677,"Hoạt động") | N13: A-39 | O13: H1-C9 | P13: H4-C3
A14: PON-03 | B14: S4-03 | C14: A-10 | D14: Đã dùng | E14: ODF-02 | F14: Trái | G14: H3-C6 | H14: TR-A1/18 | I14: Ống 3 Xanh lá / Trắng | J14: TU-A7 | K14: TU-A7/S2 | L14: =COUNTIF('Thuê bao'!$F$2:$F$677,K14) | M14: =COUNTIFS('Thuê bao'!$F$2:$F$677,K14,'Thuê bao'!$N$2:$N$677,"Hoạt động") | N14: A-39 | O14: H1-C10 | P14: H4-C3
A15: PON-03 | B15: S4-03 | C15: A-11 | D15: Đã dùng | E15: ODF-02 | F15: Trái | G15: H4-C1 | H15: TR-A1/19 | I15: Ống 4 Nâu / Xanh dương | J15: TU-A7 | K15: TU-A7/S3 | L15: =COUNTIF('Thuê bao'!$F$2:$F$677,K15) | M15: =COUNTIFS('Thuê bao'!$F$2:$F$677,K15,'Thuê bao'!$N$2:$N$677,"Hoạt động") | N15: A-39 | O15: H1-C11 | P15: H4-C3
A16: PON-03 | B16: S4-03 | C16: A-12 | D16: Dự phòng | E16: — | F16: — | G16: — | H16: — | I16: — | J16: — | K16: — | L16: 0 | M16: 0 | N16: A-39 | O16: H1-C12 | P16: H4-C3
A17: PON-04 | B17: S4-04 | C17: A-13 | D17: Đã dùng | E17: ODF-08/09 | F17: Trái | G17: H1-C1 | H17: TR-A2/01 | I17: Ống 1 Xanh dương / Xanh dương | J17: TU-A9 | K17: TU-A9/S1 | L17: =COUNTIF('Thuê bao'!$F$2:$F$677,K17) | M17: =COUNTIFS('Thuê bao'!$F$2:$F$677,K17,'Thuê bao'!$N$2:$N$677,"Hoạt động") | N17: A-40 | O17: H2-C1 | P17: H4-C4
A18: PON-04 | B18: S4-04 | C18: A-14 | D18: Đã dùng | E18: ODF-08/09 | F18: Trái | G18: H1-C2 | H18: TR-A2/02 | I18: Ống 1 Xanh dương / Cam | J18: TU-A9 | K18: TU-A9/S2 | L18: =COUNTIF('Thuê bao'!$F$2:$F$677,K18) | M18: =COUNTIFS('Thuê bao'!$F$2:$F$677,K18,'Thuê bao'!$N$2:$N$677,"Hoạt động") | N18: A-40 | O18: H2-C2 | P18: H4-C4
A19: PON-04 | B19: S4-04 | C19: A-15 | D19: Đã dùng | E19: ODF-08/09 | F19: Trái | G19: H1-C3 | H19: TR-A2/03 | I19: Ống 1 Xanh dương / Xanh lá | J19: TU-A9 | K19: TU-A9/S3 | L19: =COUNTIF('Thuê bao'!$F$2:$F$677,K19) | M19: =COUNTIFS('Thuê bao'!$F$2:$F$677,K19,'Thuê bao'!$N$2:$N$677,"Hoạt động") | N19: A-40 | O19: H2-C3 | P19: H4-C4
A20: PON-04 | B20: S4-04 | C20: A-16 | D20: Dự phòng | E20: — | F20: — | G20: — | H20: — | I20: — | J20: — | K20: — | L20: 0 | M20: 0 | N20: A-40 | O20: H2-C4 | P20: H4-C4
A21: PON-05 | B21: S4-05 | C21: A-17 | D21: Đã dùng | E21: ODF-08/09 | F21: Trái | G21: H2-C3 | H21: TR-A2/09 | I21: Ống 2 Cam / Xanh lá | J21: TU-A12 | K21: TU-A12/S1 | L21: =COUNTIF('Thuê bao'!$F$2:$F$677,K21) | M21: =COUNTIFS('Thuê bao'!$F$2:$F$677,K21,'Thuê bao'!$N$2:$N$677,"Hoạt động") | N21: A-41 | O21: H2-C5 | P21: H4-C5
A22: PON-05 | B22: S4-05 | C22: A-18 | D22: Đã dùng | E22: ODF-08/09 | F22: Trái | G22: H2-C4 | H22: TR-A2/10 | I22: Ống 2 Cam / Nâu | J22: TU-A12 | K22: TU-A12/S2 | L22: =COUNTIF('Thuê bao'!$F$2:$F$677,K22) | M22: =COUNTIFS('Thuê bao'!$F$2:$F$677,K22,'Thuê bao'!$N$2:$N$677,"Hoạt động") | N22: A-41 | O22: H2-C6 | P22: H4-C5
A23: PON-05 | B23: S4-05 | C23: A-19 | D23: Đã dùng | E23: ODF-08/09 | F23: Trái | G23: H2-C5 | H23: TR-A2/11 | I23: Ống 2 Cam / Xám | J23: TU-A12 | K23: TU-A12/S3 | L23: =COUNTIF('Thuê bao'!$F$2:$F$677,K23) | M23: =COUNTIFS('Thuê bao'!$F$2:$F$677,K23,'Thuê bao'!$N$2:$N$677,"Hoạt động") | N23: A-41 | O23: H2-C7 | P23: H4-C5
A24: PON-05 | B24: S4-05 | C24: A-20 | D24: Dự phòng | E24: — | F24: — | G24: — | H24: — | I24: — | J24: — | K24: — | L24: 0 | M24: 0 | N24: A-41 | O24: H2-C8 | P24: H4-C5
A25: PON-06 | B25: S4-06 | C25: A-21 | D25: Đã dùng | E25: ODF-08/09 | F25: Trái | G25: H3-C5 | H25: TR-A2/17 | I25: Ống 3 Xanh lá / Xám | J25: TU-A15 | K25: TU-A15/S1 | L25: =COUNTIF('Thuê bao'!$F$2:$F$677,K25) | M25: =COUNTIFS('Thuê bao'!$F$2:$F$677,K25,'Thuê bao'!$N$2:$N$677,"Hoạt động") | N25: A-42 | O25: H2-C9 | P25: H4-C6
A26: PON-06 | B26: S4-06 | C26: A-22 | D26: Đã dùng | E26: ODF-08/09 | F26: Trái | G26: H3-C6 | H26: TR-A2/18 | I26: Ống 3 Xanh lá / Trắng | J26: TU-A15 | K26: TU-A15/S2 | L26: =COUNTIF('Thuê bao'!$F$2:$F$677,K26) | M26: =COUNTIFS('Thuê bao'!$F$2:$F$677,K26,'Thuê bao'!$N$2:$N$677,"Hoạt động") | N26: A-42 | O26: H2-C10 | P26: H4-C6
A27: PON-06 | B27: S4-06 | C27: A-23 | D27: Đã dùng | E27: ODF-08/09 | F27: Trái | G27: H4-C1 | H27: TR-A2/19 | I27: Ống 4 Nâu / Xanh dương | J27: TU-A15 | K27: TU-A15/S3 | L27: =COUNTIF('Thuê bao'!$F$2:$F$677,K27) | M27: =COUNTIFS('Thuê bao'!$F$2:$F$677,K27,'Thuê bao'!$N$2:$N$677,"Hoạt động") | N27: A-42 | O27: H2-C11 | P27: H4-C6
A28: PON-06 | B28: S4-06 | C28: A-24 | D28: Dự phòng | E28: — | F28: — | G28: — | H28: — | I28: — | J28: — | K28: — | L28: 0 | M28: 0 | N28: A-42 | O28: H2-C12 | P28: H4-C6
A29: PON-07 | B29: S4-07 | C29: A-25 | D29: Đã dùng | E29: ODF-17/18 | F29: Trái | G29: H1-C1 | H29: TR-A3/01 | I29: Ống 1 Xanh dương / Xanh dương | J29: TU-A18 | K29: TU-A18/S1 | L29: =COUNTIF('Thuê bao'!$F$2:$F$677,K29) | M29: =COUNTIFS('Thuê bao'!$F$2:$F$677,K29,'Thuê bao'!$N$2:$N$677,"Hoạt động") | N29: A-43 | O29: H3-C1 | P29: H4-C7
A30: PON-07 | B30: S4-07 | C30: A-26 | D30: Đã dùng | E30: ODF-17/18 | F30: Trái | G30: H1-C2 | H30: TR-A3/02 | I30: Ống 1 Xanh dương / Cam | J30: TU-A18 | K30: TU-A18/S2 | L30: =COUNTIF('Thuê bao'!$F$2:$F$677,K30) | M30: =COUNTIFS('Thuê bao'!$F$2:$F$677,K30,'Thuê bao'!$N$2:$N$677,"Hoạt động") | N30: A-43 | O30: H3-C2 | P30: H4-C7
A31: PON-07 | B31: S4-07 | C31: A-27 | D31: Đã dùng | E31: ODF-17/18 | F31: Trái | G31: H1-C3 | H31: TR-A3/03 | I31: Ống 1 Xanh dương / Xanh lá | J31: TU-A18 | K31: TU-A18/S3 | L31: =COUNTIF('Thuê bao'!$F$2:$F$677,K31) | M31: =COUNTIFS('Thuê bao'!$F$2:$F$677,K31,'Thuê bao'!$N$2:$N$677,"Hoạt động") | N31: A-43 | O31: H3-C3 | P31: H4-C7
A32: PON-07 | B32: S4-07 | C32: A-28 | D32: Dự phòng | E32: — | F32: — | G32: — | H32: — | I32: — | J32: — | K32: — | L32: 0 | M32: 0 | N32: A-43 | O32: H3-C4 | P32: H4-C7
A33: PON-08 | B33: S4-08 | C33: A-29 | D33: Đã dùng | E33: ODF-17/18 | F33: Trái | G33: H2-C3 | H33: TR-A3/09 | I33: Ống 2 Cam / Xanh lá | J33: TU-A21 | K33: TU-A21/S1 | L33: =COUNTIF('Thuê bao'!$F$2:$F$677,K33) | M33: =COUNTIFS('Thuê bao'!$F$2:$F$677,K33,'Thuê bao'!$N$2:$N$677,"Hoạt động") | N33: A-44 | O33: H3-C5 | P33: H4-C8
A34: PON-08 | B34: S4-08 | C34: A-30 | D34: Đã dùng | E34: ODF-17/18 | F34: Trái | G34: H2-C4 | H34: TR-A3/10 | I34: Ống 2 Cam / Nâu | J34: TU-A21 | K34: TU-A21/S2 | L34: =COUNTIF('Thuê bao'!$F$2:$F$677,K34) | M34: =COUNTIFS('Thuê bao'!$F$2:$F$677,K34,'Thuê bao'!$N$2:$N$677,"Hoạt động") | N34: A-44 | O34: H3-C6 | P34: H4-C8
A35: PON-08 | B35: S4-08 | C35: A-31 | D35: Đã dùng | E35: ODF-17/18 | F35: Trái | G35: H2-C5 | H35: TR-A3/11 | I35: Ống 2 Cam / Xám | J35: TU-A21 | K35: TU-A21/S3 | L35: =COUNTIF('Thuê bao'!$F$2:$F$677,K35) | M35: =COUNTIFS('Thuê bao'!$F$2:$F$677,K35,'Thuê bao'!$N$2:$N$677,"Hoạt động") | N35: A-44 | O35: H3-C7 | P35: H4-C8
A36: PON-08 | B36: S4-08 | C36: A-32 | D36: Đã dùng | E36: ODF-17/18 | F36: Trái | G36: H3-C5 | H36: TR-A3/17 | I36: Ống 3 Xanh lá / Xám | J36: TU-A23 | K36: TU-A23/S1 | L36: =COUNTIF('Thuê bao'!$F$2:$F$677,K36) | M36: =COUNTIFS('Thuê bao'!$F$2:$F$677,K36,'Thuê bao'!$N$2:$N$677,"Hoạt động") | N36: A-44 | O36: H3-C8 | P36: H4-C8
A37: PON-09 | B37: S4-09 | C37: B-1 | D37: Đã dùng | E37: ODF-02 | F37: Phải | G37: H1-C1 | H37: TR-B1/01 | I37: Ống 1 Xanh dương / Xanh dương | J37: TU-B2 | K37: TU-B2/S1 | L37: =COUNTIF('Thuê bao'!$F$2:$F$677,K37) | M37: =COUNTIFS('Thuê bao'!$F$2:$F$677,K37,'Thuê bao'!$N$2:$N$677,"Hoạt động") | N37: B-37 | O37: H1-C1 | P37: H4-C1
A38: PON-09 | B38: S4-09 | C38: B-2 | D38: Đã dùng | E38: ODF-02 | F38: Phải | G38: H1-C2 | H38: TR-B1/02 | I38: Ống 1 Xanh dương / Cam | J38: TU-B2 | K38: TU-B2/S2 | L38: =COUNTIF('Thuê bao'!$F$2:$F$677,K38) | M38: =COUNTIFS('Thuê bao'!$F$2:$F$677,K38,'Thuê bao'!$N$2:$N$677,"Hoạt động") | N38: B-37 | O38: H1-C2 | P38: H4-C1
A39: PON-09 | B39: S4-09 | C39: B-3 | D39: Đã dùng | E39: ODF-02 | F39: Phải | G39: H1-C3 | H39: TR-B1/03 | I39: Ống 1 Xanh dương / Xanh lá | J39: TU-B2 | K39: TU-B2/S3 | L39: =COUNTIF('Thuê bao'!$F$2:$F$677,K39) | M39: =COUNTIFS('Thuê bao'!$F$2:$F$677,K39,'Thuê bao'!$N$2:$N$677,"Hoạt động") | N39: B-37 | O39: H1-C3 | P39: H4-C1
A40: PON-09 | B40: S4-09 | C40: B-4 | D40: Dự phòng | E40: — | F40: — | G40: — | H40: — | I40: — | J40: — | K40: — | L40: 0 | M40: 0 | N40: B-37 | O40: H1-C4 | P40: H4-C1
A41: PON-10 | B41: S4-10 | C41: B-5 | D41: Đã dùng | E41: ODF-02 | F41: Phải | G41: H1-C4 | H41: TR-B1/04 | I41: Ống 1 Xanh dương / Nâu | J41: TU-B2 | K41: TU-B2/S4 | L41: =COUNTIF('Thuê bao'!$F$2:$F$677,K41) | M41: =COUNTIFS('Thuê bao'!$F$2:$F$677,K41,'Thuê bao'!$N$2:$N$677,"Hoạt động") | N41: B-38 | O41: H1-C5 | P41: H4-C2
...

Sheet ODF 96FO
A1: ODF 96FO tại Phòng máy – chia 2 nửa 4×12: TRÁI = Tháp A, PHẢI = Tháp B
A2: Mỗi nửa 48 cổng, đếm từ DƯỚI lên, từ TRÁI qua phải, mỗi nửa đếm lại từ 1 (hàng 1 = cổng 1-12). Cổng 1-32 = đầu ra splitter (4 cổng/splitter); 33-36 trống; 37-44 = đầu vào splitter (nối OLT); 45-48 trống.
B3: NỬA TRÁI – THÁP A (PON 1-8) | O3: NỬA PHẢI – THÁP B (PON 9-16)
A4: Hàng 4 | B4: A-37 VÀO S4-01 OLT PON-01 | C4: A-38 VÀO S4-02 OLT PON-02 | D4: A-39 VÀO S4-03 OLT PON-03 | E4: A-40 VÀO S4-04 OLT PON-04 | F4: A-41 VÀO S4-05 OLT PON-05 | G4: A-42 VÀO S4-06 OLT PON-06 | H4: A-43 VÀO S4-07 OLT PON-07 | I4: A-44 VÀO S4-08 OLT PON-08 | J4: A-45 trống | K4: A-46 trống | L4: A-47 trống | M4: A-48 trống | O4: B-37 VÀO S4-09 OLT PON-09 | P4: B-38 VÀO S4-10 OLT PON-10 | Q4: B-39 VÀO S4-11 OLT PON-11 | R4: B-40 VÀO S4-12 OLT PON-12 | S4: B-41 VÀO S4-13 OLT PON-13 | T4: B-42 VÀO S4-14 OLT PON-14 | U4: B-43 VÀO S4-15 OLT PON-15 | V4: B-44 VÀO S4-16 OLT PON-16 | W4: B-45 trống | X4: B-46 trống | Y4: B-47 trống | Z4: B-48 trống
A5: Hàng 3 | B5: A-25 A18/S1 PON-07 | C5: A-26 A18/S2 PON-07 | D5: A-27 A18/S3 PON-07 | E5: A-28 dự phòng PON-07 | F5: A-29 A21/S1 PON-08 | G5: A-30 A21/S2 PON-08 | H5: A-31 A21/S3 PON-08 | I5: A-32 A23/S1 PON-08 | J5: A-33 trống | K5: A-34 trống | L5: A-35 trống | M5: A-36 trống | O5: B-25 B17/S2 PON-15 | P5: B-26 B17/S3 PON-15 | Q5: B-27 B20/S1 PON-15 | R5: B-28 dự phòng PON-15 | S5: B-29 B20/S2 PON-16 | T5: B-30 B20/S3 PON-16 | U5: B-31 B23/S1 PON-16 | V5: B-32 B23/S2 PON-16 | W5: B-33 trống | X5: B-34 trống | Y5: B-35 trống | Z5: B-36 trống
A6: Hàng 2 | B6: A-13 A9/S1 PON-04 | C6: A-14 A9/S2 PON-04 | D6: A-15 A9/S3 PON-04 | E6: A-16 dự phòng PON-04 | F6: A-17 A12/S1 PON-05 | G6: A-18 A12/S2 PON-05 | H6: A-19 A12/S3 PON-05 | I6: A-20 dự phòng PON-05 | J6: A-21 A15/S1 PON-06 | K6: A-22 A15/S2 PON-06 | L6: A-23 A15/S3 PON-06 | M6: A-24 dự phòng PON-06 | O6: B-13 B8/S2 PON-12 | P6: B-14 B8/S3 PON-12 | Q6: B-15 B11/S1 PON-12 | R6: B-16 dự phòng PON-12 | S6: B-17 B11/S2 PON-13 | T6: B-18 B11/S3 PON-13 | U6: B-19 B14/S1 PON-13 | V6: B-20 dự phòng PON-13 | W6: B-21 B14/S2 PON-14 | X6: B-22 B14/S3 PON-14 | Y6: B-23 B17/S1 PON-14 | Z6: B-24 dự phòng PON-14
A7: Hàng 1 | B7: A-1 A2/S1 PON-01 | C7: A-2 A2/S2 PON-01 | D7: A-3 A2/S3 PON-01 | E7: A-4 dự phòng PON-01 | F7: A-5 A5/S1 PON-02 | G7: A-6 A5/S2 PON-02 | H7: A-7 A5/S3 PON-02 | I7: A-8 dự phòng PON-02 | J7: A-9 A7/S1 PON-03 | K7: A-10 A7/S2 PON-03 | L7: A-11 A7/S3 PON-03 | M7: A-12 dự phòng PON-03 | O7: B-1 B2/S1 PON-09 | P7: B-2 B2/S2 PON-09 | Q7: B-3 B2/S3 PON-09 | R7: B-4 dự phòng PON-09 | S7: B-5 B2/S4 PON-10 | T7: B-6 B2/S5 PON-10 | U7: B-7 B5/S1 PON-10 | V7: B-8 dự phòng PON-10 | W7: B-9 B5/S2 PON-11 | X7: B-10 B5/S3 PON-11 | Y7: B-11 B8/S1 PON-11 | Z7: B-12 dự phòng PON-11
B8: Cột 1 | C8: Cột 2 | D8: Cột 3 | E8: Cột 4 | F8: Cột 5 | G8: Cột 6 | H8: Cột 7 | I8: Cột 8 | J8: Cột 9 | K8: Cột 10 | L8: Cột 11 | M8: Cột 12 | O8: Cột 1 | P8: Cột 2 | Q8: Cột 3 | R8: Cột 4 | S8: Cột 5 | T8: Cột 6 | U8: Cột 7 | V8: Cột 8 | W8: Cột 9 | X8: Cột 10 | Y8: Cột 11 | Z8: Cột 12
A10: Mỗi PON một màu: ô nhạt = đầu ra (tới ODF-48), ô đậm "VÀO" = đầu vào splitter (từ OLT). Ví dụ nửa trái: splitter S4-01 vào A-37, ra A-1…A-4; S4-08 vào A-44, ra A-29…A-32. Nửa phải: S4-09 vào B-37, ra B-1…B-4.

Sheet ODF 48FO
A1: ODF 48FO tại Phòng máy (tầng hầm B1) – 3 ODF × 2 khay
A2: Khay TRÁI = Tháp A, khay PHẢI = Tháp B. Mỗi khay 4 hàng × 6 cột coupler = 24FO; đánh số từ DƯỚI lên, từ TRÁI qua (hàng 1 = dưới cùng = ống đệm 1). Nhìn từ mặt trước ODF.
A4: ODF-02 (48FO) – hàn 2 cáp trục 24FO
B5: KHAY TRÁI – THÁP A – TR-A1 | I5: KHAY PHẢI – THÁP B – TR-B1
A6: Hàng 4 ống Nâu | B6: Sợi 19 · Xanh dương TU-A7/S3 PON-03 · P96 A-11 | C6: Sợi 20 · Cam dự phòng | D6: Sợi 21 · Xanh lá dự phòng | E6: Sợi 22 · Nâu dự phòng | F6: Sợi 23 · Xám dự phòng | G6: Sợi 24 · Trắng dự phòng | I6: Sợi 19 · Xanh dương dự phòng | J6: Sợi 20 · Cam dự phòng | K6: Sợi 21 · Xanh lá dự phòng | L6: Sợi 22 · Nâu dự phòng | M6: Sợi 23 · Xám dự phòng | N6: Sợi 24 · Trắng dự phòng
A7: Hàng 3 ống Xanh lá | B7: Sợi 13 · Xanh dương dự phòng | C7: Sợi 14 · Cam dự phòng | D7: Sợi 15 · Xanh lá dự phòng | E7: Sợi 16 · Nâu dự phòng | F7: Sợi 17 · Xám TU-A7/S1 PON-03 · P96 A-9 | G7: Sợi 18 · Trắng TU-A7/S2 PON-03 · P96 A-10 | I7: Sợi 13 · Xanh dương dự phòng | J7: Sợi 14 · Cam dự phòng | K7: Sợi 15 · Xanh lá dự phòng | L7: Sợi 16 · Nâu dự phòng | M7: Sợi 17 · Xám dự phòng | N7: Sợi 18 · Trắng dự phòng
A8: Hàng 2 ống Cam | B8: Sợi 7 · Xanh dương dự phòng | C8: Sợi 8 · Cam dự phòng | D8: Sợi 9 · Xanh lá TU-A5/S1 PON-02 · P96 A-5 | E8: Sợi 10 · Nâu TU-A5/S2 PON-02 · P96 A-6 | F8: Sợi 11 · Xám TU-A5/S3 PON-02 · P96 A-7 | G8: Sợi 12 · Trắng dự phòng | I8: Sợi 7 · Xanh dương dự phòng | J8: Sợi 8 · Cam dự phòng | K8: Sợi 9 · Xanh lá TU-B5/S1 PON-10 · P96 B-7 | L8: Sợi 10 · Nâu TU-B5/S2 PON-11 · P96 B-9 | M8: Sợi 11 · Xám TU-B5/S3 PON-11 · P96 B-10 | N8: Sợi 12 · Trắng dự phòng
A9: Hàng 1 ống Xanh dương | B9: Sợi 1 · Xanh dương TU-A2/S1 PON-01 · P96 A-1 | C9: Sợi 2 · Cam TU-A2/S2 PON-01 · P96 A-2 | D9: Sợi 3 · Xanh lá TU-A2/S3 PON-01 · P96 A-3 | E9: Sợi 4 · Nâu dự phòng | F9: Sợi 5 · Xám dự phòng | G9: Sợi 6 · Trắng dự phòng | I9: Sợi 1 · Xanh dương TU-B2/S1 PON-09 · P96 B-1 | J9: Sợi 2 · Cam TU-B2/S2 PON-09 · P96 B-2 | K9: Sợi 3 · Xanh lá TU-B2/S3 PON-09 · P96 B-3 | L9: Sợi 4 · Nâu TU-B2/S4 PON-10 · P96 B-5 | M9: Sợi 5 · Xám TU-B2/S5 PON-10 · P96 B-6 | N9: Sợi 6 · Trắng dự phòng
B10: Cột 1 | C10: Cột 2 | D10: Cột 3 | E10: Cột 4 | F10: Cột 5 | G10: Cột 6 | I10: Cột 1 | J10: Cột 2 | K10: Cột 3 | L10: Cột 4 | M10: Cột 5 | N10: Cột 6
A13: ODF-08/09 (48FO) – hàn 2 cáp trục 24FO
B14: KHAY TRÁI – THÁP A – TR-A2 | I14: KHAY PHẢI – THÁP B – TR-B2
A15: Hàng 4 ống Nâu | B15: Sợi 19 · Xanh dương TU-A15/S3 PON-06 · P96 A-23 | C15: Sợi 20 · Cam dự phòng | D15: Sợi 21 · Xanh lá dự phòng | E15: Sợi 22 · Nâu dự phòng | F15: Sợi 23 · Xám dự phòng | G15: Sợi 24 · Trắng dự phòng | I15: Sợi 19 · Xanh dương TU-B14/S3 PON-14 · P96 B-22 | J15: Sợi 20 · Cam dự phòng | K15: Sợi 21 · Xanh lá dự phòng | L15: Sợi 22 · Nâu dự phòng | M15: Sợi 23 · Xám dự phòng | N15: Sợi 24 · Trắng dự phòng
A16: Hàng 3 ống Xanh lá | B16: Sợi 13 · Xanh dương dự phòng | C16: Sợi 14 · Cam dự phòng | D16: Sợi 15 · Xanh lá dự phòng | E16: Sợi 16 · Nâu dự phòng | F16: Sợi 17 · Xám TU-A15/S1 PON-06 · P96 A-21 | G16: Sợi 18 · Trắng TU-A15/S2 PON-06 · P96 A-22 | I16: Sợi 13 · Xanh dương dự phòng | J16: Sợi 14 · Cam dự phòng | K16: Sợi 15 · Xanh lá dự phòng | L16: Sợi 16 · Nâu dự phòng | M16: Sợi 17 · Xám TU-B14/S1 PON-13 · P96 B-19 | N16: Sợi 18 · Trắng TU-B14/S2 PON-14 · P96 B-21
A17: Hàng 2 ống Cam | B17: Sợi 7 · Xanh dương dự phòng | C17: Sợi 8 · Cam dự phòng | D17: Sợi 9 · Xanh lá TU-A12/S1 PON-05 · P96 A-17 | E17: Sợi 10 · Nâu TU-A12/S2 PON-05 · P96 A-18 | F17: Sợi 11 · Xám TU-A12/S3 PON-05 · P96 A-19 | G17: Sợi 12 · Trắng dự phòng | I17: Sợi 7 · Xanh dương dự phòng | J17: Sợi 8 · Cam dự phòng | K17: Sợi 9 · Xanh lá TU-B11/S1 PON-12 · P96 B-15 | L17: Sợi 10 · Nâu TU-B11/S2 PON-13 · P96 B-17 | M17: Sợi 11 · Xám TU-B11/S3 PON-13 · P96 B-18 | N17: Sợi 12 · Trắng dự phòng
A18: Hàng 1 ống Xanh dương | B18: Sợi 1 · Xanh dương TU-A9/S1 PON-04 · P96 A-13 | C18: Sợi 2 · Cam TU-A9/S2 PON-04 · P96 A-14 | D18: Sợi 3 · Xanh lá TU-A9/S3 PON-04 · P96 A-15 | E18: Sợi 4 · Nâu dự phòng | F18: Sợi 5 · Xám dự phòng | G18: Sợi 6 · Trắng dự phòng | I18: Sợi 1 · Xanh dương TU-B8/S1 PON-11 · P96 B-11 | J18: Sợi 2 · Cam TU-B8/S2 PON-12 · P96 B-13 | K18: Sợi 3 · Xanh lá TU-B8/S3 PON-12 · P96 B-14 | L18: Sợi 4 · Nâu dự phòng | M18: Sợi 5 · Xám dự phòng | N18: Sợi 6 · Trắng dự phòng
B19: Cột 1 | C19: Cột 2 | D19: Cột 3 | E19: Cột 4 | F19: Cột 5 | G19: Cột 6 | I19: Cột 1 | J19: Cột 2 | K19: Cột 3 | L19: Cột 4 | M19: Cột 5 | N19: Cột 6
A22: ODF-17/18 (48FO) – hàn 2 cáp trục 24FO
B23: KHAY TRÁI – THÁP A – TR-A3 | I23: KHAY PHẢI – THÁP B – TR-B3
A24: Hàng 4 ống Nâu | B24: Sợi 19 · Xanh dương dự phòng | C24: Sợi 20 · Cam dự phòng | D24: Sợi 21 · Xanh lá dự phòng | E24: Sợi 22 · Nâu dự phòng | F24: Sợi 23 · Xám dự phòng | G24: Sợi 24 · Trắng dự phòng | I24: Sợi 19 · Xanh dương dự phòng | J24: Sợi 20 · Cam dự phòng | K24: Sợi 21 · Xanh lá dự phòng | L24: Sợi 22 · Nâu dự phòng | M24: Sợi 23 · Xám dự phòng | N24: Sợi 24 · Trắng dự phòng
A25: Hàng 3 ống Xanh lá | B25: Sợi 13 · Xanh dương dự phòng | C25: Sợi 14 · Cam dự phòng | D25: Sợi 15 · Xanh lá dự phòng | E25: Sợi 16 · Nâu dự phòng | F25: Sợi 17 · Xám TU-A23/S1 PON-08 · P96 A-32 | G25: Sợi 18 · Trắng dự phòng | I25: Sợi 13 · Xanh dương dự phòng | J25: Sợi 14 · Cam dự phòng | K25: Sợi 15 · Xanh lá dự phòng | L25: Sợi 16 · Nâu dự phòng | M25: Sợi 17 · Xám TU-B23/S1 PON-16 · P96 B-31 | N25: Sợi 18 · Trắng TU-B23/S2 PON-16 · P96 B-32
A26: Hàng 2 ống Cam | B26: Sợi 7 · Xanh dương dự phòng | C26: Sợi 8 · Cam dự phòng | D26: Sợi 9 · Xanh lá TU-A21/S1 PON-08 · P96 A-29 | E26: Sợi 10 · Nâu TU-A21/S2 PON-08 · P96 A-30 | F26: Sợi 11 · Xám TU-A21/S3 PON-08 · P96 A-31 | G26: Sợi 12 · Trắng dự phòng | I26: Sợi 7 · Xanh dương dự phòng | J26: Sợi 8 · Cam dự phòng | K26: Sợi 9 · Xanh lá TU-B20/S1 PON-15 · P96 B-27 | L26: Sợi 10 · Nâu TU-B20/S2 PON-16 · P96 B-29 | M26: Sợi 11 · Xám TU-B20/S3 PON-16 · P96 B-30 | N26: Sợi 12 · Trắng dự phòng
A27: Hàng 1 ống Xanh dương | B27: Sợi 1 · Xanh dương TU-A18/S1 PON-07 · P96 A-25 | C27: Sợi 2 · Cam TU-A18/S2 PON-07 · P96 A-26 | D27: Sợi 3 · Xanh lá TU-A18/S3 PON-07 · P96 A-27 | E27: Sợi 4 · Nâu dự phòng | F27: Sợi 5 · Xám dự phòng | G27: Sợi 6 · Trắng dự phòng | I27: Sợi 1 · Xanh dương TU-B17/S1 PON-14 · P96 B-23 | J27: Sợi 2 · Cam TU-B17/S2 PON-15 · P96 B-25 | K27: Sợi 3 · Xanh lá TU-B17/S3 PON-15 · P96 B-26 | L27: Sợi 4 · Nâu dự phòng | M27: Sợi 5 · Xám dự phòng | N27: Sợi 6 · Trắng dự phòng
B28: Cột 1 | C28: Cột 2 | D28: Cột 3 | E28: Cột 4 | F28: Cột 5 | G28: Cột 6 | I28: Cột 1 | J28: Cột 2 | K28: Cột 3 | L28: Cột 4 | M28: Cột 5 | N28: Cột 6
A31: Số coupler trên ODF: khay trái 1-24 (Tháp A), khay phải 25-48 (Tháp B) = 24 + số sợi trong cáp trục.

Sheet Dây nhảy PM
A1: Danh sách dây nhảy tại Phòng máy
A2: Loại 1: OLT PON → ODF-96 cổng vào (16 sợi). Loại 2: ODF-96 cổng ra → ODF-48 trục (một sợi cho mỗi splitter 1:16). Cập nhật cột "Tình trạng" khi thi công.
A4: STT | B4: Loại | C4: Đầu A | D4: Đầu B | E4: Ghi chú | F4: Tình trạng
A5: 1 | B5: OLT → ODF-96 | C5: OLT PON-01 | D5: ODF-96 nửa A cổng 37 (H4-C1) | E5: Đầu vào splitter 1:4 S4-01 | F5: Chưa cắm
A6: 2 | B6: OLT → ODF-96 | C6: OLT PON-02 | D6: ODF-96 nửa A cổng 38 (H4-C2) | E6: Đầu vào splitter 1:4 S4-02 | F6: Chưa cắm
A7: 3 | B7: OLT → ODF-96 | C7: OLT PON-03 | D7: ODF-96 nửa A cổng 39 (H4-C3) | E7: Đầu vào splitter 1:4 S4-03 | F7: Chưa cắm
A8: 4 | B8: OLT → ODF-96 | C8: OLT PON-04 | D8: ODF-96 nửa A cổng 40 (H4-C4) | E8: Đầu vào splitter 1:4 S4-04 | F8: Chưa cắm
A9: 5 | B9: OLT → ODF-96 | C9: OLT PON-05 | D9: ODF-96 nửa A cổng 41 (H4-C5) | E9: Đầu vào splitter 1:4 S4-05 | F9: Chưa cắm
A10: 6 | B10: OLT → ODF-96 | C10: OLT PON-06 | D10: ODF-96 nửa A cổng 42 (H4-C6) | E10: Đầu vào splitter 1:4 S4-06 | F10: Chưa cắm
A11: 7 | B11: OLT → ODF-96 | C11: OLT PON-07 | D11: ODF-96 nửa A cổng 43 (H4-C7) | E11: Đầu vào splitter 1:4 S4-07 | F11: Chưa cắm
A12: 8 | B12: OLT → ODF-96 | C12: OLT PON-08 | D12: ODF-96 nửa A cổng 44 (H4-C8) | E12: Đầu vào splitter 1:4 S4-08 | F12: Chưa cắm
A13: 9 | B13: OLT → ODF-96 | C13: OLT PON-09 | D13: ODF-96 nửa B cổng 37 (H4-C1) | E13: Đầu vào splitter 1:4 S4-09 | F13: Chưa cắm
A14: 10 | B14: OLT → ODF-96 | C14: OLT PON-10 | D14: ODF-96 nửa B cổng 38 (H4-C2) | E14: Đầu vào splitter 1:4 S4-10 | F14: Chưa cắm
A15: 11 | B15: OLT → ODF-96 | C15: OLT PON-11 | D15: ODF-96 nửa B cổng 39 (H4-C3) | E15: Đầu vào splitter 1:4 S4-11 | F15: Chưa cắm
A16: 12 | B16: OLT → ODF-96 | C16: OLT PON-12 | D16: ODF-96 nửa B cổng 40 (H4-C4) | E16: Đầu vào splitter 1:4 S4-12 | F16: Chưa cắm
... A70: 66 | B70: ODF-96 → ODF-48 | C70: ODF-96 nửa B cổng 32 (H3-C8) | D70: ODF-17/18 khay Phải H3-C6 (sợi 18 TR-B3) | E70: TU-B23/S2 · tầng 23 · PON-16 · 14 hộ | F70: Chưa cắm

Sheet Thuê bao
A1: Mã căn hộ | B1: Tháp | C1: Tầng | D1: Box | E1: Tủ phối quang | F1: Splitter 1:16 | G1: Cổng splitter | H1: Cáp trục | I1: Sợi trục (1-24) | J1: Ống đệm / màu sợi | K1: Splitter PM 1:4 | L1: ODF-96 cổng ra (nửa-số) | M1: PON | N1: Trạng thái | O1: Serial ONU / Ghi chú | P1: Ngày lắp | Q1: Đường quang (tự ghép) | R1: ODF-48 (trục) | S1: Khay | T1: Coupler ODF-48 (hàng-cột) | U1: ODF-96 cổng vào (nửa-số)
A2: A-23-01 | B2: A | C2: 23 | D2: 1 | E2: TU-A23 | F2: TU-A23/S1 | G2: 1 | H2: TR-A3 | I2: 17 | J2: Ống 3 Xanh lá / Xám | K2: S4-08 | L2: A-32 | M2: PON-08 | N2: Chưa lắp | Q2: =M2&" > P96#"&U2&" > "&K2&" > P96#"&L2&" > "&R2&" "&S2&" "&T2&" > "&H2&"#"&I2&" > "&F2&" p"&G2 | R2: ODF-17/18 | S2: Trái | T2: H3-C5 | U2: A-44
A3: A-23-02 | B3: A | C3: 23 | D3: 2 | E3: TU-A23 | F3: TU-A23/S1 | G3: 2 | H3: TR-A3 | I3: 17 | J3: Ống 3 Xanh lá / Xám | K3: S4-08 | L3: A-32 | M3: PON-08 | N3: Chưa lắp | Q3: =M3&" > P96#"&U3&" > "&K3&" > P96#"&L3&" > "&R3&" "&S3&" "&T3&" > "&H3&"#"&I3&" > "&F3&" p"&G3 | R3: ODF-17/18 | S3: Trái | T3: H3-C5 | U3: A-44
A4: A-23-03 | B4: A | C4: 23 | D4: 3 | E4: TU-A23 | F4: TU-A23/S1 | G4: 3 | H4: TR-A3 | I4: 17 | J4: Ống 3 Xanh lá / Xám | K4: S4-08 | L4: A-32 | M4: PON-08 | N4: Chưa lắp | Q4: =M4&" > P96#"&U4&" > "&K4&" > P96#"&L4&" > "&R4&" "&S4&" "&T4&" > "&H4&"#"&I4&" > "&F4&" p"&G4 | R4: ODF-17/18 | S4: Trái | T4: H3-C5 | U4: A-44
A5: A-23-04 | B5: A | C5: 23 | D5: 4 | E5: TU-A23 | F5: TU-A23/S1 | G5: 4 | H5: TR-A3 | I5: 17 | J5: Ống 3 Xanh lá / Xám | K5: S4-08 | L5: A-32 | M5: PON-08 | N5: Chưa lắp | Q5: =M5&" > P96#"&U5&" > "&K5&" > P96#"&L5&" > "&R5&" "&S5&" "&T5&" > "&H5&"#"&I5&" > "&F5&" p"&G5 | R5: ODF-17/18 | S5: Trái | T5: H3-C5 | U5: A-44
A6: A-23-05 | B6: A | C6: 23 | D6: 5 | E6: TU-A23 | F6: TU-A23/S1 | G6: 5 | H6: TR-A3 | I6: 17 | J6: Ống 3 Xanh lá / Xám | K6: S4-08 | L6: A-32 | M6: PON-08 | N6: Chưa lắp | Q6: =M6&" > P96#"&U6&" > "&K6&" > P96#"&L6&" > "&R6&" "&S6&" "&T6&" > "&H6&"#"&I6&" > "&F6&" p"&G6 | R6: ODF-17/18 | S6: Trái | T6: H3-C5 | U6: A-44
A7: A-23-06 | B7: A | C7: 23 | D7: 6 | E7: TU-A23 | F7: TU-A23/S1 | G7: 6 | H7: TR-A3 | I7: 17 | J7: Ống 3 Xanh lá / Xám | K7: S4-08 | L7: A-32 | M7: PON-08 | N7: Chưa lắp | Q7: =M7&" > P96#"&U7&" > "&K7&" > P96#"&L7&" > "&R7&" "&S7&" "&T7&" > "&H7&"#"&I7&" > "&F7&" p"&G7 | R7: ODF-17/18 | S7: Trái | T7: H3-C5 | U7: A-44
A8: A-23-07 | B8: A | C8: 23 | D8: 7 | E8: TU-A23 | F8: TU-A23/S1 | G8: 7 | H8: TR-A3 | I8: 17 | J8: Ống 3 Xanh lá / Xám | K8: S4-08 | L8: A-32 | M8: PON-08 | N8: Chưa lắp | Q8: =M8&" > P96#"&U8&" > "&K8&" > P96#"&L8&" > "&R8&" "&S8&" "&T8&" > "&H8&"#"&I8&" > "&F8&" p"&G8 | R8: ODF-17/18 | S8: Trái | T8: H3-C5 | U8: A-44
A9: A-23-08 | B9: A | C9: 23 | D9: 8 | E9: TU-A23 | F9: TU-A23/S1 | G9: 8 | H9: TR-A3 | I9: 17 | J9: Ống 3 Xanh lá / Xám | K9: S4-08 | L9: A-32 | M9: PON-08 | N9: Chưa lắp | Q9: =M9&" > P96#"&U9&" > "&K9&" > P96#"&L9&" > "&R9&" "&S9&" "&T9&" > "&H9&"#"&I9&" > "&F9&" p"&G9 | R9: ODF-17/18 | S9: Trái | T9: H3-C5 | U9: A-44
A10: A-23-09 | B10: A | C10: 23 | D10: 9 | E10: TU-A23 | F10: TU-A23/S1 | G10: 9 | H10: TR-A3 | I10: 17 | J10: Ống 3 Xanh lá / Xám | K10: S4-08 | L10: A-32 | M10: PON-08 | N10: Chưa lắp | Q10: =M10&" > P96#"&U10&" > "&K10&" > P96#"&L10&" > "&R10&" "&S10&" "&T10&" > "&H10&"#"&I10&" > "&F10&" p"&G10 | R10: ODF-17/18 | S10: Trái | T10: H3-C5 | U10: A-44
A11: A-23-10 | B11: A | C11: 23 | D11: 10 | E11: TU-A23 | F11: TU-A23/S1 | G11: 10 | H11: TR-A3 | I11: 17 | J11: Ống 3 Xanh lá / Xám | K11: S4-08 | L11: A-32 | M11: PON-08 | N11: Chưa lắp | Q11: =M11&" > P96#"&U11&" > "&K11&" > P96#"&L11&" > "&R11&" "&S11&" "&T11&" > "&H11&"#"&I11&" > "&F11&" p"&G11 | R11: ODF-17/18 | S11: Trái | T11: H3-C5 | U11: A-44
A12: A-23-11 | B12: A | C12: 23 | D12: 11 | E12: TU-A23 | F12: TU-A23/S1 | G12: 11 | H12: TR-A3 | I12: 17 | J12: Ống 3 Xanh lá / Xám | K12: S4-08 | L12: A-32 | M12: PON-08 | N12: Chưa lắp | Q12: =M12&" > P96#"&U12&" > "&K12&" > P96#"&L12&" > "&R12&" "&S12&" "&T12&" > "&H12&"#"&I12&" > "&F12&" p"&G12 | R12: ODF-17/18 | S12: Trái | T12: H3-C5 | U12: A-44
A13: A-23-12 | B13: A | C13: 23 | D13: 12 | E13: TU-A23 | F13: TU-A23/S1 | G13: 12 | H13: TR-A3 | I13: 17 | J13: Ống 3 Xanh lá / Xám | K13: S4-08 | L13: A-32 | M13: PON-08 | N13: Chưa lắp | Q13: =M13&" > P96#"&U13&" > "&K13&" > P96#"&L13&" > "&R13&" "&S13&" "&T13&" > "&H13&"#"&I13&" > "&F13&" p"&G13 | R13: ODF-17/18 | S13: Trái | T13: H3-C5 | U13: A-44
... A677: B-1-09 | B677: B | C677: 1 | D677: 9 | E677: TU-B2 | F677: TU-B2/S1 | G677: 9 | H677: TR-B1 | I677: 1 | J677: Ống 1 Xanh dương / Xanh dương | K677: S4-09 | L677: B-1 | M677: PON-09 | N677: Chưa lắp | Q677: =M677&" > P96#"&U677&" > "&K677&" > P96#"&L677&" > "&R677&" "&S677&" "&T677&" > "&H677&"#"&I677&" > "&F677&" p"&G677 | R677: ODF-02 | S677: Phải | T677: H1-C1 | U677: B-37

Sheet Tra cứu
A1: Tra cứu đường quang
A2: Chọn mã căn hộ ở ô vàng (gõ hoặc chọn từ danh sách).
B4: MÃ CĂN HỘ | C4: A-18-05 | E4: TỦ → SPLITTER
B5: Tháp | C5: =IFERROR(INDEX('Thuê bao'!$B$2:$B$677,MATCH($C$4,'Thuê bao'!$A$2:$A$677,0))&"","Không tìm thấy") | E5: Chọn tủ: | F5: TU-A18
B6: Tầng | C6: =IFERROR(INDEX('Thuê bao'!$C$2:$C$677,MATCH($C$4,'Thuê bao'!$A$2:$A$677,0))&"","Không tìm thấy") | E6: Splitter | F6: Căn hộ | G6: Hoạt động | H6: Còn trống | I6: PON
B7: Box | C7: =IFERROR(INDEX('Thuê bao'!$D$2:$D$677,MATCH($C$4,'Thuê bao'!$A$2:$A$677,0))&"","Không tìm thấy") | E7: =$F$5&"/S1" | F7: =COUNTIF('Thuê bao'!$F$2:$F$677,E7) | G7: =COUNTIFS('Thuê bao'!$F$2:$F$677,E7,'Thuê bao'!$N$2:$N$677,"Hoạt động") | H7: =IF(F7=0,"chưa lắp",16-F7) | I7: =IFERROR(INDEX('Thuê bao'!$M$2:$M$677,MATCH(E7,'Thuê bao'!$F$2:$F$677,0))&"","—")
B8: Tủ phối quang | C8: =IFERROR(INDEX('Thuê bao'!$E$2:$E$677,MATCH($C$4,'Thuê bao'!$A$2:$A$677,0))&"","Không tìm thấy") | E8: =$F$5&"/S2" | F8: =COUNTIF('Thuê bao'!$F$2:$F$677,E8) | G8: =COUNTIFS('Thuê bao'!$F$2:$F$677,E8,'Thuê bao'!$N$2:$N$677,"Hoạt động") | H8: =IF(F8=0,"chưa lắp",16-F8) | I8: =IFERROR(INDEX('Thuê bao'!$M$2:$M$677,MATCH(E8,'Thuê bao'!$F$2:$F$677,0))&"","—")
B9: Splitter 1:16 tại tủ | C9: =IFERROR(INDEX('Thuê bao'!$F$2:$F$677,MATCH($C$4,'Thuê bao'!$A$2:$A$677,0))&"","Không tìm thấy") | E9: =$F$5&"/S3" | F9: =COUNTIF('Thuê bao'!$F$2:$F$677,E9) | G9: =COUNTIFS('Thuê bao'!$F$2:$F$677,E9,'Thuê bao'!$N$2:$N$677,"Hoạt động") | H9: =IF(F9=0,"chưa lắp",16-F9) | I9: =IFERROR(INDEX('Thuê bao'!$M$2:$M$677,MATCH(E9,'Thuê bao'!$F$2:$F$677,0))&"","—")
B10: Cổng splitter | C10: =IFERROR(INDEX('Thuê bao'!$G$2:$G$677,MATCH($C$4,'Thuê bao'!$A$2:$A$677,0))&"","Không tìm thấy") | E10: =$F$5&"/S4" | F10: =COUNTIF('Thuê bao'!$F$2:$F$677,E10) | G10: =COUNTIFS('Thuê bao'!$F$2:$F$677,E10,'Thuê bao'!$N$2:$N$677,"Hoạt động") | H10: =IF(F10=0,"chưa lắp",16-F10) | I10: =IFERROR(INDEX('Thuê bao'!$M$2:$M$677,MATCH(E10,'Thuê bao'!$F$2:$F$677,0))&"","—")
B11: Cáp trục | C11: =IFERROR(INDEX('Thuê bao'!$H$2:$H$677,MATCH($C$4,'Thuê bao'!$A$2:$A$677,0))&"","Không tìm thấy") | E11: =$F$5&"/S5" | F11: =COUNTIF('Thuê bao'!$F$2:$F$677,E11) | G11: =COUNTIFS('Thuê bao'!$F$2:$F$677,E11,'Thuê bao'!$N$2:$N$677,"Hoạt động") | H11: =IF(F11=0,"chưa lắp",16-F11) | I11: =IFERROR(INDEX('Thuê bao'!$M$2:$M$677,MATCH(E11,'Thuê bao'!$F$2:$F$677,0))&"","—")
B12: Sợi trục | C12: =IFERROR(INDEX('Thuê bao'!$I$2:$I$677,MATCH($C$4,'Thuê bao'!$A$2:$A$677,0))&"","Không tìm thấy")
B13: Ống đệm / màu sợi | C13: =IFERROR(INDEX('Thuê bao'!$J$2:$J$677,MATCH($C$4,'Thuê bao'!$A$2:$A$677,0))&"","Không tìm thấy")
B14: ODF-48 (trục) | C14: =IFERROR(INDEX('Thuê bao'!$R$2:$R$677,MATCH($C$4,'Thuê bao'!$A$2:$A$677,0))&"","Không tìm thấy")
B15: Khay | C15: =IFERROR(INDEX('Thuê bao'!$S$2:$S$677,MATCH($C$4,'Thuê bao'!$A$2:$A$677,0))&"","Không tìm thấy")
B16: Coupler ODF-48 | C16: =IFERROR(INDEX('Thuê bao'!$T$2:$T$677,MATCH($C$4,'Thuê bao'!$A$2:$A$677,0))&"","Không tìm thấy")
B17: Splitter PM 1:4 | C17: =IFERROR(INDEX('Thuê bao'!$K$2:$K$677,MATCH($C$4,'Thuê bao'!$A$2:$A$677,0))&"","Không tìm thấy")
B18: ODF-96 cổng ra (nửa-số) | C18: =IFERROR(INDEX('Thuê bao'!$L$2:$L$677,MATCH($C$4,'Thuê bao'!$A$2:$A$677,0))&"","Không tìm thấy")
B19: ODF-96 cổng vào (OLT) | C19: =IFERROR(INDEX('Thuê bao'!$U$2:$U$677,MATCH($C$4,'Thuê bao'!$A$2:$A$677,0))&"","Không tìm thấy")
B20: PON | C20: =IFERROR(INDEX('Thuê bao'!$M$2:$M$677,MATCH($C$4,'Thuê bao'!$A$2:$A$677,0))&"","Không tìm thấy")
B21: Trạng thái | C21: =IFERROR(INDEX('Thuê bao'!$N$2:$N$677,MATCH($C$4,'Thuê bao'!$A$2:$A$677,0))&"","Không tìm thấy")
B22: Serial / Ghi chú | C22: =IFERROR(INDEX('Thuê bao'!$O$2:$O$677,MATCH($C$4,'Thuê bao'!$A$2:$A$677,0))&"","Không tìm thấy")
B23: Đường quang | C23: =IFERROR(INDEX('Thuê bao'!$Q$2:$Q$677,MATCH($C$4,'Thuê bao'!$A$2:$A$677,0))&"","Không tìm thấy")

Sheet Sự cố & khắc phục
A1: Sự cố tuyến quang và phương án khắc phục (từ dây nhảy PON ở OLT đến fast connector cắm modem)
A2: Phạm vi: OLT (cổng PON, SFP) → dây nhảy → ODF-96 → splitter 1:4 → ODF-96 → dây nhảy → ODF-48 → cáp trục 24FO → cáp nhánh 8FO → tủ (splitter 1:16) → cáp 1FO → hộp BOX → fast connector. Số hộ ảnh hưởng tính từ dữ liệu thiết kế.
A4: Mã | B4: Đoạn tuyến | C4: Sự cố | D4: Phạm vi | E4: Số hộ ảnh hưởng (nhỏ nhất / TB / lớn nhất) | F4: Triệu chứng | G4: Chẩn đoán và đo kiểm | H4: Khắc phục tạm thời | I4: Khắc phục dứt điểm | J4: Phòng ngừa | K4: Ưu tiên | L4: Thời gian mục tiêu (ước tính)
A5: P1 | B5: OLT: cổng PON và module quang SFP | C5: Cổng PON / SFP trên OLT hỏng hoặc phát yếu | D5: Cả 1 PON | E5: 31 / 42 / 56 | F5: Toàn bộ ONU của PON mất tín hiệu (LOS) cùng một lúc; OLT báo PON port down hoặc Tx power thấp; các PON khác bình thường. | G5: Xem trạng thái và DDM của SFP trên OLT (Tx power, nhiệt độ, dòng bias). Đo công suất phát bằng OPM tại đầu dây nhảy, so với số đo lúc nghiệm thu. | H5: Thay SFP dự phòng đúng chuẩn (GPON/XGS-PON, class B+/C+). Nếu cổng PON hỏng: dời dây nhảy sang cổng PON trống của OLT, cấu hình lại profile và ghi lại PON mới. | I5: Thay SFP hoặc card PON (bảo hành/RMA). Cập nhật bảng đấu nối PON ↔ cổng vào ODF-96. | J5: Dự trữ ít nhất 2 SFP mỗi loại. Ghi Tx power chuẩn khi nghiệm thu, đặt ngưỡng cảnh báo DDM. | K5: P1 | L5: 15-30 phút
A6: P2 | B6: Dây nhảy PON: OLT → ODF-96 (cổng vào) | C6: Dây nhảy OLT → ODF-96 hoặc adapter cổng vào bị bẩn, gập, hỏng | D6: Cả 1 PON | E6: 31 / 42 / 56 | F6: Toàn bộ ONU của PON mất hoặc chập chờn; Tx power OLT bình thường nhưng công suất tại cổng vào ODF-96 thấp hoặc không có; thường xảy ra sau thao tác tại rack (rút nhầm, uốn gập). | G6: Đo OPM tại đầu dây nhảy phía ODF-96. Vệ sinh đầu SC/APC bằng bút vệ sinh, soi end-face bằng kính hiển vi. Kiểm tra bán kính uốn; dùng VFL xem rò sáng. | H6: Thay ngay dây nhảy SC/APC dự phòng (đầu xanh lá, không dùng UPC). Vệ sinh adapter. | I6: Thay adapter ODF-96 nếu hỏng; chỉnh lại đường đi dây, giữ bán kính uốn ≥ 30 mm; dán nhãn hai đầu. | J6: Nhãn hai đầu (PON-k ↔ A/B-số cổng), khay quản lý cáp, chỉ dùng APC với APC. | K6: P1 | L6: 10-20 phút
A7: P3 | B7: Splitter 1:4 tại phòng máy | C7: Splitter 1:4 hỏng hoặc suy hao tăng | D7: Cả 1 PON | E7: 31 / 42 / 56 | F7: Toàn bộ ONU của PON mất, hoặc Rx của mọi ONU thuộc PON giảm bất thường (hơn 3 dB so với chuẩn); OLT và dây nhảy bình thường. | G7: Đo công suất tại cổng vào splitter và từng cổng ra; chênh lệch kỳ vọng khoảng 7,3 dB. Có ánh sáng vào mà ra không có hoặc yếu bất thường thì nghi splitter. | H7: Thay splitter 1:4 dự phòng, cắm lại đúng 4 cổng ra theo bảng cổng. | I7: Thay hẳn, đo Rx một số ONU mẫu, cập nhật số seri và ngày thay. | J7: Dự trữ 1-2 splitter 1:4. Lưu số đo chuẩn (công suất vào/ra) lúc nghiệm thu. | K7: P1 | L7: 20-40 phút
A8: S4 | B8: Dây nhảy ODF-96 (cổng ra) → ODF-48 | C8: Dây nhảy hoặc adapter giữa ODF-96 và ODF-48 hỏng | D8: Một splitter 1:16 (một tầng) | E8: 8 / 14 / 15 | F8: Cả nhóm ONU thuộc cùng một splitter 1:16 (cùng tủ, cùng tầng) mất đồng loạt; các nhánh khác của PON vẫn bình thường. | G8: Tra mã splitter trong app/Excel để biết cổng ODF-96 và coupler ODF-48. Đo OPM hai đầu dây nhảy; vệ sinh và soi end-face. | H8: Thay dây nhảy dự phòng. Hoặc chuyển nhánh sang cổng ra thứ 4 (dự phòng) của cùng splitter 1:4 nếu PON còn cổng đó, để loại trừ cổng hỏng. | I8: Thay adapter/dây nhảy, cập nhật bảng dây nhảy. | J8: Nhãn hai đầu từng dây nhảy; không cắm rút các dây khác khi chưa cần. | K8: P2 | L8: 10-20 phút
A9: S5 | B9: Cáp trục: 1 sợi (coupler ODF-48 → đầu vào splitter tại tủ) | C9: Một sợi trục bị gãy, mối hàn hoặc pigtail hỏng | D9: Một splitter 1:16 (một tầng) | E9: 8 / 14 / 15 | F9: Cả nhóm ONU của một splitter 1:16 mất; các splitter khác trên cùng cáp trục vẫn bình thường (khác với đứt cả cáp). | G9: OTDR từ ODF-48 đo đúng sợi đó (dùng dây phóng đủ dài) để xác định khoảng cách. Dùng VFL tại tủ và đo OPM tại đầu vào splitter tủ. | H9: Chuyển sang sợi dự phòng trong dải 8FO của cùng tủ: đổi coupler ở ODF-48 và cổng vào splitter ở tủ; ghi lại số sợi mới. | I9: Hàn lại mối hàn hoặc thay pigtail; sửa xong có thể trả về sợi cũ. Cập nhật bảng sợi trục. | J9: Giữ sợi dự phòng không dùng; lưu OTDR chuẩn từng sợi lúc nghiệm thu. | K9: P2 | L9: 30-90 phút
A10: S9 | B10: Tủ: splitter 1:16 | C10: Splitter 1:16 hỏng, đầu vào bẩn hoặc cổng ra hỏng | D10: Một splitter 1:16 (một tầng) | E10: 8 / 14 / 15 | F10: ONU của một splitter mất toàn bộ (hoặc vài cổng cùng chết nếu hỏng một phần); Rx các ONU còn lại thấp bất thường. | G10: Đo OPM đầu vào splitter (kỳ vọng khoảng -5 đến -8 dBm theo tính toán) và từng cổng ra (chênh khoảng 13,8 dB). Vệ sinh adapter đầu vào. | H10: Thay bằng splitter dự phòng mang theo. Nếu chỉ một cổng ra hỏng: chuyển căn hộ đó sang cổng trống cùng splitter và ghi lại cổng mới. | I10: Thay splitter, ghi seri và ngày; đo lại Rx ONU mẫu. | J10: Đậy nắp bụi mọi cổng chưa dùng; tủ có khóa và niêm phong. | K10: P2 | L10: 20-45 phút
A11: C7 | B11: Cáp nhánh 8FO: tủ → tủ hub (hộp nối tại hub) | C11: Đứt cáp nhánh 8FO hoặc hỏng mối hàn tại hub | D11: Cả 1 tủ | E11: 14 / 40 / 48 | F11: Toàn bộ căn hộ của một tủ (14-48 hộ, 1-5 splitter) mất; các tủ khác cùng cáp trục bình thường; nhiều PON mất một phần. | G11: OTDR từ ODF-48 trên từng sợi của tủ đó để biết khoảng cách điểm đứt; mở hộp nối tại hub kiểm tra mối hàn. | H11: Không có đường dự phòng vật lý. Nếu hỏng mối hàn: hàn lại ngay. Nếu cự ly ngắn: kéo cáp tạm nối trực tiếp. | I11: Hàn nối hoặc thay đoạn cáp 8FO, đo OTDR nghiệm thu, cập nhật hồ sơ. | J11: Cáp đi trong ống/thang cáp, hộp nối có khóa; lưu OTDR chuẩn. | K11: P1 | L11: 1-3 giờ
A12: C8 | B12: Tủ phối quang (vật lý) | C12: Tủ bị phá hoại, vào nước hoặc cháy | D12: Cả 1 tủ | E12: 14 / 40 / 48 | F12: Mất toàn bộ căn hộ của tủ kèm dấu hiệu hư hại vật lý (cửa mở, nước, mùi cháy). | G12: Chụp ảnh hiện trường; kiểm tra từng splitter, adapter, pigtail; đo OPM trên cáp trục tại tủ. | H12: Dựng tạm bằng splitter mang theo, cắm lại các cáp 1FO theo bảng cổng (cáp 1FO đặt cố định nên chỉ cần cắm đúng cổng đã quy hoạch). | I12: Thay tủ/splitter, hàn lại pigtail, khóa và niêm phong, cập nhật seri. | J12: Khóa tủ, niêm phong, kiểm tra định kỳ; giữ kỹ thuật viên có bảng cổng bản in và bản điện tử. | K12: P1 | L12: 2-4 giờ
