Workbook

Sheet Tổng quan
A1: Mạng ring CSG Nhà Bè — tổng quan
A2: Dữ liệu từ file ghi tay (BBNT, ODF, MX, độ dài cáp, KML). Công thức sống; sửa Tham số để tính lại.
A4: Chỉ số | B4: Giá trị
A5: Số ring | B5: =COUNTA(Ring!A5:A12)
A6: Số CSG ring | B6: =SUM(Ring!C5:C12)
A7: Số trạm nhánh cụt (cấp 3) | B7: =COUNTIF(Nút!D5:D36,"nhánh cụt*")
A8: Số đoạn cáp (gồm nhánh cụt) | B8: =COUNTA('Đoạn & quỹ suy hao'!$A$5:$A$42)
A9: Tổng km tính (đoạn ring) | B9: =SUMIF('Đoạn & quỹ suy hao'!$E$5:$E$42,"ring",'Đoạn & quỹ suy hao'!$K$5:$K$42)
A10: Đoạn dài nhất (km) | B10: =MAX('Đoạn & quỹ suy hao'!$K$5:$K$42)
A11: Dư suy hao thấp nhất (dB) | B11: =MIN('Đoạn & quỹ suy hao'!$P$5:$P$42)
A12: Số đoạn Đạt | B12: =COUNTIF('Đoạn & quỹ suy hao'!$R$5:$R$42,"Đạt")
A13: Số đoạn Cảnh báo | B13: =COUNTIF('Đoạn & quỹ suy hao'!$R$5:$R$42,"Cảnh báo")
A14: Số đoạn chưa đo | B14: =COUNTIF('Đoạn & quỹ suy hao'!$R$5:$R$42,"Chưa đo")
A15: Số măng xông trong danh bạ | B15: =COUNTA('Măng xông'!A5:A49)
A16: Số cổng ODF CSG ghi hướng | B16: =COUNTIFS('ODF chi tiết'!D:D,"<>")-1
A17: Cặp core hàn (suy từ nhãn MX) | B17: =COUNTA('Phối core MX'!A5:A180)
A18: Măng xông đã có nhãn core | B18: =SUMPRODUCT(1/COUNTIF('Phối core MX'!A5:A180,'Phối core MX'!A5:A180))
A19: Mục cần xác nhận | B19: =COUNTA('Dữ liệu cần xác nhận'!A4:A23)
A20: Cách đọc: sheet "Ring" tóm tắt 8 ring; "Đoạn & quỹ suy hao" là bảng trung tâm; "Sự cố đứt cáp" liệt kê hệ quả đứt từng đoạn.
A21: Quy ước: bảo vệ trong phạm vi từng ring AGG–AGG; các ring được phép chung cáp; nguy cơ cần tránh là một CSG không còn link nào về AGG.
A22: Suy hao tính theo từng đoạn giữa hai trạm liền kề (SFP thu/phát mỗi trạm), ngưỡng 12,1 / 17 / 27 dB theo chiều dài; lệch hai core ≤ 2 dB.
A23: Chưa có: bảng hàn từng khay của măng xông (chỉ có danh bạ), số core cụ thể của đối tác, chỉ số mét hai đầu cáp. Đã đánh dấu để bổ sung.

Sheet Hồ sơ cáp
A1: Hồ sơ cáp: mã cáp, core đang chạy / hư / trống — dùng khi đo kiểm và xử lý sự cố
A2: Core đang chạy theo đường đi người dùng mô tả; "nhãn chưa gán" = sơ đồ MX gán nhóm/trạm nhưng chưa mô tả link; "trống" = chưa dùng, chưa nhãn, không hư. Mã cáp lấy từ sổ độ dài (ô trống = sổ chưa ghi, cần bổ sung).
A4: Mã nội bộ | B4: Mã cáp (sổ) | C4: FO | D4: Từ | E4: Đến | F4: Dài (m) | G4: cs đầu | H4: cs cuối | I4: Dòng sổ | J4: Core đang chạy (link) | K4: Core hư | L4: Core có nhãn, chưa gán | M4: Trạm ghi trong nhãn | N4: Core trống | O4: Hệ quả khi đứt cáp
A5: C01 | B5: ADSS 9/2009 | C5: 24 | D5: VNPT Long Thới (ODF-02 NBE12) | E5: MX nhập đài Long Thới–NVT | F5: 150 | I5: 31 | J5: 3-4 (R1-01); 1-2 (R2-01) | K5: — | L5: — | M5: — | N5: 5-24 | O5: các link R1-01, R2-01 mất một hướng, ring vẫn bảo vệ
A6: C02 | B6: SACOM 8/2014 | C6: 12 | D6: MX nhập đài Long Thới–NVT | E6: MX_NVT_01 | F6: 680 | H6: 2677 | I6: 53 | J6: 3-4 (R1-01); 1-2 (R2-01) | K6: — | L6: — | M6: — | N6: 5-12 | O6: các link R1-01, R2-01 mất một hướng, ring vẫn bảo vệ
A7: C03 | B7: FOCAL 9/2020 | C7: 12 | D7: MX_NVT_01 | E7: HNB054 | F7: 150 | G7: 1 | H7: 176 | I7: 56 | J7: 1-2 (R2-01); 3-4 (R2-02) | K7: — | L7: — | M7: — | N7: 5-12 | O7: MẤT KẾT NỐI: HNB054
A8: C04 | B8: FOCAL 9/2020 | C8: 12 | D8: MX_NVT_01 | E8: MX_NVT_02A | F8: 1060 | G8: 5 | I8: 54 | J8: 3-4 (R1-01); 1-2 (R2-02) | K8: — | L8: 7-12 | M8: HNB066: 9-10; HNB005: 11-12 | N8: 5-6 | O8: các link R1-01, R2-02 mất một hướng, ring vẫn bảo vệ
A9: C05 | B9: (chưa ghi mã cáp trong sổ) | C9: 12 | D9: MX_NVT_02A | E9: HNB006 | F9: 220 | I9: 57 | J9: 1-2 (R2-02); 3-4 (R2-03) | K9: — | L9: — | M9: — | N9: 5-12 | O9: MẤT KẾT NỐI: HNB006
A10: C06 | B10: (chưa ghi mã cáp trong sổ) | C10: 12 | D10: MX_NVT_02A | E10: MX_NVT_03A | F10: 845 | I10: 55 | J10: 3-4 (R1-01); 2,5 (R2-03) | K10: 1 | L10: — | M10: — | N10: 6-12 | O10: các link R1-01, R2-03 mất một hướng, ring vẫn bảo vệ
A11: C07 | B11: FOCAL 2020 | C11: 6 | D11: MX_NVT_03A | E11: HNB091 | F11: 545 | H11: 741 | I11: 58 | J11: 1-2 (R2-03) | K11: — | L11: — | M11: — | N11: 3-6 | O11: các link R2-03 mất một hướng, ring vẫn bảo vệ
A12: C08 | B12: FOCAL 2020 | C12: 6 | D12: HNB091 | E12: MX_NVT_03B | F12: 550 | G12: 4460 | I12: 59 | J12: 1-2 (R2-04) | K12: — | L12: — | M12: — | N12: 3-6 | O12: các link R2-04 mất một hướng, ring vẫn bảo vệ
A13: C09 | B13: (chưa ghi mã cáp trong sổ) | C13: 12 | D13: MX_NVT_03B | E13: MX_NVT_02B | F13: 770 | I13: 64 | J13: 3-4 (R1-04); 1-2 (R2-04) | K13: — | L13: — | M13: — | N13: 5-12 | O13: các link R1-04, R2-04 mất một hướng, ring vẫn bảo vệ
A14: C10 | B14: TPKL | C14: 12 | D14: MX_NVT_02B | E14: MX_LVL-05 | F14: 6250 | I14: 65 | J14: 3-4 (R1-04); 1-2 (R2-04) | K14: — | L14: 5-12 | M14: HNB066: 9-10; HNB005: 11-12 | N14: — | O14: các link R1-04, R2-04 mất một hướng, ring vẫn bảo vệ
A15: C11 | B15: TPKL Postef 11/2016 | C15: 24 | D15: MX_LVL-05 | E15: MX_NB-01 | F15: 3236 | I15: 32 | J15: 21-22 (R1-04); 19-20 (R2-04) | K15: — | L15: 1-18,23-24 | M15: HNB012: 1-2; HNB011: 3-4; HNB055: 5-6; LACG43: 7-8 | N15: — | O15: các link R1-04, R2-04 mất một hướng, ring vẫn bảo vệ
A16: C12 | B16: (chưa ghi mã cáp trong sổ) | C16: 12 | D16: MX_NB-01 | E16: MX_NB-02 | F16: 1040 | I16: 22 | J16: 3-4 (R1-04); 1-2 (R2-04) | K16: — | L16: 5-12 | M16: HNB086: 7-8; TTC: 9-10 | N16: — | O16: các link R1-04, R2-04 mất một hướng, ring vẫn bảo vệ
A17: C13 | B17: (chưa ghi mã cáp trong sổ) | C17: 12 | D17: MX_NB-02 | E17: MX_NB-03 | F17: 1408 | I17: 21 | J17: 3-4 (R1-04); 1-2 (R2-04) | K17: — | L17: — | M17: — | N17: 5-12 | O17: các link R1-04, R2-04 mất một hướng, ring vẫn bảo vệ
A18: C14 | B18: (chưa ghi mã cáp trong sổ) | C18: 12 | D18: MX_NB-03 | E18: MX_NB-04 | F18: 1092 | I18: 20 | J18: 3-4 (R1-04); 1-2 (R2-04) | K18: — | L18: — | M18: — | N18: 5-12 | O18: các link R1-04, R2-04 mất một hướng, ring vẫn bảo vệ
A19: C15 | B19: (chưa ghi mã cáp trong sổ) | C19: 12 | D19: MX_NB-04 | E19: MX thẳng HTP | F19: 777 | I19: 19 | J19: 3-4 (R1-04); 1-2 (R2-04) | K19: — | L19: — | M19: — | N19: 5-12 | O19: các link R1-04, R2-04 mất một hướng, ring vẫn bảo vệ
A20: C16 | B20: (chưa ghi mã cáp trong sổ) | C20: 12 | D20: MX thẳng HTP | E20: MX_HTP-03B | F20: 640 | I20: 18 | J20: 3-4 (R1-04); 1-2 (R2-04) | K20: — | L20: — | M20: — | N20: 5-12 | O20: các link R1-04, R2-04 mất một hướng, ring vẫn bảo vệ
A21: C17 | B21: POSTEF | C21: 24 | D21: MX_HTP-03B | E21: ODF-02 NBE22 | F21: 260 | G21: 1550 | H21: 1288 | I21: 17 | J21: 3-4 (R1-04); 1-2 (R2-04) | K21: — | L21: — | M21: — | N21: 5-24 | O21: các link R1-04, R2-04 mất một hướng, ring vẫn bảo vệ
A22: C18 | B22: FOCAL 2020 | C22: 6 | D22: MX_NVT_03A | E22: HNB059 | F22: 1933 | H22: 4415 | I22: 60 | J22: 1-2 (R1-01) | K22: — | L22: — | M22: — | N22: 3-6 | O22: các link R1-01 mất một hướng, ring vẫn bảo vệ
A23: C19 | B23: FOCAL 2020 | C23: 6 | D23: HNB059 | E23: HNB060 | F23: 3086 | G23: 279 | H23: 1 | I23: 61 | J23: 1-2 (R1-02) | K23: — | L23: — | M23: — | N23: 3-6 | O23: các link R1-02 mất một hướng, ring vẫn bảo vệ
A24: C20 | B24: FOCAL 2020 | C24: 6 | D24: HNB060 | E24: HNB048 | F24: 4405 | G24: 1 | H24: 5 | I24: 62 | J24: 1-2 (R1-03) | K24: — | L24: — | M24: — | N24: 3-6 | O24: các link R1-03 mất một hướng, ring vẫn bảo vệ
A25: C21 | B25: FOCAL 2020 | C25: 6 | D25: HNB048 | E25: MX_NVT_03B | F25: 1680 | G25: 2445 | I25: 63 | J25: 1-2 (R1-04) | K25: — | L25: — | M25: — | N25: 3-6 | O25: các link R1-04 mất một hướng, ring vẫn bảo vệ

Sheet Tra cứu cáp
A1: Tra cứu cáp khi có sự cố
A2: Chọn mã nội bộ ở ô vàng (C01…) hoặc xem bảng Hồ sơ cáp.
A4: Mã nội bộ | B4: C04
A6: Mã cáp (sổ) | B6: =INDEX('Hồ sơ cáp'!B$5:B$25,MATCH($B$4,'Hồ sơ cáp'!$A$5:$A$25,0))&""
A7: Số FO | B7: =INDEX('Hồ sơ cáp'!C$5:C$25,MATCH($B$4,'Hồ sơ cáp'!$A$5:$A$25,0))&""
A8: Từ | B8: =INDEX('Hồ sơ cáp'!D$5:D$25,MATCH($B$4,'Hồ sơ cáp'!$A$5:$A$25,0))&""
A9: Đến | B9: =INDEX('Hồ sơ cáp'!E$5:E$25,MATCH($B$4,'Hồ sơ cáp'!$A$5:$A$25,0))&""
A10: Dài (m) | B10: =INDEX('Hồ sơ cáp'!F$5:F$25,MATCH($B$4,'Hồ sơ cáp'!$A$5:$A$25,0))&""
A11: Chỉ số mét đầu | B11: =INDEX('Hồ sơ cáp'!G$5:G$25,MATCH($B$4,'Hồ sơ cáp'!$A$5:$A$25,0))&""
A12: Chỉ số mét cuối | B12: =INDEX('Hồ sơ cáp'!H$5:H$25,MATCH($B$4,'Hồ sơ cáp'!$A$5:$A$25,0))&""
A13: Dòng sổ cáp | B13: =INDEX('Hồ sơ cáp'!I$5:I$25,MATCH($B$4,'Hồ sơ cáp'!$A$5:$A$25,0))&""
A14: Core đang chạy (link) | B14: =INDEX('Hồ sơ cáp'!J$5:J$25,MATCH($B$4,'Hồ sơ cáp'!$A$5:$A$25,0))&""
A15: Core hư | B15: =INDEX('Hồ sơ cáp'!K$5:K$25,MATCH($B$4,'Hồ sơ cáp'!$A$5:$A$25,0))&""
A16: Core có nhãn, chưa gán | B16: =INDEX('Hồ sơ cáp'!L$5:L$25,MATCH($B$4,'Hồ sơ cáp'!$A$5:$A$25,0))&""
A17: Trạm ghi trong nhãn | B17: =INDEX('Hồ sơ cáp'!M$5:M$25,MATCH($B$4,'Hồ sơ cáp'!$A$5:$A$25,0))&""
A18: Core trống | B18: =INDEX('Hồ sơ cáp'!N$5:N$25,MATCH($B$4,'Hồ sơ cáp'!$A$5:$A$25,0))&""
A19: Hệ quả khi đứt cáp | B19: =INDEX('Hồ sơ cáp'!O$5:O$25,MATCH($B$4,'Hồ sơ cáp'!$A$5:$A$25,0))&""

Sheet Cân đối cáp
A1: Cân đối tải giữa các cáp và kiểm tra quy tắc cáp vào trạm
A2: Quy tắc: cáp vào trạm từ MX trục gần trạm (<300 m) chấp nhận nếu ≥12FO; cáp dùng chung nhiều link được phép nhưng cần cân đối. "Số link" = số link đang mô tả chạy trên cáp = số link mất cùng lúc khi đứt cáp.
A4: Mã | B4: Mã cáp (sổ) | C4: FO | D4: Dài (m) | E4: Loại | F4: Số link | G4: Ring | H4: Core dùng | I4: Tỷ lệ core dùng | J4: Kiểm tra quy tắc | K4: Hệ quả khi đứt
A5: C01 | B5: ADSS 9/2009 | C5: 24 | D5: 150 | E5: cáp trục | F5: 2 | G5: R1+R2 | H5: 4 | I5: =H5/C5 | J5: — | K5: các link R1-01, R2-01 mất một hướng, ring vẫn bảo vệ
A6: C02 | B6: SACOM 8/2014 | C6: 12 | D6: 680 | E6: cáp trục | F6: 2 | G6: R1+R2 | H6: 4 | I6: =H6/C6 | J6: — | K6: các link R1-01, R2-01 mất một hướng, ring vẫn bảo vệ
A7: C03 | B7: FOCAL 9/2020 | C7: 12 | D7: 150 | E7: cáp vào trạm | F7: 2 | G7: R2 | H7: 4 | I7: =H7/C7 | J7: đạt (<300 m, ≥12FO) | K7: MẤT KẾT NỐI: HNB054
A8: C04 | B8: FOCAL 9/2020 | C8: 12 | D8: 1060 | E8: cáp trục | F8: 2 | G8: R1+R2 | H8: 4 | I8: =H8/C8 | J8: — | K8: các link R1-01, R2-02 mất một hướng, ring vẫn bảo vệ
A9: C05 | B9: (chưa ghi mã cáp trong sổ) | C9: 12 | D9: 220 | E9: cáp vào trạm | F9: 2 | G9: R2 | H9: 4 | I9: =H9/C9 | J9: đạt (<300 m, ≥12FO) | K9: MẤT KẾT NỐI: HNB006
A10: C06 | B10: (chưa ghi mã cáp trong sổ) | C10: 12 | D10: 845 | E10: cáp trục | F10: 2 | G10: R1+R2 | H10: 4 | I10: =H10/C10 | J10: — | K10: các link R1-01, R2-03 mất một hướng, ring vẫn bảo vệ
A11: C09 | B11: (chưa ghi mã cáp trong sổ) | C11: 12 | D11: 770 | E11: cáp trục | F11: 2 | G11: R1+R2 | H11: 4 | I11: =H11/C11 | J11: — | K11: các link R1-04, R2-04 mất một hướng, ring vẫn bảo vệ
A12: C10 | B12: TPKL | C12: 12 | D12: 6250 | E12: cáp trục | F12: 2 | G12: R1+R2 | H12: 4 | I12: =H12/C12 | J12: — | K12: các link R1-04, R2-04 mất một hướng, ring vẫn bảo vệ
A13: C11 | B13: TPKL Postef 11/2016 | C13: 24 | D13: 3236 | E13: cáp trục | F13: 2 | G13: R1+R2 | H13: 4 | I13: =H13/C13 | J13: — | K13: các link R1-04, R2-04 mất một hướng, ring vẫn bảo vệ
A14: C12 | B14: (chưa ghi mã cáp trong sổ) | C14: 12 | D14: 1040 | E14: cáp trục | F14: 2 | G14: R1+R2 | H14: 4 | I14: =H14/C14 | J14: — | K14: các link R1-04, R2-04 mất một hướng, ring vẫn bảo vệ
A15: C13 | B15: (chưa ghi mã cáp trong sổ) | C15: 12 | D15: 1408 | E15: cáp trục | F15: 2 | G15: R1+R2 | H15: 4 | I15: =H15/C15 | J15: — | K15: các link R1-04, R2-04 mất một hướng, ring vẫn bảo vệ
A16: C14 | B16: (chưa ghi mã cáp trong sổ) | C16: 12 | D16: 1092 | E16: cáp trục | F16: 2 | G16: R1+R2 | H16: 4 | I16: =H16/C16 | J16: — | K16: các link R1-04, R2-04 mất một hướng, ring vẫn bảo vệ
... A25: C21 | B25: FOCAL 2020 | C25: 6 | D25: 1680 | E25: cáp riêng tới trạm (>=300 m) | F25: 1 | G25: R1 | H25: 2 | I25: =H25/C25 | J25: — | K25: các link R1-04 mất một hướng, ring vẫn bảo vệ

Sheet Đường đi link
A1: Đường đi từng link ring qua ODF – cáp – măng xông (SFP 1310 nm, 2 core/link)
A2: Mô tả do người dùng cung cấp; độ dài cáp từ sổ độ dài; đối chiếu nhãn với sơ đồ MX. Link chưa hoàn chỉnh ghi rõ.
A4: Link | B4: Từ | C4: Đến | D4: Tổng cáp (m) | E4: OTDR tham chiếu (m) | F4: Lệch (m) | G4: Lệch % | H4: Kết luận | I4: Ghi chú
A5: R1-01 | B5: NBE12 | C5: HNB059 | D5: =SUMIFS($G$17:$G$2000,$A$17:$A$2000,A5,$C$17:$C$2000,"cáp") | E5: 4672 | F5: =D5-E5 | G5: =F5/E5 | H5: =IF(ABS(G5)<=0.02,"Khớp (≤2%)","Lệch >2%: kiểm tra") | I5: OTDR tham chiếu: ODF AGG ghi 4672 m
A6: R1-02 | B6: HNB059 | C6: HNB060 | D6: =SUMIFS($G$17:$G$2000,$A$17:$A$2000,A6,$C$17:$C$2000,"cáp") | E6: 3082 | F6: =D6-E6 | G6: =F6/E6 | H6: =IF(ABS(G6)<=0.02,"Khớp (≤2%)","Lệch >2%: kiểm tra") | I6: OTDR tham chiếu: BBNT (số thống nhất)
A7: R1-03 | B7: HNB060 | C7: HNB048 | D7: =SUMIFS($G$17:$G$2000,$A$17:$A$2000,A7,$C$17:$C$2000,"cáp") | E7: 4410 | F7: =D7-E7 | G7: =F7/E7 | H7: =IF(ABS(G7)<=0.02,"Khớp (≤2%)","Lệch >2%: kiểm tra") | I7: OTDR tham chiếu: BBNT (số thống nhất)
A8: R1-04 | B8: HNB048 | C8: NBE22 | D8: =SUMIFS($G$17:$G$2000,$A$17:$A$2000,A8,$C$17:$C$2000,"cáp") | E8: 17153 | F8: =D8-E8 | G8: =F8/E8 | H8: =IF(ABS(G8)<=0.02,"Khớp (≤2%)","Lệch >2%: kiểm tra") | I8: OTDR tham chiếu: ODF AGG ghi 17153 m
A9: R2-01 | B9: NBE12 | C9: HNB054 | D9: =SUMIFS($G$17:$G$2000,$A$17:$A$2000,A9,$C$17:$C$2000,"cáp") | E9: 982 | F9: =D9-E9 | G9: =F9/E9 | H9: =IF(ABS(G9)<=0.02,"Khớp (≤2%)","Lệch >2%: kiểm tra") | I9: OTDR tham chiếu: ODF AGG ghi 982/988 m
A10: R2-02 | B10: HNB054 | C10: HNB006 | D10: =SUMIFS($G$17:$G$2000,$A$17:$A$2000,A10,$C$17:$C$2000,"cáp") | E10: 1433 | F10: =D10-E10 | G10: =F10/E10 | H10: =IF(ABS(G10)<=0.02,"Khớp (≤2%)","Lệch >2%: kiểm tra") | I10: OTDR tham chiếu: BBNT (số thống nhất)
A11: R2-03 | B11: HNB006 | C11: HNB091 | D11: =SUMIFS($G$17:$G$2000,$A$17:$A$2000,A11,$C$17:$C$2000,"cáp") | E11: 1607 | F11: =D11-E11 | G11: =F11/E11 | H11: =IF(ABS(G11)<=0.02,"Khớp (≤2%)","Lệch >2%: kiểm tra") | I11: OTDR tham chiếu: BBNT (số thống nhất)
A12: R2-04 | B12: HNB091 | C12: NBE22 | D12: =SUMIFS($G$17:$G$2000,$A$17:$A$2000,A12,$C$17:$C$2000,"cáp") | E12: 16028 | F12: =D12-E12 | G12: =F12/E12 | H12: =IF(ABS(G12)<=0.02,"Khớp (≤2%)","Lệch >2%: kiểm tra") | I12: OTDR tham chiếu: ODF AGG ghi 16028 m
A15: Chi tiết từng bước
A16: Link | B16: Bước | C16: Loại | D16: Vị trí / cáp | E16: Từ → Đến | F16: Core | G16: Dài (m) | H16: Cộng dồn (m) | I16: Đối chiếu sơ đồ MX | J16: Ghi chú
A17: R1-01 | B17: 1 | C17: ODF | D17: NBE12: ODF-02 24FO hướng NVT | F17: 3+4 | J17: ODF AGG ghi cổng 3-4: HNB059 ring 1
A18: R1-01 | B18: 2 | C18: cáp | D18: ADSS 9/2009 | E18: VNPT Long Thới (ODF-02 NBE12) → MX nhập đài Long Thới–NVT | F18: 3+4 | G18: 150 | H18: =SUM(G17:G18) | J18: Sổ độ dài cáp (Tổng Hợp): 150 m
A19: R1-01 | B19: 3 | C19: măng xông | D19: MX nhập đài Long Thới–NVT | F19: 3+4 ↔ 3+4 | I19: chưa có sơ đồ — không xác định cáp trong sơ đồ MX
A20: R1-01 | B20: 4 | C20: cáp | D20: SACOM 8/2014 | E20: MX nhập đài Long Thới–NVT → MX_NVT_01 | F20: 3+4 | G20: 680 | H20: =SUM(G17:G20) | J20: Sổ độ dài cáp (Tổng Hợp): 680 m
A21: R1-01 | B21: 5 | C21: măng xông | D21: MX_NVT_01 | F21: 3+4 ↔ 3+4 | I21: chưa có nhãn — sơ đồ MX chưa ghi nhãn cho các core này | J21: đi thẳng trục, không rẽ vào HNB054
A22: R1-01 | B22: 6 | C22: cáp | D22: FOCAL 9/2020 trục (gồm 175 m ngầm) | E22: MX_NVT_01 → MX_NVT_02A | F22: 3+4 | G22: 1060 | H22: =SUM(G17:G22) | J22: Sổ độ dài cáp (Tổng Hợp): 1060 m
A23: R1-01 | B23: 7 | C23: măng xông | D23: MX_NVT_02A | F23: 3+4 ↔ 3+4 | I23: khớp sơ đồ — nhãn B | J23: nhãn B (sơ đồ) đi thẳng về NVT_03A
A24: R1-01 | B24: 8 | C24: cáp | D24: 12FO NVT_02A → NVT_03A | E24: MX_NVT_02A → MX_NVT_03A | F24: 3+4 | G24: 845 | H24: =SUM(G17:G24) | J24: Sổ độ dài cáp (Tổng Hợp): 845 m
A25: R1-01 | B25: 9 | C25: măng xông | D25: MX_NVT_03A | F25: 3+4 ↔ 1+2 | I25: chưa có sơ đồ — không xác định cáp trong sơ đồ MX | J25: rẽ vào 6FO đi HNB059 (quy ước 6FO riêng dùng 1,2)
A26: R1-01 | B26: 10 | C26: cáp | D26: FOCAL 2020 vào HNB059 (6FO) | E26: MX_NVT_03A → HNB059 | F26: 1+2 | G26: 1933 | H26: =SUM(G17:G26) | J26: Sổ độ dài cáp (Tổng Hợp): 1933 m
A27: R1-01 | B27: 11 | C27: ODF | D27: HNB059: ODF-HNB059 (hướng NBE12) | F27: 1+2
A28: R1-02 | B28: 1 | C28: ODF | D28: HNB059: ODF-HNB059 (hướng HNB060) | F28: 1+2
A29: R1-02 | B29: 2 | C29: cáp | D29: FOCAL 2020 HNB059 → HNB060 (6FO) | E29: HNB059 → HNB060 | F29: 1+2 | G29: 3086 | H29: =SUM(G28:G29) | J29: Sổ độ dài cáp (Tổng Hợp): 3086 m
A30: R1-02 | B30: 3 | C30: ODF | D30: HNB060: ODF-HNB060 (hướng HNB059) | F30: 1+2
A31: R1-03 | B31: 1 | C31: ODF | D31: HNB060: ODF-HNB060 (hướng HNB048) | F31: 1+2
A32: R1-03 | B32: 2 | C32: cáp | D32: FOCAL 2020 HNB060 → HNB048 (6FO) | E32: HNB060 → HNB048 | F32: 1+2 | G32: 4405 | H32: =SUM(G31:G32) | J32: Sổ độ dài cáp (Tổng Hợp): 4405 m
A33: R1-03 | B33: 3 | C33: ODF | D33: HNB048: ODF-HNB048 (hướng HNB060) | F33: 1+2
A34: R1-04 | B34: 1 | C34: ODF | D34: HNB048: ODF-HNB048 (hướng ra NBE22) | F34: 1+2
A35: R1-04 | B35: 2 | C35: cáp | D35: FOCAL 2020 HNB048 → MX_NVT_03B (6FO) | E35: HNB048 → MX_NVT_03B | F35: 1+2 | G35: 1680 | H35: =SUM(G34:G35) | J35: Sổ độ dài cáp (Tổng Hợp): 1680 m
A36: R1-04 | B36: 3 | C36: măng xông | D36: MX_NVT_03B | F36: 1+2 ↔ 3+4 | I36: chưa có sơ đồ — không xác định cáp trong sơ đồ MX | J36: 6FO 1,2 hàn vào trục 12FO core 3,4 (đoạn dùng chung)
A37: R1-04 | B37: 4 | C37: cáp | D37: 12FO NVT_03B → NVT_02B | E37: MX_NVT_03B → MX_NVT_02B | F37: 3+4 | G37: 770 | H37: =SUM(G34:G37) | J37: Sổ độ dài cáp (Tổng Hợp): 770 m
A38: R1-04 | B38: 5 | C38: măng xông | D38: MX_NVT_02B | F38: 3+4 ↔ 3+4 | I38: khớp sơ đồ — nhãn B | J38: nhãn B (sơ đồ)
A39: R1-04 | B39: 6 | C39: cáp | D39: TPKL 12FO trục NVT_02B → LVL-05 (qua MX thẳng nối dài) | E39: MX_NVT_02B → MX_LVL-05 | F39: 3+4 | G39: 6250 | H39: =SUM(G34:G39) | J39: Sổ độ dài cáp (Tổng Hợp): 6250 m (ghi chú sổ: 7020 = 785+1745+3715+770)
A40: R1-04 | B40: 7 | C40: măng xông | D40: MX_LVL-05 | F40: 3+4 ↔ 21+22 | I40: khớp sơ đồ — nhãn D | J40: nhãn D, trạm HNB048 (sơ đồ)
A41: R1-04 | B41: 8 | C41: cáp | D41: TPKL POSTEF 11/2016 | E41: MX_LVL-05 → MX_NB-01 | F41: 21+22 | G41: 3236 | H41: =SUM(G34:G41) | J41: Sổ độ dài cáp (Tổng Hợp): 3236 m
A42: R1-04 | B42: 9 | C42: măng xông | D42: MX_NB-01 | F42: 21+22 ↔ 3+4 | I42: khớp sơ đồ — nhãn B
A43: R1-04 | B43: 10 | C43: cáp | D43: 12FO NB-01 → NB-02 | E43: MX_NB-01 → MX_NB-02 | F43: 3+4 | G43: 1040 | H43: =SUM(G34:G43) | J43: Sổ độ dài cáp (Tổng Hợp): 1040 m (NB Phạm Thị Kỳ → nhập đài Long Thới-NB)
...

Sheet Phối core từ đường đi
A1: Bảng phối core dựng lại từ đường đi người dùng mô tả
A2: Mỗi dòng = một core hàn tại một măng xông, theo từng link. Cột đối chiếu so với nhãn trong sơ đồ MX gốc (nếu có). Hoàn thiện dần khi có thêm đường đi.
A4: Măng xông | B4: Link | C4: Cáp A | D4: Core A | E4: ↔ | F4: Cáp B | G4: Core B | H4: Đối chiếu sơ đồ MX | I4: Ghi chú
A5: MX nhập đài Long Thới–NVT | B5: R1-01 | C5: C01 ADSS 9/2009 24FO | D5: 3 | E5: ↔ | F5: C02 SACOM 8/2014 12FO | G5: 3 | H5: chưa có sơ đồ
A6: MX nhập đài Long Thới–NVT | B6: R1-01 | C6: C01 ADSS 9/2009 24FO | D6: 4 | E6: ↔ | F6: C02 SACOM 8/2014 12FO | G6: 4 | H6: chưa có sơ đồ
A7: MX_NVT_01 | B7: R1-01 | C7: C02 SACOM 8/2014 12FO | D7: 3 | E7: ↔ | F7: C04 FOCAL 9/2020 trục (gồm 175 m ngầm) 12FO | G7: 3 | H7: chưa có nhãn | I7: đi thẳng trục, không rẽ vào HNB054
A8: MX_NVT_01 | B8: R1-01 | C8: C02 SACOM 8/2014 12FO | D8: 4 | E8: ↔ | F8: C04 FOCAL 9/2020 trục (gồm 175 m ngầm) 12FO | G8: 4 | H8: chưa có nhãn | I8: đi thẳng trục, không rẽ vào HNB054
A9: MX_NVT_02A | B9: R1-01 | C9: C04 FOCAL 9/2020 trục (gồm 175 m ngầm) 12FO | D9: 3 | E9: ↔ | F9: C06 12FO NVT_02A → NVT_03A 12FO | G9: 3 | H9: khớp sơ đồ | I9: nhãn B (sơ đồ) đi thẳng về NVT_03A
A10: MX_NVT_02A | B10: R1-01 | C10: C04 FOCAL 9/2020 trục (gồm 175 m ngầm) 12FO | D10: 4 | E10: ↔ | F10: C06 12FO NVT_02A → NVT_03A 12FO | G10: 4 | H10: khớp sơ đồ | I10: nhãn B (sơ đồ) đi thẳng về NVT_03A
A11: MX_NVT_03A | B11: R1-01 | C11: C06 12FO NVT_02A → NVT_03A 12FO | D11: 3 | E11: ↔ | F11: C18 FOCAL 2020 vào HNB059 (6FO) 6FO | G11: 1 | H11: chưa có sơ đồ | I11: rẽ vào 6FO đi HNB059 (quy ước 6FO riêng dùng 1,2)
A12: MX_NVT_03A | B12: R1-01 | C12: C06 12FO NVT_02A → NVT_03A 12FO | D12: 4 | E12: ↔ | F12: C18 FOCAL 2020 vào HNB059 (6FO) 6FO | G12: 2 | H12: chưa có sơ đồ | I12: rẽ vào 6FO đi HNB059 (quy ước 6FO riêng dùng 1,2)
A13: MX_NVT_03B | B13: R1-04 | C13: C21 FOCAL 2020 HNB048 → MX_NVT_03B (6FO) 6FO | D13: 1 | E13: ↔ | F13: C09 12FO NVT_03B → NVT_02B 12FO | G13: 3 | H13: chưa có sơ đồ | I13: 6FO 1,2 hàn vào trục 12FO core 3,4 (đoạn dùng chung)
A14: MX_NVT_03B | B14: R1-04 | C14: C21 FOCAL 2020 HNB048 → MX_NVT_03B (6FO) 6FO | D14: 2 | E14: ↔ | F14: C09 12FO NVT_03B → NVT_02B 12FO | G14: 4 | H14: chưa có sơ đồ | I14: 6FO 1,2 hàn vào trục 12FO core 3,4 (đoạn dùng chung)
A15: MX_NVT_02B | B15: R1-04 | C15: C09 12FO NVT_03B → NVT_02B 12FO | D15: 3 | E15: ↔ | F15: C10 TPKL 12FO trục NVT_02B → LVL-05 (qua MX thẳng nối dài) 12FO | G15: 3 | H15: khớp sơ đồ | I15: nhãn B (sơ đồ)
A16: MX_NVT_02B | B16: R1-04 | C16: C09 12FO NVT_03B → NVT_02B 12FO | D16: 4 | E16: ↔ | F16: C10 TPKL 12FO trục NVT_02B → LVL-05 (qua MX thẳng nối dài) 12FO | G16: 4 | H16: khớp sơ đồ | I16: nhãn B (sơ đồ)
A17: MX_LVL-05 | B17: R1-04 | C17: C10 TPKL 12FO trục NVT_02B → LVL-05 (qua MX thẳng nối dài) 12FO | D17: 3 | E17: ↔ | F17: C11 TPKL POSTEF 11/2016 24FO | G17: 21 | H17: khớp sơ đồ | I17: nhãn D, trạm HNB048 (sơ đồ)
A18: MX_LVL-05 | B18: R1-04 | C18: C10 TPKL 12FO trục NVT_02B → LVL-05 (qua MX thẳng nối dài) 12FO | D18: 4 | E18: ↔ | F18: C11 TPKL POSTEF 11/2016 24FO | G18: 22 | H18: khớp sơ đồ | I18: nhãn D, trạm HNB048 (sơ đồ)
A19: MX_NB-01 | B19: R1-04 | C19: C11 TPKL POSTEF 11/2016 24FO | D19: 21 | E19: ↔ | F19: C12 12FO NB-01 → NB-02 12FO | G19: 3 | H19: khớp sơ đồ
A20: MX_NB-01 | B20: R1-04 | C20: C11 TPKL POSTEF 11/2016 24FO | D20: 22 | E20: ↔ | F20: C12 12FO NB-01 → NB-02 12FO | G20: 4 | H20: khớp sơ đồ
A21: MX_NB-02 | B21: R1-04 | C21: C12 12FO NB-01 → NB-02 12FO | D21: 3 | E21: ↔ | F21: C13 12FO NB-02 → NB-03 12FO | G21: 3 | H21: chưa có sơ đồ
A22: MX_NB-02 | B22: R1-04 | C22: C12 12FO NB-01 → NB-02 12FO | D22: 4 | E22: ↔ | F22: C13 12FO NB-02 → NB-03 12FO | G22: 4 | H22: chưa có sơ đồ
A23: MX_NB-03 | B23: R1-04 | C23: C13 12FO NB-02 → NB-03 12FO | D23: 3 | E23: ↔ | F23: C14 12FO NB-03 → NB-04 12FO | G23: 3 | H23: chưa có sơ đồ
A24: MX_NB-03 | B24: R1-04 | C24: C13 12FO NB-02 → NB-03 12FO | D24: 4 | E24: ↔ | F24: C14 12FO NB-03 → NB-04 12FO | G24: 4 | H24: chưa có sơ đồ
A25: MX_NB-04 | B25: R1-04 | C25: C14 12FO NB-03 → NB-04 12FO | D25: 3 | E25: ↔ | F25: C15 12FO NB-04 → MX thẳng HTP 12FO | G25: 3 | H25: chưa có sơ đồ
A26: MX_NB-04 | B26: R1-04 | C26: C14 12FO NB-03 → NB-04 12FO | D26: 4 | E26: ↔ | F26: C15 12FO NB-04 → MX thẳng HTP 12FO | G26: 4 | H26: chưa có sơ đồ
A27: MX thẳng HTP | B27: R1-04 | C27: C15 12FO NB-04 → MX thẳng HTP 12FO | D27: 3 | E27: ↔ | F27: C16 12FO MX thẳng HTP → HTP-03B 12FO | G27: 3 | H27: chưa có sơ đồ | I27: MX thẳng nối dài
A28: MX thẳng HTP | B28: R1-04 | C28: C15 12FO NB-04 → MX thẳng HTP 12FO | D28: 4 | E28: ↔ | F28: C16 12FO MX thẳng HTP → HTP-03B 12FO | G28: 4 | H28: chưa có sơ đồ | I28: MX thẳng nối dài
A29: MX_HTP-03B | B29: R1-04 | C29: C16 12FO MX thẳng HTP → HTP-03B 12FO | D29: 3 | E29: ↔ | F29: C17 POSTEF 24FO nhập đài (cs 1550→1288) 24FO | G29: 3 | H29: chưa có sơ đồ
A30: MX_HTP-03B | B30: R1-04 | C30: C16 12FO MX thẳng HTP → HTP-03B 12FO | D30: 4 | E30: ↔ | F30: C17 POSTEF 24FO nhập đài (cs 1550→1288) 24FO | G30: 4 | H30: chưa có sơ đồ
A31: MX nhập đài Long Thới–NVT | B31: R2-01 | C31: C01 ADSS 9/2009 24FO | D31: 1 | E31: ↔ | F31: C02 SACOM 8/2014 12FO | G31: 1 | H31: chưa có sơ đồ | I31: MX thẳng, chưa có sơ đồ nhãn
A32: MX nhập đài Long Thới–NVT | B32: R2-01 | C32: C01 ADSS 9/2009 24FO | D32: 2 | E32: ↔ | F32: C02 SACOM 8/2014 12FO | G32: 2 | H32: chưa có sơ đồ | I32: MX thẳng, chưa có sơ đồ nhãn
A33: MX_NVT_01 | B33: R2-01 | C33: C02 SACOM 8/2014 12FO | D33: 1 | E33: ↔ | F33: C03 FOCAL 9/2020 (vào HNB054) 12FO | G33: 1 | H33: chưa có nhãn
A34: MX_NVT_01 | B34: R2-01 | C34: C02 SACOM 8/2014 12FO | D34: 2 | E34: ↔ | F34: C03 FOCAL 9/2020 (vào HNB054) 12FO | G34: 2 | H34: chưa có nhãn
A35: MX_NVT_01 | B35: R2-02 | C35: C03 FOCAL 9/2020 (vào HNB054) 12FO | D35: 3 | E35: ↔ | F35: C04 FOCAL 9/2020 trục (gồm 175 m ngầm) 12FO | G35: 1 | H35: chưa có nhãn
A36: MX_NVT_01 | B36: R2-02 | C36: C03 FOCAL 9/2020 (vào HNB054) 12FO | D36: 4 | E36: ↔ | F36: C04 FOCAL 9/2020 trục (gồm 175 m ngầm) 12FO | G36: 2 | H36: chưa có nhãn
A37: MX_NVT_02A | B37: R2-02 | C37: C04 FOCAL 9/2020 trục (gồm 175 m ngầm) 12FO | D37: 1 | E37: ↔ | F37: C05 12FO vào HNB006 12FO | G37: 1 | H37: khớp sơ đồ | I37: hàn 1,2 vào 1,2 đi vào HNB006
A38: MX_NVT_02A | B38: R2-02 | C38: C04 FOCAL 9/2020 trục (gồm 175 m ngầm) 12FO | D38: 2 | E38: ↔ | F38: C05 12FO vào HNB006 12FO | G38: 2 | H38: khớp sơ đồ | I38: hàn 1,2 vào 1,2 đi vào HNB006
A39: MX_NVT_02A | B39: R2-03 | C39: C05 12FO vào HNB006 12FO | D39: 3 | E39: ↔ | F39: C06 12FO NVT_02A → NVT_03A 12FO | G39: 5 | H39: khớp sơ đồ (thay core hư) | I39: thiết kế ban đầu 3↔1, 4↔2; core 1 hư nên 3 phối với 5 (phát sinh thực tế)
A40: MX_NVT_02A | B40: R2-03 | C40: C05 12FO vào HNB006 12FO | D40: 4 | E40: ↔ | F40: C06 12FO NVT_02A → NVT_03A 12FO | G40: 2 | H40: khớp sơ đồ (thay core hư) | I40: thiết kế ban đầu 3↔1, 4↔2; core 1 hư nên 3 phối với 5 (phát sinh thực tế)
A41: MX_NVT_03A | B41: R2-03 | C41: C06 12FO NVT_02A → NVT_03A 12FO | D41: 5 | E41: ↔ | F41: C07 FOCAL 2020 vào HNB091 (6FO #1) 6FO | G41: 1 | H41: chưa có sơ đồ | I41: hàn 5,2 vào 1,2 sợi 6FO vào HNB091
...

Sheet Quỹ core
A1: Quỹ core từng cáp — loại trừ dần
A2: Core đã dùng cho link (theo đường đi mô tả) hoặc hư thì không còn là ứng viên; "có nhãn, chưa gán link" = sơ đồ MX gán nhóm nhưng đường đi chưa mô tả. Trống/chưa rõ = còn quỹ.
A4: Mã cáp | B4: Cáp | C4: Tuyến | D4: Số FO | E4: Dùng | F4: Hư | G4: Có nhãn chưa gán | H4: Trống/chưa rõ | I4: Cặp trống tối đa
A5: C01 | B5: ADSS 9/2009 | C5: VNPT Long Thới (ODF-02 NBE12) → MX nhập đài Long Thới–NVT | D5: 24 | E5: =COUNTIFS($A$29:$A$2000,A5,$E$29:$E$2000,"dùng*") | F5: =COUNTIFS($A$29:$A$2000,A5,$E$29:$E$2000,"HƯ") | G5: =COUNTIFS($A$29:$A$2000,A5,$E$29:$E$2000,"có nhãn*") | H5: =D5-E5-F5-G5 | I5: =INT(H5/2)
A6: C02 | B6: SACOM 8/2014 | C6: MX nhập đài Long Thới–NVT → MX_NVT_01 | D6: 12 | E6: =COUNTIFS($A$29:$A$2000,A6,$E$29:$E$2000,"dùng*") | F6: =COUNTIFS($A$29:$A$2000,A6,$E$29:$E$2000,"HƯ") | G6: =COUNTIFS($A$29:$A$2000,A6,$E$29:$E$2000,"có nhãn*") | H6: =D6-E6-F6-G6 | I6: =INT(H6/2)
A7: C03 | B7: FOCAL 9/2020 (vào HNB054) | C7: MX_NVT_01 → HNB054 | D7: 12 | E7: =COUNTIFS($A$29:$A$2000,A7,$E$29:$E$2000,"dùng*") | F7: =COUNTIFS($A$29:$A$2000,A7,$E$29:$E$2000,"HƯ") | G7: =COUNTIFS($A$29:$A$2000,A7,$E$29:$E$2000,"có nhãn*") | H7: =D7-E7-F7-G7 | I7: =INT(H7/2)
A8: C04 | B8: FOCAL 9/2020 trục (gồm 175 m ngầm) | C8: MX_NVT_01 → MX_NVT_02A | D8: 12 | E8: =COUNTIFS($A$29:$A$2000,A8,$E$29:$E$2000,"dùng*") | F8: =COUNTIFS($A$29:$A$2000,A8,$E$29:$E$2000,"HƯ") | G8: =COUNTIFS($A$29:$A$2000,A8,$E$29:$E$2000,"có nhãn*") | H8: =D8-E8-F8-G8 | I8: =INT(H8/2)
A9: C05 | B9: 12FO vào HNB006 | C9: MX_NVT_02A → HNB006 | D9: 12 | E9: =COUNTIFS($A$29:$A$2000,A9,$E$29:$E$2000,"dùng*") | F9: =COUNTIFS($A$29:$A$2000,A9,$E$29:$E$2000,"HƯ") | G9: =COUNTIFS($A$29:$A$2000,A9,$E$29:$E$2000,"có nhãn*") | H9: =D9-E9-F9-G9 | I9: =INT(H9/2)
A10: C06 | B10: 12FO NVT_02A → NVT_03A | C10: MX_NVT_02A → MX_NVT_03A | D10: 12 | E10: =COUNTIFS($A$29:$A$2000,A10,$E$29:$E$2000,"dùng*") | F10: =COUNTIFS($A$29:$A$2000,A10,$E$29:$E$2000,"HƯ") | G10: =COUNTIFS($A$29:$A$2000,A10,$E$29:$E$2000,"có nhãn*") | H10: =D10-E10-F10-G10 | I10: =INT(H10/2)
A11: C07 | B11: FOCAL 2020 vào HNB091 (6FO #1) | C11: MX_NVT_03A → HNB091 | D11: 6 | E11: =COUNTIFS($A$29:$A$2000,A11,$E$29:$E$2000,"dùng*") | F11: =COUNTIFS($A$29:$A$2000,A11,$E$29:$E$2000,"HƯ") | G11: =COUNTIFS($A$29:$A$2000,A11,$E$29:$E$2000,"có nhãn*") | H11: =D11-E11-F11-G11 | I11: =INT(H11/2)
A12: C08 | B12: FOCAL 2020 ra HNB091 (6FO #2) | C12: HNB091 → MX_NVT_03B | D12: 6 | E12: =COUNTIFS($A$29:$A$2000,A12,$E$29:$E$2000,"dùng*") | F12: =COUNTIFS($A$29:$A$2000,A12,$E$29:$E$2000,"HƯ") | G12: =COUNTIFS($A$29:$A$2000,A12,$E$29:$E$2000,"có nhãn*") | H12: =D12-E12-F12-G12 | I12: =INT(H12/2)
A13: C09 | B13: 12FO NVT_03B → NVT_02B | C13: MX_NVT_03B → MX_NVT_02B | D13: 12 | E13: =COUNTIFS($A$29:$A$2000,A13,$E$29:$E$2000,"dùng*") | F13: =COUNTIFS($A$29:$A$2000,A13,$E$29:$E$2000,"HƯ") | G13: =COUNTIFS($A$29:$A$2000,A13,$E$29:$E$2000,"có nhãn*") | H13: =D13-E13-F13-G13 | I13: =INT(H13/2)
A14: C10 | B14: TPKL 12FO trục NVT_02B → LVL-05 (qua MX thẳng nối dài) | C14: MX_NVT_02B → MX_LVL-05 | D14: 12 | E14: =COUNTIFS($A$29:$A$2000,A14,$E$29:$E$2000,"dùng*") | F14: =COUNTIFS($A$29:$A$2000,A14,$E$29:$E$2000,"HƯ") | G14: =COUNTIFS($A$29:$A$2000,A14,$E$29:$E$2000,"có nhãn*") | H14: =D14-E14-F14-G14 | I14: =INT(H14/2)
A15: C11 | B15: TPKL POSTEF 11/2016 | C15: MX_LVL-05 → MX_NB-01 | D15: 24 | E15: =COUNTIFS($A$29:$A$2000,A15,$E$29:$E$2000,"dùng*") | F15: =COUNTIFS($A$29:$A$2000,A15,$E$29:$E$2000,"HƯ") | G15: =COUNTIFS($A$29:$A$2000,A15,$E$29:$E$2000,"có nhãn*") | H15: =D15-E15-F15-G15 | I15: =INT(H15/2)
A16: C12 | B16: 12FO NB-01 → NB-02 | C16: MX_NB-01 → MX_NB-02 | D16: 12 | E16: =COUNTIFS($A$29:$A$2000,A16,$E$29:$E$2000,"dùng*") | F16: =COUNTIFS($A$29:$A$2000,A16,$E$29:$E$2000,"HƯ") | G16: =COUNTIFS($A$29:$A$2000,A16,$E$29:$E$2000,"có nhãn*") | H16: =D16-E16-F16-G16 | I16: =INT(H16/2)
... A25: C21 | B25: FOCAL 2020 HNB048 → MX_NVT_03B (6FO) | C25: HNB048 → MX_NVT_03B | D25: 6 | E25: =COUNTIFS($A$29:$A$2000,A25,$E$29:$E$2000,"dùng*") | F25: =COUNTIFS($A$29:$A$2000,A25,$E$29:$E$2000,"HƯ") | G25: =COUNTIFS($A$29:$A$2000,A25,$E$29:$E$2000,"có nhãn*") | H25: =D25-E25-F25-G25 | I25: =INT(H25/2)
A27: Chi tiết từng core
A28: Mã cáp | B28: Cáp | C28: Core | D28: Màu sợi | E28: Trạng thái | F28: Nhãn trong sơ đồ MX | G28: Trạm (sơ đồ) | H28: Link dùng
A29: C01 | B29: ADSS 9/2009 | C29: 1 | D29: xanh dương | E29: dùng R2-01 | H29: R2-01
A30: C01 | B30: ADSS 9/2009 | C30: 2 | D30: cam | E30: dùng R2-01 | H30: R2-01
A31: C01 | B31: ADSS 9/2009 | C31: 3 | D31: xanh lá | E31: dùng R1-01 | H31: R1-01
A32: C01 | B32: ADSS 9/2009 | C32: 4 | D32: nâu | E32: dùng R1-01 | H32: R1-01
A33: C01 | B33: ADSS 9/2009 | C33: 5 | D33: xám | E33: trống/chưa rõ
A34: C01 | B34: ADSS 9/2009 | C34: 6 | D34: trắng | E34: trống/chưa rõ
A35: C01 | B35: ADSS 9/2009 | C35: 7 | D35: xanh dương | E35: trống/chưa rõ
A36: C01 | B36: ADSS 9/2009 | C36: 8 | D36: cam | E36: trống/chưa rõ
A37: C01 | B37: ADSS 9/2009 | C37: 9 | D37: xanh lá | E37: trống/chưa rõ
A38: C01 | B38: ADSS 9/2009 | C38: 10 | D38: nâu | E38: trống/chưa rõ
A39: C01 | B39: ADSS 9/2009 | C39: 11 | D39: xám | E39: trống/chưa rõ
A40: C01 | B40: ADSS 9/2009 | C40: 12 | D40: trắng | E40: trống/chưa rõ
A41: C01 | B41: ADSS 9/2009 | C41: 13 | D41: xanh dương | E41: trống/chưa rõ
A42: C01 | B42: ADSS 9/2009 | C42: 14 | D42: cam | E42: trống/chưa rõ
A43: C01 | B43: ADSS 9/2009 | C43: 15 | D43: xanh lá | E43: trống/chưa rõ
A44: C01 | B44: ADSS 9/2009 | C44: 16 | D44: nâu | E44: trống/chưa rõ
... A52: C01 | B52: ADSS 9/2009 | C52: 24 | D52: trắng | E52: trống/chưa rõ
A53: C02 | B53: SACOM 8/2014 | C53: 1 | D53: xanh dương | E53: dùng R2-01 | H53: R2-01
A54: C02 | B54: SACOM 8/2014 | C54: 2 | D54: cam | E54: dùng R2-01 | H54: R2-01
A55: C02 | B55: SACOM 8/2014 | C55: 3 | D55: xanh lá | E55: dùng R1-01 | H55: R1-01
A56: C02 | B56: SACOM 8/2014 | C56: 4 | D56: nâu | E56: dùng R1-01 | H56: R1-01
A57: C02 | B57: SACOM 8/2014 | C57: 5 | D57: xám | E57: trống/chưa rõ
...

Sheet Phối core MX
A1: Bảng phối core tại măng xông: core nào hàn với core nào
A2: Suy từ nhãn trong sơ đồ MX (cùng nhãn = cùng nhóm hàn; core nhỏ hàn core nhỏ). Màu sợi/ống theo thứ tự 6 sợi/ống (giả định). Cột "Trạm" lấy từ tên trạm ghi sát nhãn.
A4: Măng xông | B4: Nhãn | C4: Cáp A | D4: Core A | E4: Ống A | F4: Màu A | G4: Cáp B | H4: Core B | I4: Ống B | J4: Màu B | K4: Trạm (ghi trong sơ đồ) | L4: Ghi chú
A5: MX_PHẠM HÙNG | B5: A | C5: K4 · 8FO → HNB014 | D5: 1 | E5: 1 | F5: xanh dương | G5: K17 · Focal 6/2007 8FO → HNB012 | H5: 1 | I5: 1 | J5: xanh dương
A6: MX_PHẠM HÙNG | B6: A | C6: K4 · 8FO → HNB014 | D6: 2 | E6: 1 | F6: cam | G6: K17 · Focal 6/2007 8FO → HNB012 | H6: 2 | I6: 1 | J6: cam
A7: MX_PHẠM HÙNG | B7: A | C7: K4 · 8FO → HNB014 | D7: 3 | E7: 1 | F7: xanh lá | G7: K17 · Focal 6/2007 8FO → HNB012 | H7: 3 | I7: 1 | J7: xanh lá
A8: MX_PHẠM HÙNG | B8: A | C8: K4 · 8FO → HNB014 | D8: 4 | E8: 1 | F8: nâu | G8: K17 · Focal 6/2007 8FO → HNB012 | H8: 4 | I8: 1 | J8: nâu
A9: MX_PHẠM HÙNG | B9: B | C9: K4 · 8FO → HNB014 | D9: 5 | E9: 1 | F9: xám | G9: C17 · 6FO → HNB113 | H9: 1 | I9: 1 | J9: xanh dương
A10: MX_PHẠM HÙNG | B10: B | C10: K4 · 8FO → HNB014 | D10: 6 | E10: 1 | F10: trắng | G10: C17 · 6FO → HNB113 | H10: 2 | I10: 1 | J10: cam
A11: MX_PHẠM HÙNG | B11: B | C11: K4 · 8FO → HNB014 | D11: 7 | E11: 2 | F11: xanh dương | G11: C17 · 6FO → HNB113 | H11: 3 | I11: 1 | J11: xanh lá
A12: MX_PHẠM HÙNG | B12: B | C12: K4 · 8FO → HNB014 | D12: 8 | E12: 2 | F12: cam | G12: C17 · 6FO → HNB113 | H12: 4 | I12: 1 | J12: nâu
A13: MX_LVL-01 | B13: A | C13: AM5 · VINA 2018 AESS 12FO → HNB011 | D13: 1 | E13: 1 | F13: xanh dương | G13: AA8 · FOCAL 2020 12FO → Đào Sư Tích | H13: 3 | I13: 1 | J13: xanh lá | K13: HNB011
A14: MX_LVL-01 | B14: A | C14: AM5 · VINA 2018 AESS 12FO → HNB011 | D14: 2 | E14: 1 | F14: cam | G14: AA8 · FOCAL 2020 12FO → Đào Sư Tích | H14: 4 | I14: 1 | J14: nâu | K14: HNB011
A15: MX_LVL-01 | B15: B | C15: AA8 · FOCAL 2020 12FO → Đào Sư Tích | D15: 5 | E15: 1 | F15: xám | G15: AD22 · FOCAL 2013 12FO → LVL-Ngô Quang Thắm | H15: 5 | I15: 1 | J15: xám | K15: HNB055
A16: MX_LVL-01 | B16: B | C16: AA8 · FOCAL 2020 12FO → Đào Sư Tích | D16: 6 | E16: 1 | F16: trắng | G16: AD22 · FOCAL 2013 12FO → LVL-Ngô Quang Thắm | H16: 6 | I16: 1 | J16: trắng | K16: HNB055
A17: MX_LVL-01 | B17: C | C17: AD5 · FOCAL 6/2007 12FO → HNB075 | D17: 1 | E17: 1 | F17: xanh dương | G17: AD22 · FOCAL 2013 12FO → LVL-Ngô Quang Thắm | H17: 1 | I17: 1 | J17: xanh dương | K17: HNB075
A18: MX_LVL-01 | B18: C | C18: AD5 · FOCAL 6/2007 12FO → HNB075 | D18: 2 | E18: 1 | F18: cam | G18: AD22 · FOCAL 2013 12FO → LVL-Ngô Quang Thắm | H18: 2 | I18: 1 | J18: cam | K18: HNB075
A19: MX_LVL-01 | B19: D | C19: AD5 · FOCAL 6/2007 12FO → HNB075 | D19: 3 | E19: 1 | F19: xanh lá | G19: AD22 · FOCAL 2013 12FO → LVL-Ngô Quang Thắm | H19: 7 | I19: 2 | J19: xanh dương
A20: MX_LVL-01 | B20: D | C20: AD5 · FOCAL 6/2007 12FO → HNB075 | D20: 4 | E20: 1 | F20: nâu | G20: AD22 · FOCAL 2013 12FO → LVL-Ngô Quang Thắm | H20: 8 | I20: 2 | J20: cam
A21: MX_LVL-01 | B21: D | C21: AD5 · FOCAL 6/2007 12FO → HNB075 | D21: 5 | E21: 1 | F21: xám | G21: AD22 · FOCAL 2013 12FO → LVL-Ngô Quang Thắm | H21: 9 | I21: 2 | J21: xanh lá
A22: MX_LVL-01 | B22: D | C22: AD5 · FOCAL 6/2007 12FO → HNB075 | D22: 6 | E22: 1 | F22: trắng | G22: AD22 · FOCAL 2013 12FO → LVL-Ngô Quang Thắm | H22: 10 | I22: 2 | J22: nâu
A23: MX_LVL-01 | B23: E | C23: AD5 · FOCAL 6/2007 12FO → HNB075 | D23: 7 | E23: 2 | F23: xanh dương | G23: AA8 · FOCAL 2020 12FO → Đào Sư Tích | H23: 7 | I23: 2 | J23: xanh dương
A24: MX_LVL-01 | B24: E | C24: AD5 · FOCAL 6/2007 12FO → HNB075 | D24: 8 | E24: 2 | F24: cam | G24: AA8 · FOCAL 2020 12FO → Đào Sư Tích | H24: 8 | I24: 2 | J24: cam
A25: MX_LVL-02 | B25: A | C25: AD28 · FOCAL 2013 12FO → Đào Sư Tích | D25: 1 | E25: 1 | F25: xanh dương | G25: AD41 · SACOM 1/2015 12FO → LVL-Ngô Quang Thắm | H25: 1 | I25: 1 | J25: xanh dương | K25: HNB075
A26: MX_LVL-02 | B26: A | C26: AD28 · FOCAL 2013 12FO → Đào Sư Tích | D26: 2 | E26: 1 | F26: cam | G26: AD41 · SACOM 1/2015 12FO → LVL-Ngô Quang Thắm | H26: 2 | I26: 1 | J26: cam | K26: HNB075
A27: MX_LVL-02 | B27: A | C27: AD28 · FOCAL 2013 12FO → Đào Sư Tích | D27: 7 | E27: 2 | F27: xanh dương | G27: AD41 · SACOM 1/2015 12FO → LVL-Ngô Quang Thắm | H27: 7 | I27: 2 | J27: xanh dương
A28: MX_LVL-02 | B28: A | C28: AD28 · FOCAL 2013 12FO → Đào Sư Tích | D28: 8 | E28: 2 | F28: cam | G28: AD41 · SACOM 1/2015 12FO → LVL-Ngô Quang Thắm | H28: 8 | I28: 2 | J28: cam
A29: MX_LVL-02 | B29: A | C29: AD28 · FOCAL 2013 12FO → Đào Sư Tích | D29: 9 | E29: 2 | F29: xanh lá | G29: AD41 · SACOM 1/2015 12FO → LVL-Ngô Quang Thắm | H29: 9 | I29: 2 | J29: xanh lá
A30: MX_LVL-02 | B30: A | C30: AD28 · FOCAL 2013 12FO → Đào Sư Tích | D30: 10 | E30: 2 | F30: nâu | G30: AD41 · SACOM 1/2015 12FO → LVL-Ngô Quang Thắm | H30: 10 | I30: 2 | J30: nâu
A31: MX_LVL-02 | B31: A | C31: AD28 · FOCAL 2013 12FO → Đào Sư Tích | D31: 11 | E31: 2 | F31: xám | G31: AD41 · SACOM 1/2015 12FO → LVL-Ngô Quang Thắm | H31: 11 | I31: 2 | J31: xám
A32: MX_LVL-02 | B32: A | C32: AD28 · FOCAL 2013 12FO → Đào Sư Tích | D32: 12 | E32: 2 | F32: trắng | G32: AD41 · SACOM 1/2015 12FO → LVL-Ngô Quang Thắm | H32: 12 | I32: 2 | J32: trắng
A33: MX_LVL-02 | B33: B | C33: AD28 · FOCAL 2013 12FO → Đào Sư Tích | D33: 5 | E33: 1 | F33: xám | G33: AQ28 · POSTEF 6/2019 8FO → HNB055 | H33: 1 | I33: 1 | J33: xanh dương | K33: HNB055
A34: MX_LVL-02 | B34: B | C34: AD28 · FOCAL 2013 12FO → Đào Sư Tích | D34: 6 | E34: 1 | F34: trắng | G34: AQ28 · POSTEF 6/2019 8FO → HNB055 | H34: 2 | I34: 1 | J34: cam | K34: HNB055
A35: MX_LVL-02 | B35: C | C35: AD41 · SACOM 1/2015 12FO → LVL-Ngô Quang Thắm | D35: 5 | E35: 1 | F35: xám | G35: AQ41 · SACOM 3.2016 8FO → HNB065 | H35: 1 | I35: 1 | J35: xanh dương | K35: HNB065
A36: MX_LVL-02 | B36: C | C36: AD41 · SACOM 1/2015 12FO → LVL-Ngô Quang Thắm | D36: 6 | E36: 1 | F36: trắng | G36: AQ41 · SACOM 3.2016 8FO → HNB065 | H36: 2 | I36: 1 | J36: cam | K36: HNB065
A37: MX_LVL-02 | B37: D | C37: AA31 · FO → | D37: 1 | E37: 1 | F37: xanh dương | G37: AD41 · SACOM 1/2015 12FO → LVL-Ngô Quang Thắm | H37: 3 | I37: 1 | J37: xanh lá | K37: HNB073
A38: MX_LVL-02 | B38: D | C38: AA31 · FO → | D38: 2 | E38: 1 | F38: cam | G38: AD41 · SACOM 1/2015 12FO → LVL-Ngô Quang Thắm | H38: 4 | I38: 1 | J38: nâu | K38: HNB073
A39: MX_LVL-03 | B39: A | C39: AD61 · 12FO → LVL-Ngô Quang Thắm | D39: 1 | E39: 1 | F39: xanh dương | G39: AQ61 · POSTEF 9/2019 12FO → Phạm Hữu Lầu | H39: 7 | I39: 2 | J39: xanh dương
A40: MX_LVL-03 | B40: A | C40: AD61 · 12FO → LVL-Ngô Quang Thắm | D40: 2 | E40: 1 | F40: cam | G40: AQ61 · POSTEF 9/2019 12FO → Phạm Hữu Lầu | H40: 8 | I40: 2 | J40: cam
A41: MX_LVL-03 | B41: A | C41: AD61 · 12FO → LVL-Ngô Quang Thắm | D41: 3 | E41: 1 | F41: xanh lá | G41: AQ61 · POSTEF 9/2019 12FO → Phạm Hữu Lầu | H41: 9 | I41: 2 | J41: xanh lá | K41: HNB066
...

Sheet Core theo trạm
A1: Core đi vào từng trạm theo sơ đồ MX
A2: Gom theo tên trạm ghi trong sơ đồ: măng xông, cáp, nhóm core và nhãn.
A4: Trạm | B4: Măng xông | C4: Nhãn | D4: Cáp | E4: Các core | F4: Số core
A5: HNB005 | B5: MX_HTP-01 | C5: A | D5: CE48 · FOCAL 12FO → Phạm Hũu Lầu | E5: 11, 12 | F5: 2
A6: HNB005 | B6: MX_HTP-01 | C6: A | D6: CE61 · FOCAL 12FO → AGG-NBE22 (SG mới) | E6: 11, 12 | F6: 2
A7: HNB005 | B7: MX_HTP-02 | C7: B | D7: CE68 · FOCAL 12FO → cầu Phú Xuân 2 | E7: 11, 12 | F7: 2
A8: HNB005 | B8: MX_HTP-02 | C8: B | D8: CR81 · Vina-OFC AESS2016 8FO → HNB005 | E8: 1, 2 | F8: 2
A9: HNB005 | B9: MX_LVL-03 | C9: A | D9: AD61 · 12FO → LVL-Ngô Quang Thắm | E9: 5, 6 | F9: 2
A10: HNB005 | B10: MX_LVL-03 | C10: A | D10: AQ61 · POSTEF 9/2019 12FO → Phạm Hữu Lầu | E10: 11, 12 | F10: 2
A11: HNB005 | B11: MX_LVL-04 | C11: A | D11: AD67 · SAMTEL 3/2015 12FO → Đào Sư Tích | E11: 5, 6 | F11: 2
A12: HNB005 | B12: MX_LVL-04 | C12: A | D12: AD80 · 12FO → LVL-Ngô Quang Thắm | E12: 5, 6 | F12: 2
A13: HNB005 | B13: MX_LVL-05 | C13: C | D13: AD86 · 12FO → Phạm Hữu Lầu | E13: 5, 6 | F13: 2
A14: HNB005 | B14: MX_LVL-05 | C14: C | D14: AP86 · 12FO → Ngô Quang Thắm | E14: 11, 12 | F14: 2
A15: HNB005 | B15: MX_NVT_02A | C15: C | D15: AD174 · 12FO → VNPT Long Thới | E15: 11, 12 | F15: 2
A16: HNB005 | B16: MX_NVT_02A | C16: C | D16: AQ174 · 8FO → MX_NVT_02B đối diện | E16: 5, 6 | F16: 2
... A21: HNB011 | B21: MX_LVL-05 | C21: A | D21: AD103 · HƯỚNG VỀ VNPT LONG THỚI 24FO → CÁP TREO 24FO HƯỚNG VỀ VNPT LONG THỚI | E21: 3, 4 | F21: 2
A22: HNB011 | B22: MX_NB-01 | D22: AD109 · HƯỚNG VỀ LÊ VĂN LƯƠNG 24FO → CÁP TREO 24FO HƯỚNG VỀ LÊ VĂN LƯƠNG (MX_LVL-05) | E22: 3, 4 | F22: 2
A23: HNB012 | B23: MX_LVL-05 | C23: A | D23: AA89 · 12FO → Đào Sư Tích | E23: 1, 2 | F23: 2
A24: HNB012 | B24: MX_LVL-05 | C24: A | D24: AD103 · HƯỚNG VỀ VNPT LONG THỚI 24FO → CÁP TREO 24FO HƯỚNG VỀ VNPT LONG THỚI | E24: 1, 2 | F24: 2
A25: HNB012 | B25: MX_NB-01 | C25: A | D25: AD109 · HƯỚNG VỀ LÊ VĂN LƯƠNG 24FO → CÁP TREO 24FO HƯỚNG VỀ LÊ VĂN LƯƠNG (MX_LVL-05) | E25: 1, 2 | F25: 2
A26: HNB012 | B26: MX_NB-01 | C26: A | D26: AJ126 · HƯỚNG VỀ VNPT LONG THỚI VÀO ODF-01 24FO → CÁP TREO 24FO HƯỚNG VỀ VNPT LONG THỚI VÀO ODF-01 | E26: 1, 2 | F26: 2
A27: HNB038 | B27: MX_HTP-02 | C27: C | D27: CE81 · FOCAL 12FO → AGG-NBE22 (SG mới) | E27: 9, 10 | F27: 2
A28: HNB038 | B28: MX_HTP-03A | C28: A | D28: CE101 · POSTEF HƯỚNG VỀ TÒA NHÀ 24FO → CÁP TREO 24FO POSTEF HƯỚNG VỀ TÒA NHÀ (ODF-01) (cs 1570) | E28: 9, 10 | F28: 2
A29: HNB038 | B29: MX_HTP-03A | C29: A | D29: CE88 · FOCAL 12FO → cầu Phú Xuân 2 | E29: 9, 10 | F29: 2
A30: HNB048 | B30: MX_LVL-05 | C30: D | D30: AD103 · HƯỚNG VỀ VNPT LONG THỚI 24FO → CÁP TREO 24FO HƯỚNG VỀ VNPT LONG THỚI | E30: 21, 22 | F30: 2
A31: HNB048 | B31: MX_LVL-05 | C31: D | D31: AP86 · 12FO → Ngô Quang Thắm | E31: 3, 4 | F31: 2
A32: HNB048 | B32: MX_NB-01 | C32: B | D32: AD109 · HƯỚNG VỀ LÊ VĂN LƯƠNG 24FO → CÁP TREO 24FO HƯỚNG VỀ LÊ VĂN LƯƠNG (MX_LVL-05) | E32: 21, 22 | F32: 2
A33: HNB048 | B33: MX_NB-01 | C33: B | D33: BD112 · HƯỚNG VỀ HUỲNH TẤN PHÁT 12FO → CÁP TREO 12FO HƯỚNG VỀ HUỲNH TẤN PHÁT (MX_NB-02) | E33: 3, 4 | F33: 2
A34: HNB055 | B34: MX_LVL-01 | C34: B | D34: AA8 · FOCAL 2020 12FO → Đào Sư Tích | E34: 5, 6 | F34: 2
... A96: LACG43 | B96: MX_LVL-05 | C96: B | D96: AD86 · 12FO → Phạm Hữu Lầu | E96: 7, 8 | F96: 2
A97: LACG43 | B97: MX_NB-01 | D97: AD109 · HƯỚNG VỀ LÊ VĂN LƯƠNG 24FO → CÁP TREO 24FO HƯỚNG VỀ LÊ VĂN LƯƠNG (MX_LVL-05) | E97: 7, 8 | F97: 2
A98: TTC | B98: MX_NB-01 | D98: BD112 · HƯỚNG VỀ HUỲNH TẤN PHÁT 12FO → CÁP TREO 12FO HƯỚNG VỀ HUỲNH TẤN PHÁT (MX_NB-02) | E98: 9, 10 | F98: 2

Sheet Cáp tại MX
A1: Cáp (đầu cáp) tại từng măng xông
A2: Ô gốc = vị trí ô trong sơ đồ MX. Số core vẽ / có nhãn tính từ sheet "Core MX".
A4: Măng xông | B4: Ô gốc | C4: Mã cáp | D4: Loại | E4: Số FO | F4: Chỉ số mét | G4: Hướng | H4: Số core vẽ | I4: Số core có nhãn | J4: Tiêu đề gốc
A5: MX_PHẠM HÙNG | B5: K4 | E5: 8 | G5: HNB014 | H5: =COUNTIFS('Core MX'!B:B,"MX_PHẠM HÙNG|K4") | I5: =COUNTIFS('Core MX'!B:B,"MX_PHẠM HÙNG|K4",'Core MX'!F:F,"?*") | J5: CÁP 8FO (cs ) | Hướng vào trạm HNB014
A6: MX_PHẠM HÙNG | B6: C17 | D6: treo | E6: 6 | G6: HNB113 | H6: =COUNTIFS('Core MX'!B:B,"MX_PHẠM HÙNG|C17") | I6: =COUNTIFS('Core MX'!B:B,"MX_PHẠM HÙNG|C17",'Core MX'!F:F,"?*") | J6: CÁP TREO 6FO (chỉ số ) | To: HNB113
A7: MX_PHẠM HÙNG | B7: K17 | C7: Focal 6/2007 | E7: 8 | G7: HNB012 | H7: =COUNTIFS('Core MX'!B:B,"MX_PHẠM HÙNG|K17") | I7: =COUNTIFS('Core MX'!B:B,"MX_PHẠM HÙNG|K17",'Core MX'!F:F,"?*") | J7: CÁP Focal 6/2007 8FO (cs ) | Hướng vào trạm HNB012
A8: MX_LVL-01 | B8: AD5 | C8: FOCAL 6/2007 | E8: 12 | F8: 5405 | G8: HNB075 | H8: =COUNTIFS('Core MX'!B:B,"MX_LVL-01|AD5") | I8: =COUNTIFS('Core MX'!B:B,"MX_LVL-01|AD5",'Core MX'!F:F,"?*") | J8: CÁP FOCAL 6/2007 12FO (cs 5405 ) | Hướng vào trạm HNB075
A9: MX_LVL-01 | B9: AM5 | C9: VINA 2018 AESS | E9: 12 | F9: 120 | G9: HNB011 | H9: =COUNTIFS('Core MX'!B:B,"MX_LVL-01|AM5") | I9: =COUNTIFS('Core MX'!B:B,"MX_LVL-01|AM5",'Core MX'!F:F,"?*") | J9: CÁP VINA 2018 AESS 12FO (cs 0120 ) | Hướng vào trạm HNB011
A10: MX_LVL-01 | B10: AA8 | C10: FOCAL 2020 | D10: treo | E10: 12 | F10: 3972 | G10: Đào Sư Tích | H10: =COUNTIFS('Core MX'!B:B,"MX_LVL-01|AA8") | I10: =COUNTIFS('Core MX'!B:B,"MX_LVL-01|AA8",'Core MX'!F:F,"?*") | J10: CÁP TREO FOCAL 2020 | 12FO (chỉ số 3972) | Cáp Trục hướng về Đào Sư Tích
A11: MX_LVL-01 | B11: AD22 | C11: FOCAL 2013 | D11: treo | E11: 12 | F11: 4576 | G11: LVL-Ngô Quang Thắm | H11: =COUNTIFS('Core MX'!B:B,"MX_LVL-01|AD22") | I11: =COUNTIFS('Core MX'!B:B,"MX_LVL-01|AD22",'Core MX'!F:F,"?*") | J11: CÁP TREO FOCAL 2013 12FO (chỉ số 4576 ) | Cáp Trục hướng về LVL-Ngô Quang Thắm
A12: MX_DST | B12: C23 | E12: 2 | G12: bến đò băng sông | H12: =COUNTIFS('Core MX'!B:B,"MX_DST|C23") | I12: =COUNTIFS('Core MX'!B:B,"MX_DST|C23",'Core MX'!F:F,"?*") | J12: CÁP 2FO (cs ) | Hướng bến đò băng sông
A13: MX_DST | B13: L23 | D13: treo | E13: 12 | G13: LVL(MX_LVL_01) | H13: =COUNTIFS('Core MX'!B:B,"MX_DST|L23") | I13: =COUNTIFS('Core MX'!B:B,"MX_DST|L23",'Core MX'!F:F,"?*") | J13: CÁP TREO 12FO (chỉ số ) | Cáp Trục hướng về LVL(MX_LVL_01)
A14: MX_DST | B14: L36 | D14: treo | E14: 12 | G14: Long Thới (MX_LVL_05) | H14: =COUNTIFS('Core MX'!B:B,"MX_DST|L36") | I14: =COUNTIFS('Core MX'!B:B,"MX_DST|L36",'Core MX'!F:F,"?*") | J14: CÁP TREO 12FO (chỉ số ) | Cáp Trục hướng về Long Thới (MX_LVL_05)
A15: MX_LVL-02 | B15: AD28 | C15: FOCAL 2013 | D15: treo | E15: 12 | F15: 4058 | G15: Đào Sư Tích | H15: =COUNTIFS('Core MX'!B:B,"MX_LVL-02|AD28") | I15: =COUNTIFS('Core MX'!B:B,"MX_LVL-02|AD28",'Core MX'!F:F,"?*") | J15: CÁP TREO FOCAL 2013 12FO (chỉ số 4058 ) | Cáp Trục hướng về Đào Sư Tích
A16: MX_LVL-02 | B16: AQ28 | C16: POSTEF 6/2019 | E16: 8 | F16: 1068 | G16: HNB055 | H16: =COUNTIFS('Core MX'!B:B,"MX_LVL-02|AQ28") | I16: =COUNTIFS('Core MX'!B:B,"MX_LVL-02|AQ28",'Core MX'!F:F,"?*") | J16: CÁP POSTEF 6/2019 8FO (cs 1068 ) | Hướng vào trạm HNB055
A17: MX_LVL-02 | B17: AA31 | H17: =COUNTIFS('Core MX'!B:B,"MX_LVL-02|AA31") | I17: =COUNTIFS('Core MX'!B:B,"MX_LVL-02|AA31",'Core MX'!F:F,"?*")
A18: MX_LVL-02 | B18: AD41 | C18: SACOM 1/2015 | D18: treo | E18: 12 | F18: 2854 | G18: LVL-Ngô Quang Thắm | H18: =COUNTIFS('Core MX'!B:B,"MX_LVL-02|AD41") | I18: =COUNTIFS('Core MX'!B:B,"MX_LVL-02|AD41",'Core MX'!F:F,"?*") | J18: CÁP TREO SACOM 1/2015 12FO (chỉ số 2854) | Cáp Trục hướng về LVL-Ngô Quang Thắm
A19: MX_LVL-02 | B19: AQ41 | C19: SACOM 3.2016 | E19: 8 | F19: 394 | G19: HNB065 | H19: =COUNTIFS('Core MX'!B:B,"MX_LVL-02|AQ41") | I19: =COUNTIFS('Core MX'!B:B,"MX_LVL-02|AQ41",'Core MX'!F:F,"?*") | J19: CÁP SACOM 3.2016 8FO (cs 0394) | Hướng vào trạm HNB065
A20: MX_LVL-03 | B20: AD48 | C20: VINA-OFC 2016 | D20: treo | E20: 12 | F20: 120 | G20: Đào Sư Tích | H20: =COUNTIFS('Core MX'!B:B,"MX_LVL-03|AD48") | I20: =COUNTIFS('Core MX'!B:B,"MX_LVL-03|AD48",'Core MX'!F:F,"?*") | J20: CÁP TREO VINA-OFC 2016 12FO (chỉ số 0120) | Cáp Trục hướng về Đào Sư Tích
A21: MX_LVL-03 | B21: AQ48 | C21: SACOM 2014 | E21: 12 | F21: 1131 | G21: HNB094 | H21: =COUNTIFS('Core MX'!B:B,"MX_LVL-03|AQ48") | I21: =COUNTIFS('Core MX'!B:B,"MX_LVL-03|AQ48",'Core MX'!F:F,"?*") | J21: CÁP SACOM 2014 12FO (cs 1131 ) | Hướng vào trạm HNB094
A22: MX_LVL-03 | B22: AD61 | D22: treo | E22: 12 | G22: LVL-Ngô Quang Thắm | H22: =COUNTIFS('Core MX'!B:B,"MX_LVL-03|AD61") | I22: =COUNTIFS('Core MX'!B:B,"MX_LVL-03|AD61",'Core MX'!F:F,"?*") | J22: CÁP TREO 12FO (chỉ số ) | Cáp Trục hướng về LVL-Ngô Quang Thắm
A23: MX_LVL-03 | B23: AQ61 | C23: POSTEF 9/2019 | D23: treo | E23: 12 | F23: 44 | G23: Phạm Hữu Lầu | H23: =COUNTIFS('Core MX'!B:B,"MX_LVL-03|AQ61") | I23: =COUNTIFS('Core MX'!B:B,"MX_LVL-03|AQ61",'Core MX'!F:F,"?*") | J23: CÁP TREO POSTEF 9/2019 12FO (chỉ số 0044 ) | Cáp Trục hướng về Phạm Hữu Lầu
A24: MX_HTP-01 | B24: CE48 | C24: FOCAL | D24: treo | E24: 12 | G24: Phạm Hũu Lầu | H24: =COUNTIFS('Core MX'!B:B,"MX_HTP-01|CE48") | I24: =COUNTIFS('Core MX'!B:B,"MX_HTP-01|CE48",'Core MX'!F:F,"?*") | J24: CÁP TREO 12FO FOCAL (chỉ số ) | Cáp Trục hướng về Phạm Hũu Lầu
A25: MX_HTP-01 | B25: CR48 | C25: POSTEF 2016 | D25: tròn | E25: 8 | G25: HNB066 | H25: =COUNTIFS('Core MX'!B:B,"MX_HTP-01|CR48") | I25: =COUNTIFS('Core MX'!B:B,"MX_HTP-01|CR48",'Core MX'!F:F,"?*") | J25: CÁP TRÒN 8FO POSTEF 2016 (cs ) | Hướng vào trạm HNB066
A26: MX_HTP-01 | B26: CE61 | C26: FOCAL | D26: treo | E26: 12 | G26: AGG-NBE22 (SG mới) | H26: =COUNTIFS('Core MX'!B:B,"MX_HTP-01|CE61") | I26: =COUNTIFS('Core MX'!B:B,"MX_HTP-01|CE61",'Core MX'!F:F,"?*") | J26: CÁP TREO 12FO FOCAL (chỉ số ) | Cáp Trục hướng về AGG-NBE22 (SG mới)
A27: MX_LVL-04 | B27: AD67 | C27: SAMTEL 3/2015 | D27: treo | E27: 12 | F27: 7426 | G27: Đào Sư Tích | H27: =COUNTIFS('Core MX'!B:B,"MX_LVL-04|AD67") | I27: =COUNTIFS('Core MX'!B:B,"MX_LVL-04|AD67",'Core MX'!F:F,"?*") | J27: CÁP TREO SAMTEL 12FO 3/2015 (chỉ số 7426) | Cáp Trục hướng về Đào Sư Tích
A28: MX_LVL-04 | B28: AA70 | C28: POSTEF 8/2019 | E28: 6 | G28: HNB018 | H28: =COUNTIFS('Core MX'!B:B,"MX_LVL-04|AA70") | I28: =COUNTIFS('Core MX'!B:B,"MX_LVL-04|AA70",'Core MX'!F:F,"?*") | J28: CÁP POSTEF 8/2019 6FO (cs ) | Hướng vào trạm HNB018
A29: MX_LVL-04 | B29: AR70 | H29: =COUNTIFS('Core MX'!B:B,"MX_LVL-04|AR70") | I29: =COUNTIFS('Core MX'!B:B,"MX_LVL-04|AR70",'Core MX'!F:F,"?*")
A30: MX_LVL-04 | B30: AD80 | D30: treo | E30: 12 | G30: LVL-Ngô Quang Thắm | H30: =COUNTIFS('Core MX'!B:B,"MX_LVL-04|AD80") | I30: =COUNTIFS('Core MX'!B:B,"MX_LVL-04|AD80",'Core MX'!F:F,"?*") | J30: CÁP TREO 12FO (chỉ số ) | Cáp Trục hướng về LVL-Ngô Quang Thắm
A31: MX_HTP-02 | B31: CE68 | C31: FOCAL | D31: treo | E31: 12 | G31: cầu Phú Xuân 2 | H31: =COUNTIFS('Core MX'!B:B,"MX_HTP-02|CE68") | I31: =COUNTIFS('Core MX'!B:B,"MX_HTP-02|CE68",'Core MX'!F:F,"?*") | J31: CÁP TREO 12FO FOCAL (chỉ số ) | Cáp Trục hướng về cầu Phú Xuân 2
A32: MX_HTP-02 | B32: CB71 | C32: POSTEF 1/2019 | D32: tròn | E32: 8 | G32: HNB038 | H32: =COUNTIFS('Core MX'!B:B,"MX_HTP-02|CB71") | I32: =COUNTIFS('Core MX'!B:B,"MX_HTP-02|CB71",'Core MX'!F:F,"?*") | J32: CÁP TRÒN 8FO POSTEF 1/2019 (cs ) | Hướng vào trạm HNB038
A33: MX_HTP-02 | B33: CE81 | C33: FOCAL | D33: treo | E33: 12 | G33: AGG-NBE22 (SG mới) | H33: =COUNTIFS('Core MX'!B:B,"MX_HTP-02|CE81") | I33: =COUNTIFS('Core MX'!B:B,"MX_HTP-02|CE81",'Core MX'!F:F,"?*") | J33: CÁP TREO 12FO FOCAL (chỉ số ) | Cáp Trục hướng về AGG-NBE22 (SG mới)
A34: MX_HTP-02 | B34: CR81 | C34: Vina-OFC AESS2016 | D34: treo | E34: 8 | G34: HNB005 | H34: =COUNTIFS('Core MX'!B:B,"MX_HTP-02|CR81") | I34: =COUNTIFS('Core MX'!B:B,"MX_HTP-02|CR81",'Core MX'!F:F,"?*") | J34: CÁP TREO 8FO Vina-OFC AESS2016 (cs ) | Hướng vào trạm HNB005
A35: MX_LVL-05 | B35: AD86 | D35: treo | E35: 12 | G35: Phạm Hữu Lầu | H35: =COUNTIFS('Core MX'!B:B,"MX_LVL-05|AD86") | I35: =COUNTIFS('Core MX'!B:B,"MX_LVL-05|AD86",'Core MX'!F:F,"?*") | J35: CÁP TREO 12FO (chỉ số ) | Cáp Trục LVL hướng về Phạm Hữu Lầu
A36: MX_LVL-05 | B36: AP86 | D36: treo | E36: 12 | G36: Ngô Quang Thắm | H36: =COUNTIFS('Core MX'!B:B,"MX_LVL-05|AP86") | I36: =COUNTIFS('Core MX'!B:B,"MX_LVL-05|AP86",'Core MX'!F:F,"?*") | J36: CÁP TREO 12FO (chỉ số ) | Cáp Trục LVL hướng về Ngô Quang Thắm
A37: MX_LVL-05 | B37: AA89 | D37: treo | E37: 12 | G37: Đào Sư Tích | H37: =COUNTIFS('Core MX'!B:B,"MX_LVL-05|AA89") | I37: =COUNTIFS('Core MX'!B:B,"MX_LVL-05|AA89",'Core MX'!F:F,"?*") | J37: CÁP TREO 12FO (chỉ số ) | Cáp Trục Nguyễn Bình hướng về Đào Sư Tích
A38: MX_LVL-05 | B38: AD103 | C38: HƯỚNG VỀ VNPT LONG THỚI | D38: treo | E38: 24 | H38: =COUNTIFS('Core MX'!B:B,"MX_LVL-05|AD103") | I38: =COUNTIFS('Core MX'!B:B,"MX_LVL-05|AD103",'Core MX'!F:F,"?*") | J38: CÁP TREO 24FO HƯỚNG VỀ VNPT LONG THỚI
A39: MX_HTP-03A | B39: CE88 | C39: FOCAL | D39: treo | E39: 12 | F39: 4000 | G39: cầu Phú Xuân 2 | H39: =COUNTIFS('Core MX'!B:B,"MX_HTP-03A|CE88") | I39: =COUNTIFS('Core MX'!B:B,"MX_HTP-03A|CE88",'Core MX'!F:F,"?*") | J39: CÁP TREO 12FO FOCAL (chỉ số 4000) | Cáp Trục hướng về cầu Phú Xuân 2
A40: MX_HTP-03A | B40: CU88 | C40: POSTEF 2017 | D40: treo | E40: 8 | F40: 860 | G40: HNB013 | H40: =COUNTIFS('Core MX'!B:B,"MX_HTP-03A|CU88") | I40: =COUNTIFS('Core MX'!B:B,"MX_HTP-03A|CU88",'Core MX'!F:F,"?*") | J40: CÁP TREO 8FO POSTEF 2017 (cs 860) | Hướng vào trạm HNB013
A41: MX_HTP-03A | B41: CE101 | C41: POSTEF HƯỚNG VỀ TÒA NHÀ | D41: treo | E41: 24 | F41: 1570 | H41: =COUNTIFS('Core MX'!B:B,"MX_HTP-03A|CE101") | I41: =COUNTIFS('Core MX'!B:B,"MX_HTP-03A|CE101",'Core MX'!F:F,"?*") | J41: CÁP TREO 24FO POSTEF HƯỚNG VỀ TÒA NHÀ (ODF-01) (cs 1570)
...

Sheet Core MX
A1: Từng core của từng đầu cáp tại măng xông
A2: Nhãn trống = chưa ghi (dự phòng/chưa phối).
A4: Măng xông | B4: Mã đầu cáp | C4: Core | D4: Ống | E4: Màu sợi | F4: Nhãn | G4: Trạm
A5: MX_PHẠM HÙNG | B5: MX_PHẠM HÙNG|K4 | C5: 1 | D5: 1 | E5: xanh dương | F5: A
A6: MX_PHẠM HÙNG | B6: MX_PHẠM HÙNG|K4 | C6: 2 | D6: 1 | E6: cam | F6: A
A7: MX_PHẠM HÙNG | B7: MX_PHẠM HÙNG|K4 | C7: 3 | D7: 1 | E7: xanh lá | F7: A
A8: MX_PHẠM HÙNG | B8: MX_PHẠM HÙNG|K4 | C8: 4 | D8: 1 | E8: nâu | F8: A
A9: MX_PHẠM HÙNG | B9: MX_PHẠM HÙNG|K4 | C9: 5 | D9: 1 | E9: xám | F9: B
A10: MX_PHẠM HÙNG | B10: MX_PHẠM HÙNG|K4 | C10: 6 | D10: 1 | E10: trắng | F10: B
A11: MX_PHẠM HÙNG | B11: MX_PHẠM HÙNG|K4 | C11: 7 | D11: 2 | E11: xanh dương | F11: B
A12: MX_PHẠM HÙNG | B12: MX_PHẠM HÙNG|K4 | C12: 8 | D12: 2 | E12: cam | F12: B
A13: MX_PHẠM HÙNG | B13: MX_PHẠM HÙNG|C17 | C13: 1 | D13: 1 | E13: xanh dương | F13: B
A14: MX_PHẠM HÙNG | B14: MX_PHẠM HÙNG|C17 | C14: 2 | D14: 1 | E14: cam | F14: B
A15: MX_PHẠM HÙNG | B15: MX_PHẠM HÙNG|C17 | C15: 3 | D15: 1 | E15: xanh lá | F15: B
A16: MX_PHẠM HÙNG | B16: MX_PHẠM HÙNG|C17 | C16: 4 | D16: 1 | E16: nâu | F16: B
A17: MX_PHẠM HÙNG | B17: MX_PHẠM HÙNG|C17 | C17: 5 | D17: 1 | E17: xám
A18: MX_PHẠM HÙNG | B18: MX_PHẠM HÙNG|C17 | C18: 6 | D18: 1 | E18: trắng
A19: MX_PHẠM HÙNG | B19: MX_PHẠM HÙNG|K17 | C19: 1 | D19: 1 | E19: xanh dương | F19: A
A20: MX_PHẠM HÙNG | B20: MX_PHẠM HÙNG|K17 | C20: 2 | D20: 1 | E20: cam | F20: A
A21: MX_PHẠM HÙNG | B21: MX_PHẠM HÙNG|K17 | C21: 3 | D21: 1 | E21: xanh lá | F21: A
A22: MX_PHẠM HÙNG | B22: MX_PHẠM HÙNG|K17 | C22: 4 | D22: 1 | E22: nâu | F22: A
A23: MX_PHẠM HÙNG | B23: MX_PHẠM HÙNG|K17 | C23: 5 | D23: 1 | E23: xám
A24: MX_PHẠM HÙNG | B24: MX_PHẠM HÙNG|K17 | C24: 6 | D24: 1 | E24: trắng
A25: MX_PHẠM HÙNG | B25: MX_PHẠM HÙNG|K17 | C25: 7 | D25: 2 | E25: xanh dương
A26: MX_PHẠM HÙNG | B26: MX_PHẠM HÙNG|K17 | C26: 8 | D26: 2 | E26: cam
A27: MX_LVL-01 | B27: MX_LVL-01|AD5 | C27: 1 | D27: 1 | E27: xanh dương | F27: C | G27: HNB075
A28: MX_LVL-01 | B28: MX_LVL-01|AD5 | C28: 2 | D28: 1 | E28: cam | F28: C | G28: HNB075
A29: MX_LVL-01 | B29: MX_LVL-01|AD5 | C29: 3 | D29: 1 | E29: xanh lá | F29: D
A30: MX_LVL-01 | B30: MX_LVL-01|AD5 | C30: 4 | D30: 1 | E30: nâu | F30: D
A31: MX_LVL-01 | B31: MX_LVL-01|AD5 | C31: 5 | D31: 1 | E31: xám | F31: D
A32: MX_LVL-01 | B32: MX_LVL-01|AD5 | C32: 6 | D32: 1 | E32: trắng | F32: D
A33: MX_LVL-01 | B33: MX_LVL-01|AD5 | C33: 7 | D33: 2 | E33: xanh dương | F33: E
A34: MX_LVL-01 | B34: MX_LVL-01|AD5 | C34: 8 | D34: 2 | E34: cam | F34: E
A35: MX_LVL-01 | B35: MX_LVL-01|AM5 | C35: 1 | D35: 1 | E35: xanh dương | F35: A
A36: MX_LVL-01 | B36: MX_LVL-01|AM5 | C36: 2 | D36: 1 | E36: cam | F36: A
A37: MX_LVL-01 | B37: MX_LVL-01|AM5 | C37: 3 | D37: 1 | E37: xanh lá
A38: MX_LVL-01 | B38: MX_LVL-01|AM5 | C38: 4 | D38: 1 | E38: nâu
A39: MX_LVL-01 | B39: MX_LVL-01|AM5 | C39: 5 | D39: 1 | E39: xám
A40: MX_LVL-01 | B40: MX_LVL-01|AM5 | C40: 6 | D40: 1 | E40: trắng
A41: MX_LVL-01 | B41: MX_LVL-01|AM5 | C41: 7 | D41: 2 | E41: xanh dương
...

Sheet Cảnh báo phối core
A1: Cảnh báo khi suy bảng phối core từ sơ đồ MX
A3: Măng xông | B3: Nội dung | C3: Xác nhận
A4: MX_DST | B4: C23: chưa ghi nhãn core (chưa có dữ liệu phối)
A5: MX_DST | B5: L23: chưa ghi nhãn core (chưa có dữ liệu phối)
A6: MX_DST | B6: L36: chưa ghi nhãn core (chưa có dữ liệu phối)
A7: MX_LVL-04 | B7: nhãn A: số sợi khác nhau (MX_LVL-04|AD67:10 vs MX_LVL-04|AD80:8)
A8: MX_NB-01 | B8: nhãn A: số sợi khác nhau (MX_NB-01|AD109:12 vs MX_NB-01|AJ126:4)
A9: MX_NB-01 | B9: nhãn C: chỉ có ở một đầu cáp (MX_NB-01|BD112)
A10: MX_NB-02 | B10: BI109: chưa ghi nhãn core (chưa có dữ liệu phối)
A11: MX_NB-02 | B11: BV109: chưa ghi nhãn core (chưa có dữ liệu phối)
A12: MX_NB-02 | B12: BI122: chưa ghi nhãn core (chưa có dữ liệu phối)
A13: MX_HTP-03B | B13: CE109: chưa ghi nhãn core (chưa có dữ liệu phối)
A14: MX_HTP-03B | B14: CE122: chưa ghi nhãn core (chưa có dữ liệu phối)
A15: MX_NB-03 | B15: BI129: chưa ghi nhãn core (chưa có dữ liệu phối)
... A43: ghi chú tay o | B43: noi_dung

Sheet Ring
A1: 8 ring AGG-HCMNBE12 ↔ AGG-HCMNBE22
A2: Tổng km chỉ để tham khảo; quỹ suy hao KHÔNG cộng dồn.
A4: Ring | B4: Chuỗi (từ NBE12 sang NBE22) | C4: Số CSG | D4: Số đoạn ring | E4: Tổng km tính | F4: Đoạn dài nhất (km) | G4: Dư thấp nhất (dB) | H4: Đoạn cảnh báo | I4: Nhánh cụt
A5: R1 | B5: NBE12 ─ HNB059 ─ HNB060 ─ HNB048 ─ NBE22 | C5: 3 | D5: =COUNTIFS('Đoạn & quỹ suy hao'!$B$5:$B$42,A5,'Đoạn & quỹ suy hao'!$E$5:$E$42,"ring") | E5: =SUMIFS('Đoạn & quỹ suy hao'!$K$5:$K$42,'Đoạn & quỹ suy hao'!$B$5:$B$42,A5,'Đoạn & quỹ suy hao'!$E$5:$E$42,"ring") | F5: =_xlfn.MAXIFS('Đoạn & quỹ suy hao'!$K$5:$K$42,'Đoạn & quỹ suy hao'!$B$5:$B$42,A5,'Đoạn & quỹ suy hao'!$E$5:$E$42,"ring") | G5: =_xlfn.MINIFS('Đoạn & quỹ suy hao'!$P$5:$P$42,'Đoạn & quỹ suy hao'!$B$5:$B$42,A5,'Đoạn & quỹ suy hao'!$E$5:$E$42,"ring") | H5: =COUNTIFS('Đoạn & quỹ suy hao'!$B$5:$B$42,A5,'Đoạn & quỹ suy hao'!$R$5:$R$42,"Cảnh báo") | I5: —
A6: R2 | B6: NBE12 ─ HNB054 ─ HNB006 ─ HNB091 ─ NBE22 | C6: 3 | D6: =COUNTIFS('Đoạn & quỹ suy hao'!$B$5:$B$42,A6,'Đoạn & quỹ suy hao'!$E$5:$E$42,"ring") | E6: =SUMIFS('Đoạn & quỹ suy hao'!$K$5:$K$42,'Đoạn & quỹ suy hao'!$B$5:$B$42,A6,'Đoạn & quỹ suy hao'!$E$5:$E$42,"ring") | F6: =_xlfn.MAXIFS('Đoạn & quỹ suy hao'!$K$5:$K$42,'Đoạn & quỹ suy hao'!$B$5:$B$42,A6,'Đoạn & quỹ suy hao'!$E$5:$E$42,"ring") | G6: =_xlfn.MINIFS('Đoạn & quỹ suy hao'!$P$5:$P$42,'Đoạn & quỹ suy hao'!$B$5:$B$42,A6,'Đoạn & quỹ suy hao'!$E$5:$E$42,"ring") | H6: =COUNTIFS('Đoạn & quỹ suy hao'!$B$5:$B$42,A6,'Đoạn & quỹ suy hao'!$R$5:$R$42,"Cảnh báo") | I6: —
A7: R3 | B7: NBE12 ─ HNB055 ─ HNB065 ─ HNB094 ─ NBE22 | C7: 3 | D7: =COUNTIFS('Đoạn & quỹ suy hao'!$B$5:$B$42,A7,'Đoạn & quỹ suy hao'!$E$5:$E$42,"ring") | E7: =SUMIFS('Đoạn & quỹ suy hao'!$K$5:$K$42,'Đoạn & quỹ suy hao'!$B$5:$B$42,A7,'Đoạn & quỹ suy hao'!$E$5:$E$42,"ring") | F7: =_xlfn.MAXIFS('Đoạn & quỹ suy hao'!$K$5:$K$42,'Đoạn & quỹ suy hao'!$B$5:$B$42,A7,'Đoạn & quỹ suy hao'!$E$5:$E$42,"ring") | G7: =_xlfn.MINIFS('Đoạn & quỹ suy hao'!$P$5:$P$42,'Đoạn & quỹ suy hao'!$B$5:$B$42,A7,'Đoạn & quỹ suy hao'!$E$5:$E$42,"ring") | H7: =COUNTIFS('Đoạn & quỹ suy hao'!$B$5:$B$42,A7,'Đoạn & quỹ suy hao'!$R$5:$R$42,"Cảnh báo") | I7: HNB018
A8: R4 | B8: NBE12 ─ HNB011 ─ HNB056 ─ HNB071 ─ HNB073 ─ NBE22 | C8: 4 | D8: =COUNTIFS('Đoạn & quỹ suy hao'!$B$5:$B$42,A8,'Đoạn & quỹ suy hao'!$E$5:$E$42,"ring") | E8: =SUMIFS('Đoạn & quỹ suy hao'!$K$5:$K$42,'Đoạn & quỹ suy hao'!$B$5:$B$42,A8,'Đoạn & quỹ suy hao'!$E$5:$E$42,"ring") | F8: =_xlfn.MAXIFS('Đoạn & quỹ suy hao'!$K$5:$K$42,'Đoạn & quỹ suy hao'!$B$5:$B$42,A8,'Đoạn & quỹ suy hao'!$E$5:$E$42,"ring") | G8: =_xlfn.MINIFS('Đoạn & quỹ suy hao'!$P$5:$P$42,'Đoạn & quỹ suy hao'!$B$5:$B$42,A8,'Đoạn & quỹ suy hao'!$E$5:$E$42,"ring") | H8: =COUNTIFS('Đoạn & quỹ suy hao'!$B$5:$B$42,A8,'Đoạn & quỹ suy hao'!$R$5:$R$42,"Cảnh báo") | I8: —
A9: R5 | B9: NBE12 ─ HNB012 ─ HNB014 ─ HNB075 ─ NBE22 | C9: 3 | D9: =COUNTIFS('Đoạn & quỹ suy hao'!$B$5:$B$42,A9,'Đoạn & quỹ suy hao'!$E$5:$E$42,"ring") | E9: =SUMIFS('Đoạn & quỹ suy hao'!$K$5:$K$42,'Đoạn & quỹ suy hao'!$B$5:$B$42,A9,'Đoạn & quỹ suy hao'!$E$5:$E$42,"ring") | F9: =_xlfn.MAXIFS('Đoạn & quỹ suy hao'!$K$5:$K$42,'Đoạn & quỹ suy hao'!$B$5:$B$42,A9,'Đoạn & quỹ suy hao'!$E$5:$E$42,"ring") | G9: =_xlfn.MINIFS('Đoạn & quỹ suy hao'!$P$5:$P$42,'Đoạn & quỹ suy hao'!$B$5:$B$42,A9,'Đoạn & quỹ suy hao'!$E$5:$E$42,"ring") | H9: =COUNTIFS('Đoạn & quỹ suy hao'!$B$5:$B$42,A9,'Đoạn & quỹ suy hao'!$R$5:$R$42,"Cảnh báo") | I9: HNB113
A10: R6 | B10: NBE12 ─ HNB086 ─ HNB024 ─ HNB027 ─ HNB031 ─ HNB020 ─ NBE22 | C10: 5 | D10: =COUNTIFS('Đoạn & quỹ suy hao'!$B$5:$B$42,A10,'Đoạn & quỹ suy hao'!$E$5:$E$42,"ring") | E10: =SUMIFS('Đoạn & quỹ suy hao'!$K$5:$K$42,'Đoạn & quỹ suy hao'!$B$5:$B$42,A10,'Đoạn & quỹ suy hao'!$E$5:$E$42,"ring") | F10: =_xlfn.MAXIFS('Đoạn & quỹ suy hao'!$K$5:$K$42,'Đoạn & quỹ suy hao'!$B$5:$B$42,A10,'Đoạn & quỹ suy hao'!$E$5:$E$42,"ring") | G10: =_xlfn.MINIFS('Đoạn & quỹ suy hao'!$P$5:$P$42,'Đoạn & quỹ suy hao'!$B$5:$B$42,A10,'Đoạn & quỹ suy hao'!$E$5:$E$42,"ring") | H10: =COUNTIFS('Đoạn & quỹ suy hao'!$B$5:$B$42,A10,'Đoạn & quỹ suy hao'!$R$5:$R$42,"Cảnh báo") | I10: —
